{
    "registryname": "electrolytic_cell_battery",
    "localizedname": "Electrolytic Cell Battery",
    "color": "A4A4A4",
    "parts": [
        {
            "x": -1,
            "y": 0,
            "z": 0,
            "elements": [
                "immersiveengineering:sheetmetal@8"
            ]
        },
        {
            "x": 1,
            "y": 0,
            "z": 0,
            "elements": [
                "immersiveengineering:sheetmetal@8"
            ]
        },
        {
            "x": -1,
            "y": 0,
            "z": 2,
            "elements": [
                "electrolytic_power_inputs"
            ]
        },
        {
            "x": 1,
            "y": 0,
            "z": 2,
            "elements": [
                "electrolytic_power_inputs"
            ]
        },
        {
            "x": -1,
            "y": 0,
            "z": 4,
            "elements": [
                "electrolytic_power_inputs"
            ]
        },
        {
            "x": 1,
            "y": 0,
            "z": 4,
            "elements": [
                "electrolytic_power_inputs"
            ]
        },
        {
            "x": -1,
            "y": 0,
            "z": 6,
            "elements": [
                "immersiveengineering:sheetmetal@8"
            ]
        },
        {
            "x": 0,
            "y": 0,
            "z": 6,
            "elements": [
                "immersiveengineering:sheetmetal@8"
            ]
        },
        {
            "x": 1,
            "y": 0,
            "z": 6,
            "elements": [
                "immersiveengineering:sheetmetal@8"
            ]
        },
        {
            "x": 1,
            "y": -1,
            "z": 0,
            "elements": [
                "immersiveengineering:metal_decoration1@1"
            ]
        },
        {
            "x": 0,
            "y": -1,
            "z": 0,
            "nbt": {"id":"immersiveengineering:ieslab","slabType":"1"},
            "elements": [
                "immersiveengineering:sheetmetal_slab@8"
            ]
        },
        {
            "x": -1,
            "y": 1,
            "z": 0,
            "elements": [
                "modularmachinery:blockfluidinputhatch@2"
            ]
        },
        {
            "x": 0,
            "y": 1,
            "z": 0,
            "nbt": {"id":"immersiveengineering:ieslab","slabType":"0"},
            "elements": [
                "immersiveengineering:sheetmetal_slab@8"
            ]
        },
        {
            "x": -1,
            "y": -1,
            "z": 0,
            "elements": [
                "modularmachinery:blockfluidinputhatch@2"
            ]
        },
        {
            "x": -1,
            "y": 1,
            "z": 2,
            "elements": [
                "immersiveengineering:metal_device1@6"
            ]
        },
        {
            "x": 1,
            "y": 1,
            "z": 0,
            "elements": [
                "modularmachinery:blockfluidinputhatch@2"
            ]
        },
        {
            "x": 0,
            "y": 1,
            "z": 2,
            "elements": [
                "modularmachinery:blockoutputbus@1"
            ]
        },
        {
            "x": -1,
            "y": -1,
            "z": 1,
            "elements": [
                "immersiveengineering:metal_device1@6"
            ]
        },
        {
            "x": 0,
            "y": -1,
            "z": 1,
            "elements": [
                "immersiveengineering:sheetmetal@8"
            ]
        },
        {
            "x": -1,
            "y": 1,
            "z": 4,
            "elements": [
                "immersiveengineering:metal_device1@6"
            ]
        },
        {
            "x": 1,
            "y": 1,
            "z": 2,
            "elements": [
                "immersiveengineering:metal_device1@6"
            ]
        },
        {
            "x": 0,
            "y": 1,
            "z": 4,
            "elements": [
                "modularmachinery:blockoutputbus@1"
            ]
        },
        {
            "x": 1,
            "y": -1,
            "z": 1,
            "elements": [
                "immersiveengineering:metal_decoration1@1"
            ]
        },
        {
            "x": -1,
            "y": -1,
            "z": 3,
            "elements": [
                "immersiveengineering:metal_device1@6"
            ]
        },
        {
            "x": 0,
            "y": -1,
            "z": 3,
            "elements": [
                "immersiveengineering:sheetmetal@8"
            ]
        },
        {
            "x": -1,
            "y": 1,
            "z": 6,
            "elements": [
                "modularmachinery:blockfluidoutputhatch@2"
            ]
        },
        {
            "x": 1,
            "y": 1,
            "z": 4,
            "elements": [
                "immersiveengineering:metal_device1@6"
            ]
        },
        {
            "x": 0,
            "y": 1,
            "z": 6,
            "nbt": {"id":"immersiveengineering:ieslab","slabType":"0"},
            "elements": [
                "immersiveengineering:sheetmetal_slab@8"
            ]
        },
        {
            "x": 1,
            "y": -1,
            "z": 3,
            "elements": [
                "immersiveengineering:metal_decoration1@1"
            ]
        },
        {
            "x": -1,
            "y": -1,
            "z": 5,
            "elements": [
                "immersiveengineering:metal_device1@6"
            ]
        },
        {
            "x": 0,
            "y": -1,
            "z": 5,
            "elements": [
                "immersiveengineering:sheetmetal@8"
            ]
        },
        {
            "x": 1,
            "y": 1,
            "z": 6,
            "elements": [
                "modularmachinery:blockfluidoutputhatch@2"
            ]
        },
        {
            "x": 1,
            "y": -1,
            "z": 5,
            "elements": [
                "immersiveengineering:metal_decoration1@1"
            ]
        },
        {
            "x": -1,
            "y": 0,
            "z": 1,
            "elements": [
                "electrolytic_power_inputs"
            ]
        },
        {
            "x": 1,
            "y": 0,
            "z": 1,
            "elements": [
                "electrolytic_power_inputs"
            ]
        },
        {
            "x": -1,
            "y": 0,
            "z": 3,
            "elements": [
                "electrolytic_power_inputs"
            ]
        },
        {
            "x": 1,
            "y": 0,
            "z": 3,
            "elements": [
                "electrolytic_power_inputs"
            ]
        },
        {
            "x": -1,
            "y": 0,
            "z": 5,
            "elements": [
                "electrolytic_power_inputs"
            ]
        },
        {
            "x": 1,
            "y": 0,
            "z": 5,
            "elements": [
                "electrolytic_power_inputs"
            ]
        },
        {
            "x": -1,
            "y": 1,
            "z": 1,
            "elements": [
                "immersiveengineering:metal_device1@6"
            ]
        },
        {
            "x": 0,
            "y": 1,
            "z": 1,
            "elements": [
                "modularmachinery:blockinputbus@1"
            ]
        },
        {
            "x": -1,
            "y": 1,
            "z": 3,
            "elements": [
                "immersiveengineering:metal_device1@6"
            ]
        },
        {
            "x": 1,
            "y": 1,
            "z": 1,
            "elements": [
                "immersiveengineering:metal_device1@6"
            ]
        },
        {
            "x": 0,
            "y": 1,
            "z": 3,
            "elements": [
                "modularmachinery:blockinputbus@1"
            ]
        },
        {
            "x": -1,
            "y": -1,
            "z": 2,
            "elements": [
                "immersiveengineering:metal_device1@6"
            ]
        },
        {
            "x": 0,
            "y": -1,
            "z": 2,
            "elements": [
                "immersiveengineering:sheetmetal@8"
            ]
        },
        {
            "x": -1,
            "y": 1,
            "z": 5,
            "elements": [
                "immersiveengineering:metal_device1@6"
            ]
        },
        {
            "x": 1,
            "y": 1,
            "z": 3,
            "elements": [
                "immersiveengineering:metal_device1@6"
            ]
        },
        {
            "x": 0,
            "y": 1,
            "z": 5,
            "elements": [
                "modularmachinery:blockinputbus@1"
            ]
        },
        {
            "x": 1,
            "y": -1,
            "z": 2,
            "elements": [
                "immersiveengineering:metal_decoration1@1"
            ]
        },
        {
            "x": -1,
            "y": -1,
            "z": 4,
            "elements": [
                "immersiveengineering:metal_device1@6"
            ]
        },
        {
            "x": 0,
            "y": -1,
            "z": 4,
            "elements": [
                "immersiveengineering:sheetmetal@8"
            ]
        },
        {
            "x": 1,
            "y": 1,
            "z": 5,
            "elements": [
                "immersiveengineering:metal_device1@6"
            ]
        },
        {
            "x": 1,
            "y": -1,
            "z": 4,
            "elements": [
                "immersiveengineering:metal_decoration1@1"
            ]
        },
        {
            "x": -1,
            "y": -1,
            "z": 6,
            "elements": [
                "modularmachinery:blockfluidoutputhatch@2"
            ]
        },
        {
            "x": 0,
            "y": -1,
            "z": 6,
            "nbt": {"id":"immersiveengineering:ieslab","slabType":"1"},
            "elements": [
                "immersiveengineering:sheetmetal_slab@8"
            ]
        },
        {
            "x": 1,
            "y": -1,
            "z": 6,
            "elements": [
                "immersiveengineering:metal_decoration1@1"
            ]
        }
    ]}
