{
    "registryname": "fission_reactor",
    "localizedname": "Pebble Bed Reactor",
    "parts": [
        {
            "x": -2,
            "y": -2,
            "z": -1,
            "elements": [
                "immersiveengineering:storage@8"
            ]
        },
        {
            "x": -1,
            "y": 0,
            "z": 0,
            "elements": [
                "modularmachinery:blockinputbus@1"
            ]
        },
        {
            "x": -3,
            "y": -2,
            "z": -1,
            "elements": [
                "immersiveengineering:stone_decoration@7"
            ]
        },
        {
            "x": -2,
            "y": 0,
            "z": 0,
            "elements": [
                "modularmachinery:blockfluidoutputhatch@2"
            ]
        },
        {
            "x": 1,
            "y": 0,
            "z": 0,
            "elements": [
                "modularmachinery:blockinputbus@1"
            ]
        },
        {
            "x": 2,
            "y": 0,
            "z": 0,
            "elements": [
                "modularmachinery:blockfluidoutputhatch@2"
            ]
        },
        {
            "x": 3,
            "y": -3,
            "z": -1,
            "elements": [
                "immersiveengineering:stone_decoration@7"
            ]
        },
        {
            "x": 2,
            "y": -5,
            "z": -2,
            "elements": [
                "immersiveengineering:stone_decoration@7"
            ]
        },
        {
            "x": 1,
            "y": -7,
            "z": -3,
            "elements": [
                "immersiveengineering:stone_decoration@7"
            ]
        },
        {
            "x": 0,
            "y": -7,
            "z": -3,
            "elements": [
                "immersiveengineering:stone_decoration@7"
            ]
        },
        {
            "x": 2,
            "y": -3,
            "z": -1,
            "elements": [
                "immersiveengineering:storage@8"
            ]
        },
        {
            "x": 1,
            "y": -5,
            "z": -2,
            "elements": [
                "immersiveengineering:storage@8"
            ]
        },
        {
            "x": -1,
            "y": -7,
            "z": -3,
            "elements": [
                "immersiveengineering:stone_decoration@7"
            ]
        },
        {
            "x": 0,
            "y": -5,
            "z": -2,
            "elements": [
                "immersiveengineering:storage@8"
            ]
        },
        {
            "x": 2,
            "y": -1,
            "z": 0,
            "elements": [
                "immersiveengineering:stone_decoration@7"
            ]
        },
        {
            "x": 1,
            "y": -3,
            "z": -1,
            "elements": [
                "contenttweaker:fission_control_drum@0"
            ]
        },
        {
            "x": -1,
            "y": -5,
            "z": -2,
            "elements": [
                "immersiveengineering:storage@8"
            ]
        },
        {
            "x": 1,
            "y": -1,
            "z": 0,
            "elements": [
                "immersiveengineering:storage@8"
            ]
        },
        {
            "x": -2,
            "y": -5,
            "z": -2,
            "elements": [
                "immersiveengineering:stone_decoration@7"
            ]
        },
        {
            "x": -1,
            "y": -3,
            "z": -1,
            "elements": [
                "contenttweaker:fission_control_drum@0"
            ]
        },
        {
            "x": -2,
            "y": -3,
            "z": -1,
            "elements": [
                "immersiveengineering:storage@8"
            ]
        },
        {
            "x": -1,
            "y": -1,
            "z": 0,
            "elements": [
                "immersiveengineering:storage@8"
            ]
        },
        {
            "x": -3,
            "y": -3,
            "z": -1,
            "elements": [
                "immersiveengineering:stone_decoration@7"
            ]
        },
        {
            "x": -2,
            "y": -1,
            "z": 0,
            "elements": [
                "immersiveengineering:stone_decoration@7"
            ]
        },
        {
            "x": 3,
            "y": -4,
            "z": -1,
            "elements": [
                "immersiveengineering:stone_decoration@7"
            ]
        },
        {
            "x": 2,
            "y": -6,
            "z": -2,
            "elements": [
                "immersiveengineering:stone_decoration@7"
            ]
        },
        {
            "x": 1,
            "y": -8,
            "z": -3,
            "elements": [
                "immersiveengineering:stone_decoration@7"
            ]
        },
        {
            "x": 0,
            "y": -8,
            "z": -3,
            "elements": [
                "immersiveengineering:stone_decoration@7"
            ]
        },
        {
            "x": 3,
            "y": -2,
            "z": 0,
            "elements": [
                "immersiveengineering:stone_decoration@7"
            ]
        },
        {
            "x": 2,
            "y": -4,
            "z": -1,
            "elements": [
                "immersiveengineering:storage@8"
            ]
        },
        {
            "x": 1,
            "y": -6,
            "z": -2,
            "elements": [
                "immersiveengineering:storage@8"
            ]
        },
        {
            "x": -1,
            "y": -8,
            "z": -3,
            "elements": [
                "immersiveengineering:stone_decoration@7"
            ]
        },
        {
            "x": 0,
            "y": -6,
            "z": -2,
            "elements": [
                "immersiveengineering:storage@8"
            ]
        },
        {
            "x": 2,
            "y": -2,
            "z": 0,
            "elements": [
                "immersiveengineering:storage@8"
            ]
        },
        {
            "x": 1,
            "y": -4,
            "z": -1,
            "elements": [
                "contenttweaker:fission_control_drum@0"
            ]
        },
        {
            "x": -1,
            "y": -6,
            "z": -2,
            "elements": [
                "immersiveengineering:storage@8"
            ]
        },
        {
            "x": -2,
            "y": -6,
            "z": -2,
            "elements": [
                "immersiveengineering:stone_decoration@7"
            ]
        },
        {
            "x": -1,
            "y": -4,
            "z": -1,
            "elements": [
                "contenttweaker:fission_control_drum@0"
            ]
        },
        {
            "x": 0,
            "y": -2,
            "z": 0,
            "elements": [
                "modularmachinery:blockcontroller"
            ]
        },
        {
            "x": -2,
            "y": -4,
            "z": -1,
            "elements": [
                "immersiveengineering:storage@8"
            ]
        },
        {
            "x": -3,
            "y": -4,
            "z": -1,
            "elements": [
                "immersiveengineering:stone_decoration@7"
            ]
        },
        {
            "x": -2,
            "y": -2,
            "z": 0,
            "elements": [
                "immersiveengineering:storage@8"
            ]
        },
        {
            "x": -3,
            "y": -2,
            "z": 0,
            "elements": [
                "immersiveengineering:stone_decoration@7"
            ]
        },
        {
            "x": -1,
            "y": -8,
            "z": 3,
            "elements": [
                "immersiveengineering:stone_decoration@7"
            ]
        },
        {
            "x": 0,
            "y": -8,
            "z": 3,
            "elements": [
                "immersiveengineering:stone_decoration@7"
            ]
        },
        {
            "x": 1,
            "y": -8,
            "z": 3,
            "elements": [
                "immersiveengineering:stone_decoration@7"
            ]
        },
        {
            "x": 0,
            "y": -10,
            "z": 2,
            "elements": [
                "modularmachinery:blockfluidinputhatch@2"
            ]
        },
        {
            "x": 3,
            "y": -5,
            "z": -1,
            "elements": [
                "immersiveengineering:stone_decoration@7"
            ]
        },
        {
            "x": 2,
            "y": -7,
            "z": -2,
            "elements": [
                "immersiveengineering:stone_decoration@7"
            ]
        },
        {
            "x": 3,
            "y": -3,
            "z": 0,
            "elements": [
                "immersiveengineering:stone_decoration@7"
            ]
        },
        {
            "x": 2,
            "y": -5,
            "z": -1,
            "elements": [
                "immersiveengineering:storage@8"
            ]
        },
        {
            "x": 1,
            "y": -7,
            "z": -2,
            "elements": [
                "immersiveengineering:storage@8"
            ]
        },
        {
            "x": 0,
            "y": -7,
            "z": -2,
            "elements": [
                "immersiveengineering:storage@8"
            ]
        },
        {
            "x": 2,
            "y": -3,
            "z": 0,
            "elements": [
                "immersiveengineering:storage@8"
            ]
        },
        {
            "x": 1,
            "y": -5,
            "z": -1,
            "elements": [
                "contenttweaker:fission_control_drum@0"
            ]
        },
        {
            "x": -1,
            "y": -7,
            "z": -2,
            "elements": [
                "immersiveengineering:storage@8"
            ]
        },
        {
            "x": -2,
            "y": -7,
            "z": -2,
            "elements": [
                "immersiveengineering:stone_decoration@7"
            ]
        },
        {
            "x": -1,
            "y": -5,
            "z": -1,
            "elements": [
                "contenttweaker:fission_control_drum@0"
            ]
        },
        {
            "x": -2,
            "y": -5,
            "z": -1,
            "elements": [
                "immersiveengineering:storage@8"
            ]
        },
        {
            "x": -3,
            "y": -5,
            "z": -1,
            "elements": [
                "immersiveengineering:stone_decoration@7"
            ]
        },
        {
            "x": -2,
            "y": -3,
            "z": 0,
            "elements": [
                "immersiveengineering:storage@8"
            ]
        },
        {
            "x": -3,
            "y": -3,
            "z": 0,
            "elements": [
                "immersiveengineering:stone_decoration@7"
            ]
        },
        {
            "x": -1,
            "y": -7,
            "z": 3,
            "elements": [
                "immersiveengineering:stone_decoration@7"
            ]
        },
        {
            "x": -1,
            "y": -9,
            "z": 2,
            "elements": [
                "immersiveengineering:stone_decoration@7"
            ]
        },
        {
            "x": 0,
            "y": -7,
            "z": 3,
            "elements": [
                "immersiveengineering:stone_decoration@7"
            ]
        },
        {
            "x": 1,
            "y": -7,
            "z": 3,
            "elements": [
                "immersiveengineering:stone_decoration@7"
            ]
        },
        {
            "x": 0,
            "y": -9,
            "z": 2,
            "elements": [
                "immersiveengineering:stone_decoration@7"
            ]
        },
        {
            "x": 1,
            "y": -9,
            "z": 2,
            "elements": [
                "immersiveengineering:stone_decoration@7"
            ]
        },
        {
            "x": 3,
            "y": -6,
            "z": -1,
            "elements": [
                "immersiveengineering:stone_decoration@7"
            ]
        },
        {
            "x": 2,
            "y": -8,
            "z": -2,
            "elements": [
                "immersiveengineering:stone_decoration@7"
            ]
        },
        {
            "x": 3,
            "y": -4,
            "z": 0,
            "elements": [
                "immersiveengineering:stone_decoration@7"
            ]
        },
        {
            "x": 2,
            "y": -6,
            "z": -1,
            "elements": [
                "immersiveengineering:storage@8"
            ]
        },
        {
            "x": 1,
            "y": -8,
            "z": -2,
            "elements": [
                "immersiveengineering:storage@8"
            ]
        },
        {
            "x": 0,
            "y": -8,
            "z": -2,
            "elements": [
                "immersiveengineering:storage@8"
            ]
        },
        {
            "x": 2,
            "y": -4,
            "z": 0,
            "elements": [
                "immersiveengineering:storage@8"
            ]
        },
        {
            "x": 1,
            "y": -6,
            "z": -1,
            "elements": [
                "contenttweaker:fission_control_drum@0"
            ]
        },
        {
            "x": -1,
            "y": -8,
            "z": -2,
            "elements": [
                "immersiveengineering:storage@8"
            ]
        },
        {
            "x": -2,
            "y": -8,
            "z": -2,
            "elements": [
                "immersiveengineering:stone_decoration@7"
            ]
        },
        {
            "x": -1,
            "y": -6,
            "z": -1,
            "elements": [
                "contenttweaker:fission_control_drum@0"
            ]
        },
        {
            "x": -2,
            "y": -6,
            "z": -1,
            "elements": [
                "immersiveengineering:storage@8"
            ]
        },
        {
            "x": -3,
            "y": -6,
            "z": -1,
            "elements": [
                "immersiveengineering:stone_decoration@7"
            ]
        },
        {
            "x": -2,
            "y": -4,
            "z": 0,
            "elements": [
                "immersiveengineering:storage@8"
            ]
        },
        {
            "x": -3,
            "y": -4,
            "z": 0,
            "elements": [
                "immersiveengineering:stone_decoration@7"
            ]
        },
        {
            "x": -2,
            "y": -8,
            "z": 2,
            "elements": [
                "immersiveengineering:stone_decoration@7"
            ]
        },
        {
            "x": -1,
            "y": -6,
            "z": 3,
            "elements": [
                "immersiveengineering:stone_decoration@7"
            ]
        },
        {
            "x": -1,
            "y": -8,
            "z": 2,
            "elements": [
                "immersiveengineering:storage@8"
            ]
        },
        {
            "x": 0,
            "y": -6,
            "z": 3,
            "elements": [
                "immersiveengineering:stone_decoration@7"
            ]
        },
        {
            "x": -1,
            "y": -10,
            "z": 1,
            "elements": [
                "immersiveengineering:stone_decoration@7"
            ]
        },
        {
            "x": 0,
            "y": -8,
            "z": 2,
            "elements": [
                "immersiveengineering:storage@8"
            ]
        },
        {
            "x": 1,
            "y": -6,
            "z": 3,
            "elements": [
                "immersiveengineering:stone_decoration@7"
            ]
        },
        {
            "x": 1,
            "y": -8,
            "z": 2,
            "elements": [
                "immersiveengineering:storage@8"
            ]
        },
        {
            "x": 0,
            "y": -10,
            "z": 1,
            "elements": [
                "immersiveengineering:stone_decoration@7"
            ]
        },
        {
            "x": 2,
            "y": -8,
            "z": 2,
            "elements": [
                "immersiveengineering:stone_decoration@7"
            ]
        },
        {
            "x": 1,
            "y": -10,
            "z": 1,
            "elements": [
                "immersiveengineering:stone_decoration@7"
            ]
        },
        {
            "x": 3,
            "y": -7,
            "z": -1,
            "elements": [
                "immersiveengineering:stone_decoration@7"
            ]
        },
        {
            "x": 3,
            "y": -5,
            "z": 0,
            "elements": [
                "immersiveengineering:stone_decoration@7"
            ]
        },
        {
            "x": 2,
            "y": -7,
            "z": -1,
            "elements": [
                "immersiveengineering:storage@8"
            ]
        },
        {
            "x": 1,
            "y": -9,
            "z": -2,
            "elements": [
                "immersiveengineering:stone_decoration@7"
            ]
        },
        {
            "x": 2,
            "y": -5,
            "z": 0,
            "elements": [
                "immersiveengineering:storage@8"
            ]
        },
        {
            "x": 1,
            "y": -7,
            "z": -1,
            "elements": [
                "contenttweaker:fission_control_drum@0"
            ]
        },
        {
            "x": 0,
            "y": -9,
            "z": -2,
            "elements": [
                "immersiveengineering:stone_decoration@7"
            ]
        },
        {
            "x": -1,
            "y": -9,
            "z": -2,
            "elements": [
                "immersiveengineering:stone_decoration@7"
            ]
        },
        {
            "x": -1,
            "y": -7,
            "z": -1,
            "elements": [
                "contenttweaker:fission_control_drum@0"
            ]
        },
        {
            "x": -2,
            "y": -7,
            "z": -1,
            "elements": [
                "immersiveengineering:storage@8"
            ]
        },
        {
            "x": -3,
            "y": -7,
            "z": -1,
            "elements": [
                "immersiveengineering:stone_decoration@7"
            ]
        },
        {
            "x": -2,
            "y": -5,
            "z": 0,
            "elements": [
                "immersiveengineering:storage@8"
            ]
        },
        {
            "x": -3,
            "y": -5,
            "z": 0,
            "elements": [
                "immersiveengineering:stone_decoration@7"
            ]
        },
        {
            "x": -2,
            "y": -7,
            "z": 2,
            "elements": [
                "immersiveengineering:stone_decoration@7"
            ]
        },
        {
            "x": -1,
            "y": -5,
            "z": 3,
            "elements": [
                "immersiveengineering:stone_decoration@7"
            ]
        },
        {
            "x": -2,
            "y": -9,
            "z": 1,
            "elements": [
                "immersiveengineering:stone_decoration@7"
            ]
        },
        {
            "x": -1,
            "y": -7,
            "z": 2,
            "elements": [
                "immersiveengineering:storage@8"
            ]
        },
        {
            "x": 0,
            "y": -5,
            "z": 3,
            "elements": [
                "immersiveengineering:stone_decoration@7"
            ]
        },
        {
            "x": -1,
            "y": -9,
            "z": 1,
            "elements": [
                "immersiveengineering:storage@8"
            ]
        },
        {
            "x": 0,
            "y": -7,
            "z": 2,
            "elements": [
                "immersiveengineering:storage@8"
            ]
        },
        {
            "x": 1,
            "y": -5,
            "z": 3,
            "elements": [
                "immersiveengineering:stone_decoration@7"
            ]
        },
        {
            "x": 1,
            "y": -7,
            "z": 2,
            "elements": [
                "immersiveengineering:storage@8"
            ]
        },
        {
            "x": 0,
            "y": -9,
            "z": 1,
            "elements": [
                "immersiveengineering:storage@8"
            ]
        },
        {
            "x": 2,
            "y": -7,
            "z": 2,
            "elements": [
                "immersiveengineering:stone_decoration@7"
            ]
        },
        {
            "x": 1,
            "y": -9,
            "z": 1,
            "elements": [
                "immersiveengineering:storage@8"
            ]
        },
        {
            "x": 2,
            "y": -9,
            "z": 1,
            "elements": [
                "immersiveengineering:stone_decoration@7"
            ]
        },
        {
            "x": 3,
            "y": -8,
            "z": -1,
            "elements": [
                "immersiveengineering:stone_decoration@7"
            ]
        },
        {
            "x": 3,
            "y": -6,
            "z": 0,
            "elements": [
                "immersiveengineering:stone_decoration@7"
            ]
        },
        {
            "x": 2,
            "y": -8,
            "z": -1,
            "elements": [
                "immersiveengineering:storage@8"
            ]
        },
        {
            "x": 2,
            "y": -6,
            "z": 0,
            "elements": [
                "immersiveengineering:storage@8"
            ]
        },
        {
            "x": 1,
            "y": -8,
            "z": -1,
            "elements": [
                "contenttweaker:fission_control_drum@0"
            ]
        },
        {
            "x": 0,
            "y": -10,
            "z": -2,
            "elements": [
                "modularmachinery:blockfluidinputhatch@2"
            ]
        },
        {
            "x": -1,
            "y": -8,
            "z": -1,
            "elements": [
                "contenttweaker:fission_control_drum@0"
            ]
        },
        {
            "x": -2,
            "y": -8,
            "z": -1,
            "elements": [
                "immersiveengineering:storage@8"
            ]
        },
        {
            "x": -3,
            "y": -8,
            "z": -1,
            "elements": [
                "immersiveengineering:stone_decoration@7"
            ]
        },
        {
            "x": -2,
            "y": -6,
            "z": 0,
            "elements": [
                "immersiveengineering:storage@8"
            ]
        },
        {
            "x": -3,
            "y": -6,
            "z": 0,
            "elements": [
                "immersiveengineering:stone_decoration@7"
            ]
        },
        {
            "x": -3,
            "y": -8,
            "z": 1,
            "elements": [
                "immersiveengineering:stone_decoration@7"
            ]
        },
        {
            "x": -2,
            "y": -6,
            "z": 2,
            "elements": [
                "immersiveengineering:stone_decoration@7"
            ]
        },
        {
            "x": -1,
            "y": -4,
            "z": 3,
            "elements": [
                "immersiveengineering:stone_decoration@7"
            ]
        },
        {
            "x": -2,
            "y": -8,
            "z": 1,
            "elements": [
                "immersiveengineering:storage@8"
            ]
        },
        {
            "x": -1,
            "y": -6,
            "z": 2,
            "elements": [
                "immersiveengineering:storage@8"
            ]
        },
        {
            "x": 0,
            "y": -4,
            "z": 3,
            "elements": [
                "immersiveengineering:stone_decoration@7"
            ]
        },
        {
            "x": -1,
            "y": -8,
            "z": 1,
            "elements": [
                "contenttweaker:fission_control_drum@0"
            ]
        },
        {
            "x": 0,
            "y": -6,
            "z": 2,
            "elements": [
                "immersiveengineering:storage@8"
            ]
        },
        {
            "x": 1,
            "y": -4,
            "z": 3,
            "elements": [
                "immersiveengineering:stone_decoration@7"
            ]
        },
        {
            "x": 1,
            "y": -6,
            "z": 2,
            "elements": [
                "immersiveengineering:storage@8"
            ]
        },
        {
            "x": 2,
            "y": -6,
            "z": 2,
            "elements": [
                "immersiveengineering:stone_decoration@7"
            ]
        },
        {
            "x": 1,
            "y": -8,
            "z": 1,
            "elements": [
                "contenttweaker:fission_control_drum@0"
            ]
        },
        {
            "x": 2,
            "y": -8,
            "z": 1,
            "elements": [
                "immersiveengineering:storage@8"
            ]
        },
        {
            "x": 3,
            "y": -8,
            "z": 1,
            "elements": [
                "immersiveengineering:stone_decoration@7"
            ]
        },
        {
            "x": 3,
            "y": -7,
            "z": 0,
            "elements": [
                "immersiveengineering:stone_decoration@7"
            ]
        },
        {
            "x": 2,
            "y": -9,
            "z": -1,
            "elements": [
                "immersiveengineering:stone_decoration@7"
            ]
        },
        {
            "x": 2,
            "y": -7,
            "z": 0,
            "elements": [
                "immersiveengineering:storage@8"
            ]
        },
        {
            "x": 1,
            "y": -9,
            "z": -1,
            "elements": [
                "immersiveengineering:storage@8"
            ]
        },
        {
            "x": 0,
            "y": -9,
            "z": -1,
            "elements": [
                "immersiveengineering:storage@8"
            ]
        },
        {
            "x": -1,
            "y": -9,
            "z": -1,
            "elements": [
                "immersiveengineering:storage@8"
            ]
        },
        {
            "x": -2,
            "y": -9,
            "z": -1,
            "elements": [
                "immersiveengineering:stone_decoration@7"
            ]
        },
        {
            "x": -2,
            "y": -7,
            "z": 0,
            "elements": [
                "immersiveengineering:storage@8"
            ]
        },
        {
            "x": -3,
            "y": -7,
            "z": 0,
            "elements": [
                "immersiveengineering:stone_decoration@7"
            ]
        },
        {
            "x": -3,
            "y": -7,
            "z": 1,
            "elements": [
                "immersiveengineering:stone_decoration@7"
            ]
        },
        {
            "x": -2,
            "y": -5,
            "z": 2,
            "elements": [
                "immersiveengineering:stone_decoration@7"
            ]
        },
        {
            "x": -1,
            "y": -3,
            "z": 3,
            "elements": [
                "immersiveengineering:stone_decoration@7"
            ]
        },
        {
            "x": -2,
            "y": -7,
            "z": 1,
            "elements": [
                "immersiveengineering:storage@8"
            ]
        },
        {
            "x": -1,
            "y": -5,
            "z": 2,
            "elements": [
                "immersiveengineering:storage@8"
            ]
        },
        {
            "x": 0,
            "y": -3,
            "z": 3,
            "elements": [
                "immersiveengineering:stone_decoration@7"
            ]
        },
        {
            "x": -1,
            "y": -7,
            "z": 1,
            "elements": [
                "contenttweaker:fission_control_drum@0"
            ]
        },
        {
            "x": 0,
            "y": -5,
            "z": 2,
            "elements": [
                "immersiveengineering:storage@8"
            ]
        },
        {
            "x": 1,
            "y": -3,
            "z": 3,
            "elements": [
                "immersiveengineering:stone_decoration@7"
            ]
        },
        {
            "x": 1,
            "y": -5,
            "z": 2,
            "elements": [
                "immersiveengineering:storage@8"
            ]
        },
        {
            "x": 2,
            "y": -5,
            "z": 2,
            "elements": [
                "immersiveengineering:stone_decoration@7"
            ]
        },
        {
            "x": 1,
            "y": -7,
            "z": 1,
            "elements": [
                "contenttweaker:fission_control_drum@0"
            ]
        },
        {
            "x": 2,
            "y": -7,
            "z": 1,
            "elements": [
                "immersiveengineering:storage@8"
            ]
        },
        {
            "x": 3,
            "y": -7,
            "z": 1,
            "elements": [
                "immersiveengineering:stone_decoration@7"
            ]
        },
        {
            "x": 3,
            "y": -8,
            "z": 0,
            "elements": [
                "immersiveengineering:stone_decoration@7"
            ]
        },
        {
            "x": 2,
            "y": -8,
            "z": 0,
            "elements": [
                "immersiveengineering:storage@8"
            ]
        },
        {
            "x": 1,
            "y": -10,
            "z": -1,
            "elements": [
                "immersiveengineering:stone_decoration@7"
            ]
        },
        {
            "x": 0,
            "y": -10,
            "z": -1,
            "elements": [
                "immersiveengineering:stone_decoration@7"
            ]
        },
        {
            "x": -1,
            "y": -10,
            "z": -1,
            "elements": [
                "immersiveengineering:stone_decoration@7"
            ]
        },
        {
            "x": -2,
            "y": -8,
            "z": 0,
            "elements": [
                "immersiveengineering:storage@8"
            ]
        },
        {
            "x": -3,
            "y": -8,
            "z": 0,
            "elements": [
                "immersiveengineering:stone_decoration@7"
            ]
        },
        {
            "x": -1,
            "y": -2,
            "z": 3,
            "elements": [
                "immersiveengineering:stone_decoration@7"
            ]
        },
        {
            "x": -3,
            "y": -6,
            "z": 1,
            "elements": [
                "immersiveengineering:stone_decoration@7"
            ]
        },
        {
            "x": -2,
            "y": -4,
            "z": 2,
            "elements": [
                "immersiveengineering:stone_decoration@7"
            ]
        },
        {
            "x": -2,
            "y": -6,
            "z": 1,
            "elements": [
                "immersiveengineering:storage@8"
            ]
        },
        {
            "x": -1,
            "y": -4,
            "z": 2,
            "elements": [
                "immersiveengineering:storage@8"
            ]
        },
        {
            "x": 0,
            "y": -2,
            "z": 3,
            "elements": [
                "immersiveengineering:stone_decoration@7"
            ]
        },
        {
            "x": -1,
            "y": -6,
            "z": 1,
            "elements": [
                "contenttweaker:fission_control_drum@0"
            ]
        },
        {
            "x": 0,
            "y": -4,
            "z": 2,
            "elements": [
                "immersiveengineering:storage@8"
            ]
        },
        {
            "x": 1,
            "y": -2,
            "z": 3,
            "elements": [
                "immersiveengineering:stone_decoration@7"
            ]
        },
        {
            "x": 1,
            "y": -4,
            "z": 2,
            "elements": [
                "immersiveengineering:storage@8"
            ]
        },
        {
            "x": 2,
            "y": -4,
            "z": 2,
            "elements": [
                "immersiveengineering:stone_decoration@7"
            ]
        },
        {
            "x": 1,
            "y": -6,
            "z": 1,
            "elements": [
                "contenttweaker:fission_control_drum@0"
            ]
        },
        {
            "x": 2,
            "y": -6,
            "z": 1,
            "elements": [
                "immersiveengineering:storage@8"
            ]
        },
        {
            "x": 3,
            "y": -6,
            "z": 1,
            "elements": [
                "immersiveengineering:stone_decoration@7"
            ]
        },
        {
            "x": 2,
            "y": -9,
            "z": 0,
            "elements": [
                "immersiveengineering:stone_decoration@7"
            ]
        },
        {
            "x": 1,
            "y": -9,
            "z": 0,
            "elements": [
                "immersiveengineering:storage@8"
            ]
        },
        {
            "x": 0,
            "y": -9,
            "z": 0,
            "elements": [
                "immersiveengineering:storage@8"
            ]
        },
        {
            "x": -1,
            "y": -9,
            "z": 0,
            "elements": [
                "immersiveengineering:storage@8"
            ]
        },
        {
            "x": -2,
            "y": -9,
            "z": 0,
            "elements": [
                "immersiveengineering:stone_decoration@7"
            ]
        },
        {
            "x": -3,
            "y": -5,
            "z": 1,
            "elements": [
                "immersiveengineering:stone_decoration@7"
            ]
        },
        {
            "x": -2,
            "y": -3,
            "z": 2,
            "elements": [
                "immersiveengineering:stone_decoration@7"
            ]
        },
        {
            "x": -2,
            "y": -5,
            "z": 1,
            "elements": [
                "immersiveengineering:storage@8"
            ]
        },
        {
            "x": -1,
            "y": -3,
            "z": 2,
            "elements": [
                "immersiveengineering:storage@8"
            ]
        },
        {
            "x": -1,
            "y": -5,
            "z": 1,
            "elements": [
                "contenttweaker:fission_control_drum@0"
            ]
        },
        {
            "x": 0,
            "y": -3,
            "z": 2,
            "elements": [
                "immersiveengineering:storage@8"
            ]
        },
        {
            "x": 1,
            "y": -3,
            "z": 2,
            "elements": [
                "immersiveengineering:storage@8"
            ]
        },
        {
            "x": 2,
            "y": -3,
            "z": 2,
            "elements": [
                "immersiveengineering:stone_decoration@7"
            ]
        },
        {
            "x": 1,
            "y": -5,
            "z": 1,
            "elements": [
                "contenttweaker:fission_control_drum@0"
            ]
        },
        {
            "x": 2,
            "y": -5,
            "z": 1,
            "elements": [
                "immersiveengineering:storage@8"
            ]
        },
        {
            "x": 3,
            "y": -5,
            "z": 1,
            "elements": [
                "immersiveengineering:stone_decoration@7"
            ]
        },
        {
            "x": 2,
            "y": -10,
            "z": 0,
            "elements": [
                "modularmachinery:blockfluidinputhatch@2"
            ]
        },
        {
            "x": 1,
            "y": -10,
            "z": 0,
            "elements": [
                "immersiveengineering:stone_decoration@7"
            ]
        },
        {
            "x": 0,
            "y": -10,
            "z": 0,
            "elements": [
                "modularmachinery:blockoutputbus@1"
            ]
        },
        {
            "x": -1,
            "y": -10,
            "z": 0,
            "elements": [
                "immersiveengineering:stone_decoration@7"
            ]
        },
        {
            "x": -2,
            "y": -10,
            "z": 0,
            "elements": [
                "modularmachinery:blockfluidinputhatch@2"
            ]
        },
        {
            "x": -3,
            "y": -4,
            "z": 1,
            "elements": [
                "immersiveengineering:stone_decoration@7"
            ]
        },
        {
            "x": -2,
            "y": -2,
            "z": 2,
            "elements": [
                "immersiveengineering:stone_decoration@7"
            ]
        },
        {
            "x": -1,
            "y": -2,
            "z": 2,
            "elements": [
                "immersiveengineering:storage@8"
            ]
        },
        {
            "x": -2,
            "y": -4,
            "z": 1,
            "elements": [
                "immersiveengineering:storage@8"
            ]
        },
        {
            "x": -1,
            "y": -4,
            "z": 1,
            "elements": [
                "contenttweaker:fission_control_drum@0"
            ]
        },
        {
            "x": 0,
            "y": -2,
            "z": 2,
            "elements": [
                "immersiveengineering:storage@8"
            ]
        },
        {
            "x": 1,
            "y": -2,
            "z": 2,
            "elements": [
                "immersiveengineering:storage@8"
            ]
        },
        {
            "x": 2,
            "y": -2,
            "z": 2,
            "elements": [
                "immersiveengineering:stone_decoration@7"
            ]
        },
        {
            "x": 1,
            "y": -4,
            "z": 1,
            "elements": [
                "contenttweaker:fission_control_drum@0"
            ]
        },
        {
            "x": 2,
            "y": -4,
            "z": 1,
            "elements": [
                "immersiveengineering:storage@8"
            ]
        },
        {
            "x": 3,
            "y": -4,
            "z": 1,
            "elements": [
                "immersiveengineering:stone_decoration@7"
            ]
        },
        {
            "x": -3,
            "y": -3,
            "z": 1,
            "elements": [
                "immersiveengineering:stone_decoration@7"
            ]
        },
        {
            "x": -2,
            "y": -3,
            "z": 1,
            "elements": [
                "immersiveengineering:storage@8"
            ]
        },
        {
            "x": -1,
            "y": -1,
            "z": 2,
            "elements": [
                "immersiveengineering:stone_decoration@7"
            ]
        },
        {
            "x": -1,
            "y": -3,
            "z": 1,
            "elements": [
                "contenttweaker:fission_control_drum@0"
            ]
        },
        {
            "x": 0,
            "y": -1,
            "z": 2,
            "elements": [
                "immersiveengineering:stone_decoration@7"
            ]
        },
        {
            "x": 1,
            "y": -1,
            "z": 2,
            "elements": [
                "immersiveengineering:stone_decoration@7"
            ]
        },
        {
            "x": 1,
            "y": -3,
            "z": 1,
            "elements": [
                "contenttweaker:fission_control_drum@0"
            ]
        },
        {
            "x": 2,
            "y": -3,
            "z": 1,
            "elements": [
                "immersiveengineering:storage@8"
            ]
        },
        {
            "x": 3,
            "y": -3,
            "z": 1,
            "elements": [
                "immersiveengineering:stone_decoration@7"
            ]
        },
        {
            "x": 1,
            "y": -2,
            "z": -3,
            "elements": [
                "immersiveengineering:stone_decoration@7"
            ]
        },
        {
            "x": 0,
            "y": -2,
            "z": -3,
            "elements": [
                "immersiveengineering:stone_decoration@7"
            ]
        },
        {
            "x": -3,
            "y": -2,
            "z": 1,
            "elements": [
                "immersiveengineering:stone_decoration@7"
            ]
        },
        {
            "x": 0,
            "y": 0,
            "z": -2,
            "elements": [
                "modularmachinery:blockfluidoutputhatch@2"
            ]
        },
        {
            "x": -2,
            "y": -2,
            "z": 1,
            "elements": [
                "immersiveengineering:storage@8"
            ]
        },
        {
            "x": -1,
            "y": -2,
            "z": -3,
            "elements": [
                "immersiveengineering:stone_decoration@7"
            ]
        },
        {
            "x": 0,
            "y": 0,
            "z": 2,
            "elements": [
                "modularmachinery:blockfluidoutputhatch@2"
            ]
        },
        {
            "x": -1,
            "y": -2,
            "z": 1,
            "elements": [
                "contenttweaker:fission_control_drum@0"
            ]
        },
        {
            "x": 1,
            "y": -2,
            "z": 1,
            "elements": [
                "contenttweaker:fission_control_drum@0"
            ]
        },
        {
            "x": 2,
            "y": -2,
            "z": 1,
            "elements": [
                "immersiveengineering:storage@8"
            ]
        },
        {
            "x": 3,
            "y": -2,
            "z": 1,
            "elements": [
                "immersiveengineering:stone_decoration@7"
            ]
        },
        {
            "x": 1,
            "y": -3,
            "z": -3,
            "elements": [
                "immersiveengineering:stone_decoration@7"
            ]
        },
        {
            "x": 0,
            "y": -3,
            "z": -3,
            "elements": [
                "immersiveengineering:stone_decoration@7"
            ]
        },
        {
            "x": 1,
            "y": -1,
            "z": -2,
            "elements": [
                "immersiveengineering:stone_decoration@7"
            ]
        },
        {
            "x": -1,
            "y": -3,
            "z": -3,
            "elements": [
                "immersiveengineering:stone_decoration@7"
            ]
        },
        {
            "x": 0,
            "y": -1,
            "z": -2,
            "elements": [
                "immersiveengineering:stone_decoration@7"
            ]
        },
        {
            "x": -2,
            "y": -1,
            "z": 1,
            "elements": [
                "immersiveengineering:stone_decoration@7"
            ]
        },
        {
            "x": -1,
            "y": -1,
            "z": -2,
            "elements": [
                "immersiveengineering:stone_decoration@7"
            ]
        },
        {
            "x": -1,
            "y": -1,
            "z": 1,
            "elements": [
                "immersiveengineering:storage@8"
            ]
        },
        {
            "x": 0,
            "y": -1,
            "z": 1,
            "elements": [
                "immersiveengineering:storage@8"
            ]
        },
        {
            "x": 1,
            "y": -1,
            "z": 1,
            "elements": [
                "immersiveengineering:storage@8"
            ]
        },
        {
            "x": 2,
            "y": -1,
            "z": 1,
            "elements": [
                "immersiveengineering:stone_decoration@7"
            ]
        },
        {
            "x": 2,
            "y": -2,
            "z": -2,
            "elements": [
                "immersiveengineering:stone_decoration@7"
            ]
        },
        {
            "x": 1,
            "y": -4,
            "z": -3,
            "elements": [
                "immersiveengineering:stone_decoration@7"
            ]
        },
        {
            "x": 0,
            "y": -4,
            "z": -3,
            "elements": [
                "immersiveengineering:stone_decoration@7"
            ]
        },
        {
            "x": 1,
            "y": -2,
            "z": -2,
            "elements": [
                "immersiveengineering:storage@8"
            ]
        },
        {
            "x": -1,
            "y": -4,
            "z": -3,
            "elements": [
                "immersiveengineering:stone_decoration@7"
            ]
        },
        {
            "x": 0,
            "y": -2,
            "z": -2,
            "elements": [
                "immersiveengineering:storage@8"
            ]
        },
        {
            "x": 1,
            "y": 0,
            "z": -1,
            "elements": [
                "immersiveengineering:stone_decoration@7"
            ]
        },
        {
            "x": 0,
            "y": 0,
            "z": -1,
            "elements": [
                "modularmachinery:blockinputbus@1"
            ]
        },
        {
            "x": -1,
            "y": 0,
            "z": 1,
            "elements": [
                "immersiveengineering:stone_decoration@7"
            ]
        },
        {
            "x": -1,
            "y": -2,
            "z": -2,
            "elements": [
                "immersiveengineering:storage@8"
            ]
        },
        {
            "x": 0,
            "y": 0,
            "z": 1,
            "elements": [
                "modularmachinery:blockinputbus@1"
            ]
        },
        {
            "x": -2,
            "y": -2,
            "z": -2,
            "elements": [
                "immersiveengineering:stone_decoration@7"
            ]
        },
        {
            "x": -1,
            "y": 0,
            "z": -1,
            "elements": [
                "immersiveengineering:stone_decoration@7"
            ]
        },
        {
            "x": 1,
            "y": 0,
            "z": 1,
            "elements": [
                "immersiveengineering:stone_decoration@7"
            ]
        },
        {
            "x": 2,
            "y": -3,
            "z": -2,
            "elements": [
                "immersiveengineering:stone_decoration@7"
            ]
        },
        {
            "x": 1,
            "y": -5,
            "z": -3,
            "elements": [
                "immersiveengineering:stone_decoration@7"
            ]
        },
        {
            "x": 0,
            "y": -5,
            "z": -3,
            "elements": [
                "immersiveengineering:stone_decoration@7"
            ]
        },
        {
            "x": 2,
            "y": -1,
            "z": -1,
            "elements": [
                "immersiveengineering:stone_decoration@7"
            ]
        },
        {
            "x": 1,
            "y": -3,
            "z": -2,
            "elements": [
                "immersiveengineering:storage@8"
            ]
        },
        {
            "x": -1,
            "y": -5,
            "z": -3,
            "elements": [
                "immersiveengineering:stone_decoration@7"
            ]
        },
        {
            "x": 0,
            "y": -3,
            "z": -2,
            "elements": [
                "immersiveengineering:storage@8"
            ]
        },
        {
            "x": 1,
            "y": -1,
            "z": -1,
            "elements": [
                "immersiveengineering:storage@8"
            ]
        },
        {
            "x": -1,
            "y": -3,
            "z": -2,
            "elements": [
                "immersiveengineering:storage@8"
            ]
        },
        {
            "x": 0,
            "y": -1,
            "z": -1,
            "elements": [
                "immersiveengineering:storage@8"
            ]
        },
        {
            "x": -2,
            "y": -3,
            "z": -2,
            "elements": [
                "immersiveengineering:stone_decoration@7"
            ]
        },
        {
            "x": -1,
            "y": -1,
            "z": -1,
            "elements": [
                "immersiveengineering:storage@8"
            ]
        },
        {
            "x": -2,
            "y": -1,
            "z": -1,
            "elements": [
                "immersiveengineering:stone_decoration@7"
            ]
        },
        {
            "x": 3,
            "y": -2,
            "z": -1,
            "elements": [
                "immersiveengineering:stone_decoration@7"
            ]
        },
        {
            "x": 2,
            "y": -4,
            "z": -2,
            "elements": [
                "immersiveengineering:stone_decoration@7"
            ]
        },
        {
            "x": 1,
            "y": -6,
            "z": -3,
            "elements": [
                "immersiveengineering:stone_decoration@7"
            ]
        },
        {
            "x": 0,
            "y": -6,
            "z": -3,
            "elements": [
                "immersiveengineering:stone_decoration@7"
            ]
        },
        {
            "x": 2,
            "y": -2,
            "z": -1,
            "elements": [
                "immersiveengineering:storage@8"
            ]
        },
        {
            "x": 1,
            "y": -4,
            "z": -2,
            "elements": [
                "immersiveengineering:storage@8"
            ]
        },
        {
            "x": -1,
            "y": -6,
            "z": -3,
            "elements": [
                "immersiveengineering:stone_decoration@7"
            ]
        },
        {
            "x": 0,
            "y": -4,
            "z": -2,
            "elements": [
                "immersiveengineering:storage@8"
            ]
        },
        {
            "x": 1,
            "y": -2,
            "z": -1,
            "elements": [
                "contenttweaker:fission_control_drum@0"
            ]
        },
        {
            "x": -1,
            "y": -4,
            "z": -2,
            "elements": [
                "immersiveengineering:storage@8"
            ]
        },
        {
            "x": -2,
            "y": -4,
            "z": -2,
            "elements": [
                "immersiveengineering:stone_decoration@7"
            ]
        },
        {
            "x": -1,
            "y": -2,
            "z": -1,
            "elements": [
                "contenttweaker:fission_control_drum@0"
            ]
        }
    ]}
