{
    "registryname": "fusion_reactor_injector",
    "localizedname": "Fusion Reactor - Fuel Injector",
    "color": "A4A4A4",
    "parts": [
        {
            "x": -1,
            "y": 0,
            "z": 0,
            "elements": [
                "contenttweaker:outer_fusion_casing"
            ]
        },
        {
            "x": 1,
            "y": 0,
            "z": 0,
            "elements": [
                "contenttweaker:outer_fusion_casing"
            ]
        },
        {
            "x": -1,
            "y": -2,
            "z": 3,
            "elements": [
                "contenttweaker:inner_fusion_casing"
            ]
        },
        {
            "x": 0,
            "y": -2,
            "z": 3,
            "elements": [
                "fusion_plasma_heater"
            ]
        },
        {
            "x": 1,
            "y": -2,
            "z": 3,
            "elements": [
                "contenttweaker:inner_fusion_casing"
            ]
        },
        {
            "x": 1,
            "y": -3,
            "z": -1,
            "elements": [
                "contenttweaker:outer_fusion_casing"
            ]
        },
        {
            "x": 1,
            "y": -1,
            "z": 0,
            "elements": [
                "contenttweaker:outer_fusion_casing"
            ]
        },
        {
            "x": 0,
            "y": -3,
            "z": -1,
            "elements": [
                "contenttweaker:outer_fusion_casing"
            ]
        },
        {
            "x": -1,
            "y": -3,
            "z": -1,
            "elements": [
                "contenttweaker:outer_fusion_casing"
            ]
        },
        {
            "x": 0,
            "y": -1,
            "z": 0,
            "nbt": {"statusTag":{"type":"1","message":"craftcheck.failure.fluid.output.space"}},
            "elements": [
                "modularmachinery:blockcontroller"
            ]
        },
        {
            "x": -1,
            "y": -1,
            "z": 0,
            "elements": [
                "contenttweaker:outer_fusion_casing"
            ]
        },
        {
            "x": -1,
            "y": -1,
            "z": 1,
            "elements": [
                "contenttweaker:inner_fusion_casing"
            ]
        },
        {
            "x": 0,
            "y": -1,
            "z": 1,
            "elements": [
                "contenttweaker:inner_fusion_casing"
            ]
        },
        {
            "x": 1,
            "y": -1,
            "z": 1,
            "elements": [
                "contenttweaker:inner_fusion_casing"
            ]
        },
        {
            "x": -1,
            "y": -1,
            "z": 3,
            "elements": [
                "contenttweaker:outer_fusion_casing"
            ]
        },
        {
            "x": -1,
            "y": -3,
            "z": 2,
            "elements": [
                "contenttweaker:outer_fusion_casing"
            ]
        },
        {
            "x": 0,
            "y": -1,
            "z": 3,
            "elements": [
                "contenttweaker:inner_fusion_casing"
            ]
        },
        {
            "x": 1,
            "y": -1,
            "z": 3,
            "elements": [
                "contenttweaker:outer_fusion_casing"
            ]
        },
        {
            "x": 0,
            "y": -3,
            "z": 2,
            "elements": [
                "contenttweaker:inner_fusion_casing"
            ]
        },
        {
            "x": -1,
            "y": -3,
            "z": 4,
            "elements": [
                "contenttweaker:outer_fusion_casing"
            ]
        },
        {
            "x": 1,
            "y": -3,
            "z": 2,
            "elements": [
                "contenttweaker:outer_fusion_casing"
            ]
        },
        {
            "x": 0,
            "y": -3,
            "z": 4,
            "elements": [
                "modularmachinery:blockfluidinputhatch@2"
            ]
        },
        {
            "x": 1,
            "y": -3,
            "z": 4,
            "elements": [
                "contenttweaker:outer_fusion_casing"
            ]
        },
        {
            "x": 1,
            "y": -2,
            "z": 0,
            "elements": [
                "contenttweaker:inner_fusion_casing"
            ]
        },
        {
            "x": 0,
            "y": -2,
            "z": 0,
            "elements": [
                "contenttweaker:inner_fusion_casing"
            ]
        },
        {
            "x": -1,
            "y": -2,
            "z": 0,
            "elements": [
                "contenttweaker:inner_fusion_casing"
            ]
        },
        {
            "x": 1,
            "y": 0,
            "z": -1,
            "elements": [
                "contenttweaker:outer_fusion_casing"
            ]
        },
        {
            "x": 0,
            "y": 0,
            "z": -1,
            "elements": [
                "contenttweaker:outer_fusion_casing"
            ]
        },
        {
            "x": -1,
            "y": 0,
            "z": 1,
            "elements": [
                "contenttweaker:outer_fusion_casing"
            ]
        },
        {
            "x": -1,
            "y": 0,
            "z": -1,
            "elements": [
                "contenttweaker:outer_fusion_casing"
            ]
        },
        {
            "x": 0,
            "y": 0,
            "z": 1,
            "elements": [
                "contenttweaker:outer_fusion_casing"
            ]
        },
        {
            "x": 1,
            "y": 0,
            "z": 1,
            "elements": [
                "contenttweaker:outer_fusion_casing"
            ]
        },
        {
            "x": -1,
            "y": -2,
            "z": 2,
            "elements": [
                "contenttweaker:inner_fusion_casing"
            ]
        },
        {
            "x": -1,
            "y": -2,
            "z": 4,
            "elements": [
                "modularmachinery:blockenergyinputhatch@2"
            ]
        },
        {
            "x": 1,
            "y": -2,
            "z": 2,
            "elements": [
                "contenttweaker:inner_fusion_casing"
            ]
        },
        {
            "x": 0,
            "y": -2,
            "z": 4,
            "elements": [
                "contenttweaker:inner_fusion_casing"
            ]
        },
        {
            "x": 1,
            "y": -2,
            "z": 4,
            "elements": [
                "modularmachinery:blockenergyinputhatch@2"
            ]
        },
        {
            "x": 1,
            "y": -3,
            "z": 0,
            "elements": [
                "contenttweaker:outer_fusion_casing"
            ]
        },
        {
            "x": 0,
            "y": -3,
            "z": 0,
            "elements": [
                "contenttweaker:outer_fusion_casing"
            ]
        },
        {
            "x": -1,
            "y": -3,
            "z": 0,
            "elements": [
                "contenttweaker:outer_fusion_casing"
            ]
        },
        {
            "x": 1,
            "y": -1,
            "z": -1,
            "elements": [
                "contenttweaker:outer_fusion_casing"
            ]
        },
        {
            "x": 0,
            "y": -1,
            "z": -1,
            "elements": [
                "contenttweaker:fusion_coil"
            ]
        },
        {
            "x": -1,
            "y": -1,
            "z": -1,
            "elements": [
                "contenttweaker:outer_fusion_casing"
            ]
        },
        {
            "x": -1,
            "y": -1,
            "z": 2,
            "elements": [
                "contenttweaker:outer_fusion_casing"
            ]
        },
        {
            "x": -1,
            "y": -3,
            "z": 1,
            "elements": [
                "contenttweaker:inner_fusion_casing"
            ]
        },
        {
            "x": 0,
            "y": -1,
            "z": 2,
            "elements": [
                "contenttweaker:inner_fusion_casing"
            ]
        },
        {
            "x": -1,
            "y": -1,
            "z": 4,
            "elements": [
                "contenttweaker:outer_fusion_casing"
            ]
        },
        {
            "x": 1,
            "y": -1,
            "z": 2,
            "elements": [
                "contenttweaker:outer_fusion_casing"
            ]
        },
        {
            "x": 0,
            "y": -3,
            "z": 1,
            "elements": [
                "contenttweaker:inner_fusion_casing"
            ]
        },
        {
            "x": 0,
            "y": -1,
            "z": 4,
            "elements": [
                "modularmachinery:blockfluidinputhatch@2"
            ]
        },
        {
            "x": 1,
            "y": -3,
            "z": 1,
            "elements": [
                "contenttweaker:inner_fusion_casing"
            ]
        },
        {
            "x": -1,
            "y": -3,
            "z": 3,
            "elements": [
                "contenttweaker:outer_fusion_casing"
            ]
        },
        {
            "x": 1,
            "y": -1,
            "z": 4,
            "elements": [
                "contenttweaker:outer_fusion_casing"
            ]
        },
        {
            "x": 0,
            "y": -3,
            "z": 3,
            "elements": [
                "contenttweaker:inner_fusion_casing"
            ]
        },
        {
            "x": 1,
            "y": -3,
            "z": 3,
            "elements": [
                "contenttweaker:outer_fusion_casing"
            ]
        },
        {
            "x": 1,
            "y": -2,
            "z": -1,
            "elements": [
                "contenttweaker:outer_fusion_casing"
            ]
        },
        {
            "x": 0,
            "y": -2,
            "z": -1,
            "elements": [
                "contenttweaker:fusion_coil"
            ]
        },
        {
            "x": -1,
            "y": -2,
            "z": -1,
            "elements": [
                "contenttweaker:outer_fusion_casing"
            ]
        }
    ]}
