{
    "registryname": "fusion_reactor_5_toroid",
    "localizedname": "Fusion Reactor - Toroid - Radius 5",
    "color": "A4A4A4",
    "parts": [
        {
            "x": 7,
            "y": 1,
            "z": -7,
            "elements": [
                "fusion_coil"
            ]
        },
        {
            "x": -7,
            "y": 0,
            "z": 7,
            "elements": [
                "fusion_coil"
            ]
        },
        {
            "x": -7,
            "y": -1,
            "z": 7,
            "elements": [
                "fusion_coil"
            ]
        },
        {
            "x": -7,
            "y": -1,
            "z": -7,
            "elements": [
                "fusion_coil"
            ]
        },
        {
            "x": 7,
            "y": 1,
            "z": 7,
            "elements": [
                "fusion_coil"
            ]
        },
        {
            "x": -7,
            "y": 0,
            "z": -7,
            "elements": [
                "fusion_coil"
            ]
        },
        {
            "x": 7,
            "y": 0,
            "z": 7,
            "elements": [
                "fusion_coil"
            ]
        },
        {
            "x": 7,
            "y": -1,
            "z": -7,
            "elements": [
                "fusion_coil"
            ]
        },
        {
            "x": -7,
            "y": 1,
            "z": -7,
            "elements": [
                "fusion_coil"
            ]
        },
        {
            "x": 7,
            "y": -1,
            "z": 7,
            "elements": [
                "fusion_coil"
            ]
        },
        {
            "x": 7,
            "y": 0,
            "z": -7,
            "elements": [
                "fusion_coil"
            ]
        },
        {
            "x": -7,
            "y": 1,
            "z": 7,
            "elements": [
                "fusion_coil"
            ]
        },
        {
            "x": -1,
            "y": 0,
            "z": 1,
            "elements": [
                "inner_fusion_casing"
            ]
        },
        {
            "x": 0,
            "y": 1,
            "z": 1,
            "elements": [
                "modularmachinery:blockcasing@5"
            ]
        },
        {
            "x": 1,
            "y": 1,
            "z": 0,
            "elements": [
                "modularmachinery:blockcasing@5"
            ]
        },
        {
            "x": 1,
            "y": 1,
            "z": -1,
            "elements": [
                "inner_fusion_casing"
            ]
        },
        {
            "x": -1,
            "y": -1,
            "z": -1,
            "elements": [
                "inner_fusion_casing"
            ]
        },
        {
            "x": -1,
            "y": -1,
            "z": 1,
            "elements": [
                "inner_fusion_casing"
            ]
        },
        {
            "x": 1,
            "y": 1,
            "z": 1,
            "elements": [
                "inner_fusion_casing"
            ]
        },
        {
            "x": -1,
            "y": 0,
            "z": -1,
            "elements": [
                "inner_fusion_casing"
            ]
        },
        {
            "x": 0,
            "y": 1,
            "z": -1,
            "elements": [
                "modularmachinery:blockcasing@5"
            ]
        },
        {
            "x": 1,
            "y": 0,
            "z": 1,
            "elements": [
                "inner_fusion_casing"
            ]
        },
        {
            "x": 0,
            "y": -1,
            "z": 1,
            "elements": [
                "modularmachinery:blockcasing@5"
            ]
        },
        {
            "x": -1,
            "y": 1,
            "z": -1,
            "elements": [
                "inner_fusion_casing"
            ]
        },
        {
            "x": 1,
            "y": -1,
            "z": 1,
            "elements": [
                "inner_fusion_casing"
            ]
        },
        {
            "x": 1,
            "y": -1,
            "z": 0,
            "elements": [
                "modularmachinery:blockcasing@5"
            ]
        },
        {
            "x": 1,
            "y": -1,
            "z": -1,
            "elements": [
                "inner_fusion_casing"
            ]
        },
        {
            "x": -1,
            "y": 1,
            "z": 0,
            "elements": [
                "modularmachinery:blockcasing@5"
            ]
        },
        {
            "x": -1,
            "y": 1,
            "z": 1,
            "elements": [
                "inner_fusion_casing"
            ]
        },
        {
            "x": 1,
            "y": 0,
            "z": -1,
            "elements": [
                "inner_fusion_casing"
            ]
        },
        {
            "x": 0,
            "y": -1,
            "z": -1,
            "elements": [
                "modularmachinery:blockcasing@5"
            ]
        },
        {
            "x": -1,
            "y": -1,
            "z": 0,
            "elements": [
                "modularmachinery:blockcasing@5"
            ]
        },
        {
            "x": -6,
            "y": -2,
            "z": -6,
            "elements": [
                "fusion_coil"
            ]
        },
        {
            "x": -6,
            "y": 0,
            "z": 0,
            
            "elements": [
                "inner_fusion_casing"
            ]
        },
        {
            "x": 2,
            "y": 0,
            "z": -8,
            "elements": [
                "inner_fusion_casing"
            ]
        },
        {
            "x": 6,
            "y": 0,
            "z": 0,
            
            "elements": [
                "inner_fusion_casing"
            ]
        },
        {
            "x": -2,
            "y": 0,
            "z": 8,
            
            "elements": [
                "inner_fusion_casing"
            ]
        },
        {
            "x": 2,
            "y": 2,
            "z": -7,
            "elements": [
                "fusion_coil"
            ]
        },
        {
            "x": 1,
            "y": 0,
            "z": -8,
            
            "elements": [
                "inner_fusion_casing"
            ]
        },
        {
            "x": -8,
            "y": 0,
            "z": 0,
            
            "elements": [
                "inner_fusion_casing"
            ]
        },
        {
            "x": 0,
            "y": 0,
            "z": -8,
            
            "elements": [
                "inner_fusion_casing"
            ]
        },
        {
            "x": -2,
            "y": -2,
            "z": 7,
            "elements": [
                "fusion_coil"
            ]
        },
        {
            "x": -1,
            "y": 0,
            "z": 8,
            
            "elements": [
                "inner_fusion_casing"
            ]
        },
        {
            "x": 0,
            "y": 0,
            "z": 8,
            
            "elements": [
                "inner_fusion_casing"
            ]
        },
        {
            "x": 8,
            "y": 0,
            "z": 0,
            
            "elements": [
                "inner_fusion_casing"
            ]
        },
        {
            "x": -1,
            "y": 0,
            "z": -8,
            
            "elements": [
                "inner_fusion_casing"
            ]
        },
        {
            "x": -2,
            "y": 0,
            "z": -8,
            
            "elements": [
                "inner_fusion_casing"
            ]
        },
        {
            "x": 1,
            "y": 0,
            "z": 8,
            
            "elements": [
                "inner_fusion_casing"
            ]
        },
        {
            "x": -2,
            "y": 2,
            "z": -7,
            "elements": [
                "fusion_coil"
            ]
        },
        {
            "x": 2,
            "y": 0,
            "z": 8,
            
            "elements": [
                "inner_fusion_casing"
            ]
        },
        {
            "x": 2,
            "y": -2,
            "z": 7,
            "elements": [
                "fusion_coil"
            ]
        },
        {
            "x": 7,
            "y": -1,
            "z": 0,
            
            "elements": [
                "inner_fusion_casing"
            ]
        },
        {
            "x": -7,
            "y": 1,
            "z": 0,
            
            "elements": [
                "inner_fusion_casing"
            ]
        },
        {
            "x": -7,
            "y": -1,
            "z": 0,
            
            "elements": [
                "inner_fusion_casing"
            ]
        },
        {
            "x": 2,
            "y": 1,
            "z": -7,
            
            "elements": [
                "inner_fusion_casing"
            ]
        },
        {
            "x": 7,
            "y": 1,
            "z": 0,
            
            "elements": [
                "inner_fusion_casing"
            ]
        },
        {
            "x": -2,
            "y": -1,
            "z": 7,
            
            "elements": [
                "inner_fusion_casing"
            ]
        },
        {
            "x": 1,
            "y": 1,
            "z": -7,
            
            "elements": [
                "inner_fusion_casing"
            ]
        },
        {
            "x": 0,
            "y": 1,
            "z": -7,
            
            "elements": [
                "inner_fusion_casing"
            ]
        },
        {
            "x": -1,
            "y": -1,
            "z": 7,
            
            "elements": [
                "inner_fusion_casing"
            ]
        },
        {
            "x": 0,
            "y": -1,
            "z": 7,
            
            "elements": [
                "inner_fusion_casing"
            ]
        },
        {
            "x": -1,
            "y": 1,
            "z": -7,
            
            "elements": [
                "inner_fusion_casing"
            ]
        },
        {
            "x": -2,
            "y": 1,
            "z": -7,
            
            "elements": [
                "inner_fusion_casing"
            ]
        },
        {
            "x": 1,
            "y": -1,
            "z": 7,
            
            "elements": [
                "inner_fusion_casing"
            ]
        },
        {
            "x": 2,
            "y": -1,
            "z": 7,
            
            "elements": [
                "inner_fusion_casing"
            ]
        },
        {
            "x": 6,
            "y": 2,
            "z": -6,
            "elements": [
                "fusion_coil"
            ]
        },
        {
            "x": -6,
            "y": -2,
            "z": 6,
            "elements": [
                "fusion_coil"
            ]
        },
        {
            "x": 4,
            "y": 0,
            "z": -7,
            
            "elements": [
                "inner_fusion_casing"
            ]
        },
        {
            "x": -4,
            "y": 0,
            "z": 7,
            
            "elements": [
                "inner_fusion_casing"
            ]
        },
        {
            "x": 3,
            "y": 0,
            "z": -7,
            
            "elements": [
                "inner_fusion_casing"
            ]
        },
        {
            "x": 2,
            "y": -2,
            "z": -8,
            "elements": [
                "fusion_coil"
            ]
        },
        {
            "x": -3,
            "y": 0,
            "z": 7,
            
            "elements": [
                "inner_fusion_casing"
            ]
        },
        {
            "x": -2,
            "y": 2,
            "z": 8,
            "elements": [
                "fusion_coil"
            ]
        },
        {
            "x": 2,
            "y": 2,
            "z": -6,
            "elements": [
                "fusion_coil"
            ]
        },
        {
            "x": -2,
            "y": -2,
            "z": 6,
            "elements": [
                "fusion_coil"
            ]
        },
        {
            "x": -2,
            "y": -2,
            "z": -8,
            "elements": [
                "fusion_coil"
            ]
        },
        {
            "x": 2,
            "y": 2,
            "z": 8,
            "elements": [
                "fusion_coil"
            ]
        },
        {
            "x": -3,
            "y": 0,
            "z": -7,
            
            "elements": [
                "inner_fusion_casing"
            ]
        },
        {
            "x": -2,
            "y": 2,
            "z": -6,
            "elements": [
                "fusion_coil"
            ]
        },
        {
            "x": -4,
            "y": 0,
            "z": -7,
            
            "elements": [
                "inner_fusion_casing"
            ]
        },
        {
            "x": 3,
            "y": 0,
            "z": 7,
            
            "elements": [
                "inner_fusion_casing"
            ]
        },
        {
            "x": 2,
            "y": -2,
            "z": 6,
            "elements": [
                "fusion_coil"
            ]
        },
        {
            "x": 4,
            "y": 0,
            "z": 7,
            
            "elements": [
                "inner_fusion_casing"
            ]
        },
        {
            "x": -6,
            "y": 2,
            "z": -6,
            "elements": [
                "fusion_coil"
            ]
        },
        {
            "x": 6,
            "y": -2,
            "z": 6,
            "elements": [
                "fusion_coil"
            ]
        },
        {
            "x": 4,
            "y": 1,
            "z": -6,
            
            "elements": [
                "inner_fusion_casing"
            ]
        },
        {
            "x": -4,
            "y": -1,
            "z": 6,
            
            "elements": [
                "inner_fusion_casing"
            ]
        },
        {
            "x": 3,
            "y": 1,
            "z": -6,
            
            "elements": [
                "inner_fusion_casing"
            ]
        },
        {
            "x": 2,
            "y": -1,
            "z": -7,
            
            "elements": [
                "inner_fusion_casing"
            ]
        },
        {
            "x": -3,
            "y": -1,
            "z": 6,
            
            "elements": [
                "inner_fusion_casing"
            ]
        },
        {
            "x": -2,
            "y": 1,
            "z": 7,
            
            "elements": [
                "inner_fusion_casing"
            ]
        },
        {
            "x": 1,
            "y": -1,
            "z": -7,
            
            "elements": [
                "inner_fusion_casing"
            ]
        },
        {
            "x": 0,
            "y": -1,
            "z": -7,
            
            "elements": [
                "inner_fusion_casing"
            ]
        },
        {
            "x": -1,
            "y": 1,
            "z": 7,
            
            "elements": [
                "inner_fusion_casing"
            ]
        },
        {
            "x": 0,
            "y": 1,
            "z": 7,
            
            "elements": [
                "inner_fusion_casing"
            ]
        },
        {
            "x": -1,
            "y": -1,
            "z": -7,
            
            "elements": [
                "inner_fusion_casing"
            ]
        },
        {
            "x": -2,
            "y": -1,
            "z": -7,
            
            "elements": [
                "inner_fusion_casing"
            ]
        },
        {
            "x": 1,
            "y": 1,
            "z": 7,
            
            "elements": [
                "inner_fusion_casing"
            ]
        },
        {
            "x": 2,
            "y": 1,
            "z": 7,
            
            "elements": [
                "inner_fusion_casing"
            ]
        },
        {
            "x": -3,
            "y": 1,
            "z": -6,
            
            "elements": [
                "inner_fusion_casing"
            ]
        },
        {
            "x": -4,
            "y": 1,
            "z": -6,
            
            "elements": [
                "inner_fusion_casing"
            ]
        },
        {
            "x": 3,
            "y": -1,
            "z": 6,
            
            "elements": [
                "inner_fusion_casing"
            ]
        },
        {
            "x": 4,
            "y": -1,
            "z": 6,
            
            "elements": [
                "inner_fusion_casing"
            ]
        },
        {
            "x": 6,
            "y": 0,
            "z": -6,
            "elements": [
                "inner_fusion_casing"
            ]
        },
        {
            "x": -6,
            "y": 0,
            "z": 6,
            "elements": [
                "inner_fusion_casing"
            ]
        },
        {
            "x": 5,
            "y": 0,
            "z": -6,
            
            "elements": [
                "inner_fusion_casing"
            ]
        },
        {
            "x": -5,
            "y": 0,
            "z": 6,
            
            "elements": [
                "inner_fusion_casing"
            ]
        },
        {
            "x": 5,
            "y": 2,
            "z": -5,
            "elements": [
                "fusion_coil"
            ]
        },
        {
            "x": -5,
            "y": -2,
            "z": 5,
            "elements": [
                "fusion_coil"
            ]
        },
        {
            "x": 2,
            "y": -2,
            "z": -7,
            "elements": [
                "fusion_coil"
            ]
        },
        {
            "x": -2,
            "y": 2,
            "z": 7,
            "elements": [
                "fusion_coil"
            ]
        },
        {
            "x": 2,
            "y": 0,
            "z": -6,
            
            "elements": [
                "inner_fusion_casing"
            ]
        },
        {
            "x": -2,
            "y": 0,
            "z": 6,
            
            "elements": [
                "inner_fusion_casing"
            ]
        },
        {
            "x": 2,
            "y": 2,
            "z": -5,
            "elements": [
                "modularmachinery:blockfluidoutputhatch@2"
            ]
        },
        {
            "x": 1,
            "y": 0,
            "z": -6,
            
            "elements": [
                "inner_fusion_casing"
            ]
        },
        {
            "x": 0,
            "y": 0,
            "z": -6,
            
            "elements": [
                "inner_fusion_casing"
            ]
        },
        {
            "x": -2,
            "y": -2,
            "z": 5,
            "elements": [
                "modularmachinery:blockfluidinputhatch@2"
            ]
        },
        {
            "x": -1,
            "y": 0,
            "z": 6,
            
            "elements": [
                "inner_fusion_casing"
            ]
        },
        {
            "x": 0,
            "y": 0,
            "z": 6,
            
            "elements": [
                "inner_fusion_casing"
            ]
        },
        {
            "x": -2,
            "y": -2,
            "z": -7,
            "elements": [
                "fusion_coil"
            ]
        },
        {
            "x": -1,
            "y": 0,
            "z": -6,
            
            "elements": [
                "inner_fusion_casing"
            ]
        },
        {
            "x": -2,
            "y": 0,
            "z": -6,
            
            "elements": [
                "inner_fusion_casing"
            ]
        },
        {
            "x": 2,
            "y": 2,
            "z": 7,
            "elements": [
                "fusion_coil"
            ]
        },
        {
            "x": 1,
            "y": 0,
            "z": 6,
            
            "elements": [
                "inner_fusion_casing"
            ]
        },
        {
            "x": -2,
            "y": 2,
            "z": -5,
            "elements": [
                "modularmachinery:blockfluidoutputhatch@2"
            ]
        },
        {
            "x": 2,
            "y": 0,
            "z": 6,
            
            "elements": [
                "inner_fusion_casing"
            ]
        },
        {
            "x": 2,
            "y": -2,
            "z": 5,
            "elements": [
                "modularmachinery:blockfluidinputhatch@2"
            ]
        },
        {
            "x": -5,
            "y": 0,
            "z": -6,
            
            "elements": [
                "inner_fusion_casing"
            ]
        },
        {
            "x": -6,
            "y": 0,
            "z": -6,
            "elements": [
                "inner_fusion_casing"
            ]
        },
        {
            "x": -5,
            "y": 2,
            "z": -5,
            "elements": [
                "fusion_coil"
            ]
        },
        {
            "x": 5,
            "y": 0,
            "z": 6,
            
            "elements": [
                "inner_fusion_casing"
            ]
        },
        {
            "x": 6,
            "y": 0,
            "z": 6,
            "elements": [
                "inner_fusion_casing"
            ]
        },
        {
            "x": 5,
            "y": -2,
            "z": 5,
            "elements": [
                "fusion_coil"
            ]
        },
        {
            "x": 5,
            "y": 1,
            "z": -5,
            
            "elements": [
                "inner_fusion_casing"
            ]
        },
        {
            "x": 4,
            "y": -1,
            "z": -6,
            
            "elements": [
                "inner_fusion_casing"
            ]
        },
        {
            "x": -5,
            "y": -1,
            "z": 5,
            
            "elements": [
                "inner_fusion_casing"
            ]
        },
        {
            "x": -4,
            "y": 1,
            "z": 6,
            
            "elements": [
                "inner_fusion_casing"
            ]
        },
        {
            "x": 3,
            "y": -1,
            "z": -6,
            
            "elements": [
                "inner_fusion_casing"
            ]
        },
        {
            "x": -3,
            "y": 1,
            "z": 6,
            
            "elements": [
                "inner_fusion_casing"
            ]
        },
        {
            "x": 2,
            "y": 1,
            "z": -5,
            "elements": [
                "fusion_coil"
            ]
        },
        {
            "x": -2,
            "y": -1,
            "z": 5,
            "elements": [
                "fusion_coil"
            ]
        },
        {
            "x": -3,
            "y": -1,
            "z": -6,
            
            "elements": [
                "inner_fusion_casing"
            ]
        },
        {
            "x": -2,
            "y": 1,
            "z": -5,
            "elements": [
                "fusion_coil"
            ]
        },
        {
            "x": -4,
            "y": -1,
            "z": -6,
            
            "elements": [
                "inner_fusion_casing"
            ]
        },
        {
            "x": 3,
            "y": 1,
            "z": 6,
            
            "elements": [
                "inner_fusion_casing"
            ]
        },
        {
            "x": 2,
            "y": -1,
            "z": 5,
            "elements": [
                "fusion_coil"
            ]
        },
        {
            "x": 4,
            "y": 1,
            "z": 6,
            
            "elements": [
                "inner_fusion_casing"
            ]
        },
        {
            "x": -5,
            "y": 1,
            "z": -5,
            
            "elements": [
                "inner_fusion_casing"
            ]
        },
        {
            "x": 5,
            "y": -1,
            "z": 5,
            
            "elements": [
                "inner_fusion_casing"
            ]
        },
        {
            "x": 6,
            "y": -2,
            "z": -6,
            "elements": [
                "fusion_coil"
            ]
        },
        {
            "x": -6,
            "y": 2,
            "z": 6,
            "elements": [
                "fusion_coil"
            ]
        },
        {
            "x": 6,
            "y": 0,
            "z": -5,
            
            "elements": [
                "inner_fusion_casing"
            ]
        },
        {
            "x": -6,
            "y": 0,
            "z": 5,
            
            "elements": [
                "inner_fusion_casing"
            ]
        },
        {
            "x": 4,
            "y": 0,
            "z": -5,
            
            "elements": [
                "inner_fusion_casing"
            ]
        },
        {
            "x": -4,
            "y": 0,
            "z": 5,
            
            "elements": [
                "inner_fusion_casing"
            ]
        },
        {
            "x": 4,
            "y": 2,
            "z": -4,
            "elements": [
                "modularmachinery:blockfluidoutputhatch@2"
            ]
        },
        {
            "x": 3,
            "y": 0,
            "z": -5,
            
            "elements": [
                "inner_fusion_casing"
            ]
        },
        {
            "x": 2,
            "y": -2,
            "z": -6,
            "elements": [
                "fusion_coil"
            ]
        },
        {
            "x": -4,
            "y": -2,
            "z": 4,
            "elements": [
                "modularmachinery:blockfluidinputhatch@2"
            ]
        },
        {
            "x": -3,
            "y": 0,
            "z": 5,
            
            "elements": [
                "inner_fusion_casing"
            ]
        },
        {
            "x": -2,
            "y": 2,
            "z": 6,
            "elements": [
                "fusion_coil"
            ]
        },
        {
            "x": 2,
            "y": 0,
            "z": -5,
            "elements": [
                "modularmachinery:blockenergyinputhatch@2"
            ]
        },
        {
            "x": -2,
            "y": 0,
            "z": 5,
            "elements": [
                "modularmachinery:blockenergyinputhatch@2"
            ]
        },
        {
            "x": -2,
            "y": -2,
            "z": -6,
            "elements": [
                "fusion_coil"
            ]
        },
        {
            "x": -2,
            "y": 0,
            "z": -5,
            "elements": [
                "modularmachinery:blockenergyinputhatch@2"
            ]
        },
        {
            "x": 2,
            "y": 2,
            "z": 6,
            "elements": [
                "fusion_coil"
            ]
        },
        {
            "x": -3,
            "y": 0,
            "z": -5,
            
            "elements": [
                "inner_fusion_casing"
            ]
        },
        {
            "x": 2,
            "y": 0,
            "z": 5,
            "elements": [
                "modularmachinery:blockenergyinputhatch@2"
            ]
        },
        {
            "x": -4,
            "y": 0,
            "z": -5,
            
            "elements": [
                "inner_fusion_casing"
            ]
        },
        {
            "x": 3,
            "y": 0,
            "z": 5,
            
            "elements": [
                "inner_fusion_casing"
            ]
        },
        {
            "x": -4,
            "y": 2,
            "z": -4,
            "elements": [
                "modularmachinery:blockfluidoutputhatch@2"
            ]
        },
        {
            "x": 4,
            "y": 0,
            "z": 5,
            
            "elements": [
                "inner_fusion_casing"
            ]
        },
        {
            "x": -6,
            "y": 0,
            "z": -5,
            
            "elements": [
                "inner_fusion_casing"
            ]
        },
        {
            "x": 6,
            "y": 2,
            "z": 6,
            "elements": [
                "fusion_coil"
            ]
        },
        {
            "x": 4,
            "y": -2,
            "z": 4,
            "elements": [
                "modularmachinery:blockfluidinputhatch@2"
            ]
        },
        {
            "x": 6,
            "y": 0,
            "z": 5,
            
            "elements": [
                "inner_fusion_casing"
            ]
        },
        {
            "x": 6,
            "y": 1,
            "z": -4,
            
            "elements": [
                "inner_fusion_casing"
            ]
        },
        {
            "x": 5,
            "y": -1,
            "z": -5,
            
            "elements": [
                "inner_fusion_casing"
            ]
        },
        {
            "x": -6,
            "y": -1,
            "z": 4,
            
            "elements": [
                "inner_fusion_casing"
            ]
        },
        {
            "x": -5,
            "y": 1,
            "z": 5,
            
            "elements": [
                "inner_fusion_casing"
            ]
        },
        {
            "x": 4,
            "y": 1,
            "z": -4,
            "elements": [
                "fusion_coil"
            ]
        },
        {
            "x": -4,
            "y": -1,
            "z": 4,
            "elements": [
                "fusion_coil"
            ]
        },
        {
            "x": 2,
            "y": -1,
            "z": -5,
            "elements": [
                "fusion_coil"
            ]
        },
        {
            "x": -2,
            "y": 1,
            "z": 5,
            "elements": [
                "fusion_coil"
            ]
        },
        {
            "x": -2,
            "y": -1,
            "z": -5,
            "elements": [
                "fusion_coil"
            ]
        },
        {
            "x": 2,
            "y": 1,
            "z": 5,
            "elements": [
                "fusion_coil"
            ]
        },
        {
            "x": -5,
            "y": -1,
            "z": -5,
            
            "elements": [
                "inner_fusion_casing"
            ]
        },
        {
            "x": -4,
            "y": 1,
            "z": -4,
            "elements": [
                "fusion_coil"
            ]
        },
        {
            "x": 5,
            "y": 1,
            "z": 5,
            
            "elements": [
                "inner_fusion_casing"
            ]
        },
        {
            "x": 4,
            "y": -1,
            "z": 4,
            "elements": [
                "fusion_coil"
            ]
        },
        {
            "x": -6,
            "y": 1,
            "z": -4,
            
            "elements": [
                "inner_fusion_casing"
            ]
        },
        {
            "x": 6,
            "y": -1,
            "z": 4,
            
            "elements": [
                "inner_fusion_casing"
            ]
        },
        {
            "x": 7,
            "y": 0,
            "z": -4,
            
            "elements": [
                "inner_fusion_casing"
            ]
        },
        {
            "x": -7,
            "y": 0,
            "z": 4,
            
            "elements": [
                "inner_fusion_casing"
            ]
        },
        {
            "x": 5,
            "y": -2,
            "z": -5,
            "elements": [
                "fusion_coil"
            ]
        },
        {
            "x": -5,
            "y": 2,
            "z": 5,
            "elements": [
                "fusion_coil"
            ]
        },
        {
            "x": 5,
            "y": 0,
            "z": -4,
            
            "elements": [
                "inner_fusion_casing"
            ]
        },
        {
            "x": -5,
            "y": 0,
            "z": 4,
            
            "elements": [
                "inner_fusion_casing"
            ]
        },
        {
            "x": 4,
            "y": 0,
            "z": -4,
            "elements": [
                "modularmachinery:blockenergyinputhatch@2"
            ]
        },
        {
            "x": -4,
            "y": 0,
            "z": 4,
            "elements": [
                "modularmachinery:blockenergyinputhatch@2"
            ]
        },
        {
            "x": 2,
            "y": -2,
            "z": -5,
            "elements": [
                "modularmachinery:blockfluidinputhatch@2"
            ]
        },
        {
            "x": -2,
            "y": 2,
            "z": 5,
            "elements": [
                "modularmachinery:blockfluidoutputhatch@2"
            ]
        },
        {
            "x": -2,
            "y": -2,
            "z": -5,
            "elements": [
                "modularmachinery:blockfluidinputhatch@2"
            ]
        },
        {
            "x": 2,
            "y": 2,
            "z": 5,
            "elements": [
                "modularmachinery:blockfluidoutputhatch@2"
            ]
        },
        {
            "x": -5,
            "y": -2,
            "z": -5,
            "elements": [
                "fusion_coil"
            ]
        },
        {
            "x": -4,
            "y": 0,
            "z": -4,
            "elements": [
                "modularmachinery:blockenergyinputhatch@2"
            ]
        },
        {
            "x": -5,
            "y": 0,
            "z": -4,
            
            "elements": [
                "inner_fusion_casing"
            ]
        },
        {
            "x": 5,
            "y": 2,
            "z": 5,
            "elements": [
                "fusion_coil"
            ]
        },
        {
            "x": 4,
            "y": 0,
            "z": 4,
            "elements": [
                "modularmachinery:blockenergyinputhatch@2"
            ]
        },
        {
            "x": 5,
            "y": 0,
            "z": 4,
            
            "elements": [
                "inner_fusion_casing"
            ]
        },
        {
            "x": -7,
            "y": 0,
            "z": -4,
            
            "elements": [
                "inner_fusion_casing"
            ]
        },
        {
            "x": 7,
            "y": 0,
            "z": 4,
            
            "elements": [
                "inner_fusion_casing"
            ]
        },
        {
            "x": 6,
            "y": -1,
            "z": -4,
            
            "elements": [
                "inner_fusion_casing"
            ]
        },
        {
            "x": -6,
            "y": 1,
            "z": 4,
            
            "elements": [
                "inner_fusion_casing"
            ]
        },
        {
            "x": 6,
            "y": 1,
            "z": -3,
            
            "elements": [
                "inner_fusion_casing"
            ]
        },
        {
            "x": -6,
            "y": -1,
            "z": 3,
            
            "elements": [
                "inner_fusion_casing"
            ]
        },
        {
            "x": 4,
            "y": -1,
            "z": -4,
            "elements": [
                "fusion_coil"
            ]
        },
        {
            "x": -4,
            "y": 1,
            "z": 4,
            "elements": [
                "fusion_coil"
            ]
        },
        {
            "x": -4,
            "y": -1,
            "z": -4,
            "elements": [
                "fusion_coil"
            ]
        },
        {
            "x": 4,
            "y": 1,
            "z": 4,
            "elements": [
                "fusion_coil"
            ]
        },
        {
            "x": -6,
            "y": -1,
            "z": -4,
            
            "elements": [
                "inner_fusion_casing"
            ]
        },
        {
            "x": -6,
            "y": 1,
            "z": -3,
            
            "elements": [
                "inner_fusion_casing"
            ]
        },
        {
            "x": 6,
            "y": 1,
            "z": 4,
            
            "elements": [
                "inner_fusion_casing"
            ]
        },
        {
            "x": 6,
            "y": -1,
            "z": 3,
            
            "elements": [
                "inner_fusion_casing"
            ]
        },
        {
            "x": 8,
            "y": 2,
            "z": -2,
            "elements": [
                "fusion_coil"
            ]
        },
        {
            "x": 7,
            "y": 0,
            "z": -3,
            
            "elements": [
                "inner_fusion_casing"
            ]
        },
        {
            "x": -8,
            "y": -2,
            "z": 2,
            "elements": [
                "fusion_coil"
            ]
        },
        {
            "x": -7,
            "y": 0,
            "z": 3,
            
            "elements": [
                "inner_fusion_casing"
            ]
        },
        {
            "x": 7,
            "y": 2,
            "z": -2,
            "elements": [
                "fusion_coil"
            ]
        },
        {
            "x": -7,
            "y": -2,
            "z": 2,
            "elements": [
                "fusion_coil"
            ]
        },
        {
            "x": 6,
            "y": 2,
            "z": -2,
            "elements": [
                "fusion_coil"
            ]
        },
        {
            "x": 5,
            "y": 0,
            "z": -3,
            
            "elements": [
                "inner_fusion_casing"
            ]
        },
        {
            "x": 4,
            "y": -2,
            "z": -4,
            "elements": [
                "modularmachinery:blockfluidinputhatch@2"
            ]
        },
        {
            "x": -6,
            "y": -2,
            "z": 2,
            "elements": [
                "fusion_coil"
            ]
        },
        {
            "x": -5,
            "y": 0,
            "z": 3,
            
            "elements": [
                "inner_fusion_casing"
            ]
        },
        {
            "x": -4,
            "y": 2,
            "z": 4,
            "elements": [
                "modularmachinery:blockfluidoutputhatch@2"
            ]
        },
        {
            "x": 5,
            "y": 2,
            "z": -2,
            "elements": [
                "modularmachinery:blockfluidoutputhatch@2"
            ]
        },
        {
            "x": -5,
            "y": -2,
            "z": 2,
            "elements": [
                "modularmachinery:blockfluidinputhatch@2"
            ]
        },
        {
            "x": -4,
            "y": -2,
            "z": -4,
            "elements": [
                "modularmachinery:blockfluidinputhatch@2"
            ]
        },
        {
            "x": 4,
            "y": 2,
            "z": 4,
            "elements": [
                "modularmachinery:blockfluidoutputhatch@2"
            ]
        },
        {
            "x": -5,
            "y": 0,
            "z": -3,
            
            "elements": [
                "inner_fusion_casing"
            ]
        },
        {
            "x": -5,
            "y": 2,
            "z": -2,
            "elements": [
                "modularmachinery:blockfluidoutputhatch@2"
            ]
        },
        {
            "x": 5,
            "y": 0,
            "z": 3,
            
            "elements": [
                "inner_fusion_casing"
            ]
        },
        {
            "x": -7,
            "y": 0,
            "z": -3,
            
            "elements": [
                "inner_fusion_casing"
            ]
        },
        {
            "x": -6,
            "y": 2,
            "z": -2,
            "elements": [
                "fusion_coil"
            ]
        },
        {
            "x": 5,
            "y": -2,
            "z": 2,
            "elements": [
                "modularmachinery:blockfluidinputhatch@2"
            ]
        },
        {
            "x": -7,
            "y": 2,
            "z": -2,
            "elements": [
                "fusion_coil"
            ]
        },
        {
            "x": 7,
            "y": 0,
            "z": 3,
            
            "elements": [
                "inner_fusion_casing"
            ]
        },
        {
            "x": 6,
            "y": -2,
            "z": 2,
            "elements": [
                "fusion_coil"
            ]
        },
        {
            "x": 7,
            "y": -2,
            "z": 2,
            "elements": [
                "fusion_coil"
            ]
        },
        {
            "x": -8,
            "y": 2,
            "z": -2,
            "elements": [
                "fusion_coil"
            ]
        },
        {
            "x": 8,
            "y": -2,
            "z": 2,
            "elements": [
                "fusion_coil"
            ]
        },
        {
            "x": 9,
            "y": 1,
            "z": -2,
            "elements": [
                "fusion_coil"
            ]
        },
        {
            "x": -9,
            "y": -1,
            "z": 2,
            "elements": [
                "fusion_coil"
            ]
        },
        {
            "x": 7,
            "y": 1,
            "z": -2,
            
            "elements": [
                "inner_fusion_casing"
            ]
        },
        {
            "x": 6,
            "y": -1,
            "z": -3,
            
            "elements": [
                "inner_fusion_casing"
            ]
        },
        {
            "x": -7,
            "y": -1,
            "z": 2,
            
            "elements": [
                "inner_fusion_casing"
            ]
        },
        {
            "x": -6,
            "y": 1,
            "z": 3,
            
            "elements": [
                "inner_fusion_casing"
            ]
        },
        {
            "x": 5,
            "y": 1,
            "z": -2,
            "elements": [
                "fusion_coil"
            ]
        },
        {
            "x": -5,
            "y": -1,
            "z": 2,
            "elements": [
                "fusion_coil"
            ]
        },
        {
            "x": -6,
            "y": -1,
            "z": -3,
            
            "elements": [
                "inner_fusion_casing"
            ]
        },
        {
            "x": -5,
            "y": 1,
            "z": -2,
            "elements": [
                "fusion_coil"
            ]
        },
        {
            "x": 6,
            "y": 1,
            "z": 3,
            
            "elements": [
                "inner_fusion_casing"
            ]
        },
        {
            "x": 5,
            "y": -1,
            "z": 2,
            "elements": [
                "fusion_coil"
            ]
        },
        {
            "x": -7,
            "y": 1,
            "z": -2,
            
            "elements": [
                "inner_fusion_casing"
            ]
        },
        {
            "x": 7,
            "y": -1,
            "z": 2,
            
            "elements": [
                "inner_fusion_casing"
            ]
        },
        {
            "x": -9,
            "y": 1,
            "z": -2,
            "elements": [
                "fusion_coil"
            ]
        },
        {
            "x": 9,
            "y": -1,
            "z": 2,
            "elements": [
                "fusion_coil"
            ]
        },
        {
            "x": 9,
            "y": 0,
            "z": -2,
            "elements": [
                "fusion_coil"
            ]
        },
        {
            "x": 8,
            "y": 0,
            "z": -2,
            
            "elements": [
                "inner_fusion_casing"
            ]
        },
        {
            "x": -9,
            "y": 0,
            "z": 2,
            "elements": [
                "fusion_coil"
            ]
        },
        {
            "x": -8,
            "y": 0,
            "z": 2,
            
            "elements": [
                "inner_fusion_casing"
            ]
        },
        {
            "x": 6,
            "y": 0,
            "z": -2,
            
            "elements": [
                "inner_fusion_casing"
            ]
        },
        {
            "x": -6,
            "y": 0,
            "z": 2,
            
            "elements": [
                "inner_fusion_casing"
            ]
        },
        {
            "x": 5,
            "y": 0,
            "z": -2,
            "elements": [
                "modularmachinery:blockenergyinputhatch@2"
            ]
        },
        {
            "x": -5,
            "y": 0,
            "z": 2,
            "elements": [
                "modularmachinery:blockenergyinputhatch@2"
            ]
        },
        {
            "x": -5,
            "y": 0,
            "z": -2,
            "elements": [
                "modularmachinery:blockenergyinputhatch@2"
            ]
        },
        {
            "x": -6,
            "y": 0,
            "z": -2,
            
            "elements": [
                "inner_fusion_casing"
            ]
        },
        {
            "x": 5,
            "y": 0,
            "z": 2,
            "elements": [
                "modularmachinery:blockenergyinputhatch@2"
            ]
        },
        {
            "x": 6,
            "y": 0,
            "z": 2,
            
            "elements": [
                "inner_fusion_casing"
            ]
        },
        {
            "x": -8,
            "y": 0,
            "z": -2,
            
            "elements": [
                "inner_fusion_casing"
            ]
        },
        {
            "x": 8,
            "y": 0,
            "z": 2,
            
            "elements": [
                "inner_fusion_casing"
            ]
        },
        {
            "x": -9,
            "y": 0,
            "z": -2,
            "elements": [
                "fusion_coil"
            ]
        },
        {
            "x": 9,
            "y": 0,
            "z": 2,
            "elements": [
                "fusion_coil"
            ]
        },
        {
            "x": 9,
            "y": -1,
            "z": -2,
            "elements": [
                "fusion_coil"
            ]
        },
        {
            "x": -9,
            "y": 1,
            "z": 2,
            "elements": [
                "fusion_coil"
            ]
        },
        {
            "x": 7,
            "y": -1,
            "z": -2,
            
            "elements": [
                "inner_fusion_casing"
            ]
        },
        {
            "x": -7,
            "y": 1,
            "z": 2,
            
            "elements": [
                "inner_fusion_casing"
            ]
        },
        {
            "x": 7,
            "y": 1,
            "z": -1,
            
            "elements": [
                "inner_fusion_casing"
            ]
        },
        {
            "x": -7,
            "y": -1,
            "z": 1,
            
            "elements": [
                "inner_fusion_casing"
            ]
        },
        {
            "x": 5,
            "y": -1,
            "z": -2,
            "elements": [
                "fusion_coil"
            ]
        },
        {
            "x": -5,
            "y": 1,
            "z": 2,
            "elements": [
                "fusion_coil"
            ]
        },
        {
            "x": -5,
            "y": -1,
            "z": -2,
            "elements": [
                "fusion_coil"
            ]
        },
        {
            "x": 5,
            "y": 1,
            "z": 2,
            "elements": [
                "fusion_coil"
            ]
        },
        {
            "x": -7,
            "y": -1,
            "z": -2,
            
            "elements": [
                "inner_fusion_casing"
            ]
        },
        {
            "x": 2,
            "y": 1,
            "z": -9,
            "elements": [
                "fusion_coil"
            ]
        },
        {
            "x": -7,
            "y": 1,
            "z": -1,
            
            "elements": [
                "inner_fusion_casing"
            ]
        },
        {
            "x": 7,
            "y": 1,
            "z": 2,
            
            "elements": [
                "inner_fusion_casing"
            ]
        },
        {
            "x": -2,
            "y": -1,
            "z": 9,
            "elements": [
                "fusion_coil"
            ]
        },
        {
            "x": 7,
            "y": -1,
            "z": 1,
            
            "elements": [
                "inner_fusion_casing"
            ]
        },
        {
            "x": -9,
            "y": -1,
            "z": -2,
            "elements": [
                "fusion_coil"
            ]
        },
        {
            "x": 9,
            "y": 1,
            "z": 2,
            "elements": [
                "fusion_coil"
            ]
        },
        {
            "x": -2,
            "y": 1,
            "z": -9,
            "elements": [
                "fusion_coil"
            ]
        },
        {
            "x": 2,
            "y": -1,
            "z": 9,
            "elements": [
                "fusion_coil"
            ]
        },
        {
            "x": 8,
            "y": -2,
            "z": -2,
            "elements": [
                "fusion_coil"
            ]
        },
        {
            "x": 8,
            "y": 0,
            "z": -1,
            
            "elements": [
                "inner_fusion_casing"
            ]
        },
        {
            "x": 7,
            "y": -2,
            "z": -2,
            "elements": [
                "fusion_coil"
            ]
        },
        {
            "x": -8,
            "y": 2,
            "z": 2,
            "elements": [
                "fusion_coil"
            ]
        },
        {
            "x": -8,
            "y": 0,
            "z": 1,
            
            "elements": [
                "inner_fusion_casing"
            ]
        },
        {
            "x": -7,
            "y": 2,
            "z": 2,
            "elements": [
                "fusion_coil"
            ]
        },
        {
            "x": 6,
            "y": -2,
            "z": -2,
            "elements": [
                "fusion_coil"
            ]
        },
        {
            "x": -6,
            "y": 2,
            "z": 2,
            "elements": [
                "fusion_coil"
            ]
        },
        {
            "x": 6,
            "y": 0,
            "z": -1,
            
            "elements": [
                "inner_fusion_casing"
            ]
        },
        {
            "x": 5,
            "y": -2,
            "z": -2,
            "elements": [
                "modularmachinery:blockfluidinputhatch@2"
            ]
        },
        {
            "x": -6,
            "y": 0,
            "z": 1,
            
            "elements": [
                "inner_fusion_casing"
            ]
        },
        {
            "x": -5,
            "y": 2,
            "z": 2,
            "elements": [
                "modularmachinery:blockfluidoutputhatch@2"
            ]
        },
        {
            "x": -5,
            "y": -2,
            "z": -2,
            "elements": [
                "modularmachinery:blockfluidinputhatch@2"
            ]
        },
        {
            "x": -6,
            "y": -2,
            "z": -2,
            "elements": [
                "fusion_coil"
            ]
        },
        {
            "x": 5,
            "y": 2,
            "z": 2,
            "elements": [
                "modularmachinery:blockfluidoutputhatch@2"
            ]
        },
        {
            "x": -7,
            "y": -2,
            "z": -2,
            "elements": [
                "fusion_coil"
            ]
        },
        {
            "x": -6,
            "y": 0,
            "z": -1,
            
            "elements": [
                "inner_fusion_casing"
            ]
        },
        {
            "x": 6,
            "y": 2,
            "z": 2,
            "elements": [
                "fusion_coil"
            ]
        },
        {
            "x": 2,
            "y": 0,
            "z": -9,
            "elements": [
                "fusion_coil"
            ]
        },
        {
            "x": -8,
            "y": -2,
            "z": -2,
            "elements": [
                "fusion_coil"
            ]
        },
        {
            "x": 7,
            "y": 2,
            "z": 2,
            "elements": [
                "fusion_coil"
            ]
        },
        {
            "x": 6,
            "y": 0,
            "z": 1,
            
            "elements": [
                "inner_fusion_casing"
            ]
        },
        {
            "x": -2,
            "y": 0,
            "z": 9,
            "elements": [
                "fusion_coil"
            ]
        },
        {
            "x": 2,
            "y": 2,
            "z": -8,
            "elements": [
                "fusion_coil"
            ]
        },
        {
            "x": -8,
            "y": 0,
            "z": -1,
            
            "elements": [
                "inner_fusion_casing"
            ]
        },
        {
            "x": 8,
            "y": 2,
            "z": 2,
            "elements": [
                "fusion_coil"
            ]
        },
        {
            "x": -2,
            "y": -2,
            "z": 8,
            "elements": [
                "fusion_coil"
            ]
        },
        {
            "x": 8,
            "y": 0,
            "z": 1,
            
            "elements": [
                "inner_fusion_casing"
            ]
        },
        {
            "x": -2,
            "y": 0,
            "z": -9,
            "elements": [
                "fusion_coil"
            ]
        },
        {
            "x": -2,
            "y": 2,
            "z": -8,
            "elements": [
                "fusion_coil"
            ]
        },
        {
            "x": 2,
            "y": 0,
            "z": 9,
            "elements": [
                "fusion_coil"
            ]
        },
        {
            "x": 2,
            "y": -2,
            "z": 8,
            "elements": [
                "fusion_coil"
            ]
        },
        {
            "x": 7,
            "y": -1,
            "z": -1,
            
            "elements": [
                "inner_fusion_casing"
            ]
        },
        {
            "x": -7,
            "y": 1,
            "z": 1,
            
            "elements": [
                "inner_fusion_casing"
            ]
        },
        {
            "x": 2,
            "y": -1,
            "z": -9,
            "elements": [
                "fusion_coil"
            ]
        },
        {
            "x": -7,
            "y": -1,
            "z": -1,
            
            "elements": [
                "inner_fusion_casing"
            ]
        },
        {
            "x": -2,
            "y": 1,
            "z": 9,
            "elements": [
                "fusion_coil"
            ]
        },
        {
            "x": 7,
            "y": 1,
            "z": 1,
            
            "elements": [
                "inner_fusion_casing"
            ]
        },
        {
            "x": -2,
            "y": -1,
            "z": -9,
            "elements": [
                "fusion_coil"
            ]
        },
        {
            "x": 2,
            "y": 1,
            "z": 9,
            "elements": [
                "fusion_coil"
            ]
        }
    ]}
