{
    "registryname": "fusion_reactor_t2",
    "localizedname": "High-Field Fusion Reactor Toroid System",
    "modifiers": [
        {
            "x": 0,
            "y": 0,
            "z": -8,
            "nbt": {"statusTag":{"type":"0"}},
            "elements": [
                "modularmachinery:blockcontroller"
            ],
            "modifier": {
                "io": "input",
                "target": "fluid",
                "operation": 1,
                "multiplier": 0
            }
        },
        {
            "x": 0,
            "y": 0,
            "z": -8,
            "nbt": {"statusTag":{"type":"0"}},
            "elements": [
                "modularmachinery:blockcontroller"
            ],
            "modifier": {
                "io": "output",
                "target": "fluid",
                "operation": 1,
                "multiplier": 0
            }
        },
        {
            "x": 0,
            "y": 0,
            "z": -8,
            "nbt": {"statusTag":{"type":"0"}},
            "elements": [
                "modularmachinery:blockcontroller"
            ],
            "description": "Requires functioning injector system integrated to run",
            "modifier": {
                "io": "input",
                "target": "energy",
                "operation": 1,
                "multiplier": 0
            }
        }
    ],
    "parts": [
        {
            "x": -7,
            "y": -5,
            "z": 2,

            "elements": [
                "modularmachinery:blockfluidoutputhatch@1"
            ]
        },
        {
            "x": 2,
            "y": -3,
            "z": -7,

            "elements": [
                "modularmachinery:blockfluidinputhatch@1"
            ]
        },
        {
            "x": -2,
            "y": -5,
            "z": -7,

            "elements": [
                "modularmachinery:blockfluidoutputhatch@1"
            ]
        },
        {
            "x": -7,
            "y": -5,
            "z": -2,

            "elements": [
                "modularmachinery:blockfluidoutputhatch@1"
            ]
        },
        {
            "x": -7,
            "y": -3,
            "z": -2,

            "elements": [
                "modularmachinery:blockfluidinputhatch@1"
            ]
        },
        {
            "x": -2,
            "y": -3,
            "z": -7,

            "elements": [
                "modularmachinery:blockfluidinputhatch@1"
            ]
        },
        {
            "x": -2,
            "y": -3,
            "z": 7,

            "elements": [
                "modularmachinery:blockfluidinputhatch@1"
            ]
        },
        {
            "x": -2,
            "y": -5,
            "z": 7,

            "elements": [
                "modularmachinery:blockfluidoutputhatch@1"
            ]
        },
        {
            "x": 7,
            "y": -3,
            "z": 2,

            "elements": [
                "modularmachinery:blockfluidinputhatch@1"
            ]
        },
        {
            "x": 2,
            "y": -3,
            "z": 7,

            "elements": [
                "modularmachinery:blockfluidinputhatch@1"
            ]
        },
        {
            "x": 2,
            "y": -5,
            "z": 7,

            "elements": [
                "modularmachinery:blockfluidoutputhatch@1"
            ]
        },
        {
            "x": 7,
            "y": -5,
            "z": 2,

            "elements": [
                "modularmachinery:blockfluidoutputhatch@1"
            ]
        },
        {
            "x": 7,
            "y": -5,
            "z": -2,

            "elements": [
                "modularmachinery:blockfluidoutputhatch@1"
            ]
        },
        {
            "x": 7,
            "y": -3,
            "z": -2,

            "elements": [
                "modularmachinery:blockfluidinputhatch@1"
            ]
        },
        {
            "x": -7,
            "y": -3,
            "z": 2,

            "elements": [
                "modularmachinery:blockfluidinputhatch@1"
            ]
        },
        {
            "x": 2,
            "y": -5,
            "z": -7,

            "elements": [
                "modularmachinery:blockfluidoutputhatch@1"
            ]
        },
        {
            "x": -3,
            "y": -4,
            "z": -2,
            "elements": [
                "contenttweaker:fusion_reactor_inner_casing@0"
            ]
        },
        {
            "x": -1,
            "y": 0,
            "z": 0,
            "elements": [
                "immersiveengineering:storage@8"
            ]
        },
        {
            "x": 1,
            "y": 0,
            "z": 0,
            "elements": [
                "immersiveengineering:storage@8"
            ]
        },
        {
            "x": -2,
            "y": 0,
            "z": 0,
            "elements": [
                "immersiveengineering:storage@8"
            ]
        },
        {
            "x": -3,
            "y": 0,
            "z": 0,
            "elements": [
                "immersiveengineering:storage@8"
            ]
        },
        {
            "x": 2,
            "y": 0,
            "z": 0,
            "elements": [
                "immersiveengineering:storage@8"
            ]
        },
        {
            "x": 3,
            "y": 0,
            "z": 0,
            "elements": [
                "immersiveengineering:storage@8"
            ]
        },
        {
            "x": -6,
            "y": -4,
            "z": -2,
            "elements": [
                "contenttweaker:fusion_reactor_inner_casing@0"
            ]
        },
        {
            "x": -4,
            "y": 0,
            "z": 0,
            "elements": [
                "immersiveengineering:storage@8"
            ]
        },
        {
            "x": -7,
            "y": -4,
            "z": -2,
            "elements": [
                "contenttweaker:fusion_reactor_outer_casing@0"
            ]
        },
        {
            "x": -5,
            "y": 0,
            "z": 0,
            "elements": [
                "immersiveengineering:storage@8"
            ]
        },
        {
            "x": 4,
            "y": 0,
            "z": 0,
            "elements": [
                "immersiveengineering:storage@8"
            ]
        },
        {
            "x": 5,
            "y": 0,
            "z": 0,
            "elements": [
                "immersiveengineering:storage@8"
            ]
        },
        {
            "x": -6,
            "y": 0,
            "z": 0,
            "elements": [
                "immersiveengineering:storage@8"
            ]
        },
        {
            "x": -7,
            "y": 0,
            "z": 0,
            "elements": [
                "immersiveengineering:storage@8"
            ]
        },
        {
            "x": 6,
            "y": 0,
            "z": 0,
            "elements": [
                "immersiveengineering:storage@8"
            ]
        },
        {
            "x": 7,
            "y": 0,
            "z": 0,
            "elements": [
                "immersiveengineering:storage@8"
            ]
        },
        {
            "x": -8,
            "y": 0,
            "z": 0,
            "elements": [
                "immersiveengineering:storage@8"
            ]
        },
        {
            "x": 8,
            "y": 0,
            "z": 0,
            "elements": [
                "immersiveengineering:storage@8"
            ]
        },
        {
            "x": 8,
            "y": -1,
            "z": 0,
            "elements": [
                "immersiveengineering:storage@8"
            ]
        },
        {
            "x": 6,
            "y": -5,
            "z": -2,
            "elements": [
                "contenttweaker:fusion_reactor_inner_casing@0"
            ]
        },
        {
            "x": 5,
            "y": -1,
            "z": 0,
            "elements": [
                "contenttweaker:fusion_reactor_outer_casing@0"
            ]
        },
        {
            "x": 3,
            "y": -5,
            "z": -2,
            "elements": [
                "contenttweaker:fusion_reactor_inner_casing@0"
            ]
        },
        {
            "x": 4,
            "y": -1,
            "z": 0,
            "elements": [
                "contenttweaker:fusion_reactor_outer_casing@0"
            ]
        },
        {
            "x": 2,
            "y": -5,
            "z": -2,
            "elements": [
                "contenttweaker:high_current_superconductive_coil@0"
            ]
        },
        {
            "x": 3,
            "y": -1,
            "z": 0,
            "elements": [
                "contenttweaker:fusion_reactor_outer_casing@0"
            ]
        },
        {
            "x": 1,
            "y": -5,
            "z": -2,
            "elements": [
                "contenttweaker:high_current_superconductive_coil@0"
            ]
        },
        {
            "x": 0,
            "y": -5,
            "z": -2,
            "elements": [
                "contenttweaker:high_current_superconductive_coil@0"
            ]
        },
        {
            "x": 2,
            "y": -1,
            "z": 0,
            "elements": [
                "contenttweaker:high_current_superconductive_coil@0"
            ]
        },
        {
            "x": 1,
            "y": -1,
            "z": 0,
            "elements": [
                "immersiveengineering:storage@8"
            ]
        },
        {
            "x": -1,
            "y": -5,
            "z": -2,
            "elements": [
                "contenttweaker:high_current_superconductive_coil@0"
            ]
        },
        {
            "x": -2,
            "y": -5,
            "z": -2,
            "elements": [
                "contenttweaker:high_current_superconductive_coil@0"
            ]
        },
        {
            "x": 0,
            "y": -1,
            "z": 0,

            "elements": [
                "modularmachinery:blockcasing@5"
            ]
        },
        {
            "x": -3,
            "y": -5,
            "z": -2,
            "elements": [
                "contenttweaker:fusion_reactor_inner_casing@0"
            ]
        },
        {
            "x": -1,
            "y": -1,
            "z": 0,
            "elements": [
                "immersiveengineering:storage@8"
            ]
        },
        {
            "x": -2,
            "y": -1,
            "z": 0,
            "elements": [
                "contenttweaker:high_current_superconductive_coil@0"
            ]
        },
        {
            "x": -3,
            "y": -1,
            "z": 0,
            "elements": [
                "contenttweaker:fusion_reactor_outer_casing@0"
            ]
        },
        {
            "x": -6,
            "y": -5,
            "z": -2,
            "elements": [
                "contenttweaker:fusion_reactor_inner_casing@0"
            ]
        },
        {
            "x": -4,
            "y": -1,
            "z": 0,
            "elements": [
                "contenttweaker:fusion_reactor_outer_casing@0"
            ]
        },
        {
            "x": -5,
            "y": -1,
            "z": 0,
            "elements": [
                "contenttweaker:fusion_reactor_outer_casing@0"
            ]
        },
        {
            "x": -8,
            "y": -1,
            "z": 0,
            "elements": [
                "immersiveengineering:storage@8"
            ]
        },
        {
            "x": 8,
            "y": -2,
            "z": 0,
            "elements": [
                "immersiveengineering:storage@8"
            ]
        },
        {
            "x": 6,
            "y": -6,
            "z": -2,
            "elements": [
                "contenttweaker:fusion_reactor_outer_casing@0"
            ]
        },
        {
            "x": 5,
            "y": -6,
            "z": -2,
            "elements": [
                "contenttweaker:fusion_reactor_inner_casing@0"
            ]
        },
        {
            "x": 6,
            "y": -2,
            "z": 0,
            "elements": [
                "contenttweaker:fusion_reactor_outer_casing@0"
            ]
        },
        {
            "x": 4,
            "y": -6,
            "z": -2,
            "elements": [
                "contenttweaker:fusion_reactor_inner_casing@0"
            ]
        },
        {
            "x": 5,
            "y": -2,
            "z": 0,
            "elements": [
                "contenttweaker:fusion_reactor_inner_casing@0"
            ]
        },
        {
            "x": 3,
            "y": -6,
            "z": -2,
            "elements": [
                "contenttweaker:fusion_reactor_inner_casing@0"
            ]
        },
        {
            "x": 4,
            "y": -2,
            "z": 0,
            "elements": [
                "contenttweaker:fusion_reactor_inner_casing@0"
            ]
        },
        {
            "x": 2,
            "y": -6,
            "z": -2,
            "elements": [
                "contenttweaker:high_current_superconductive_coil@0"
            ]
        },
        {
            "x": 3,
            "y": -2,
            "z": 0,
            "elements": [
                "contenttweaker:fusion_reactor_outer_casing@0"
            ]
        },
        {
            "x": 1,
            "y": -6,
            "z": -2,
            "elements": [
                "contenttweaker:high_current_superconductive_coil@0"
            ]
        },
        {
            "x": 0,
            "y": -6,
            "z": -2,
            "elements": [
                "contenttweaker:high_current_superconductive_coil@0"
            ]
        },
        {
            "x": 2,
            "y": -2,
            "z": 0,
            "elements": [
                "contenttweaker:high_current_superconductive_coil@0"
            ]
        },
        {
            "x": 1,
            "y": -2,
            "z": 0,
            "elements": [
                "immersiveengineering:storage@8"
            ]
        },
        {
            "x": -1,
            "y": -6,
            "z": -2,
            "elements": [
                "contenttweaker:high_current_superconductive_coil@0"
            ]
        },
        {
            "x": -2,
            "y": -6,
            "z": -2,
            "elements": [
                "contenttweaker:high_current_superconductive_coil@0"
            ]
        },
        {
            "x": 0,
            "y": -2,
            "z": 0,

            "elements": [
                "modularmachinery:blockcasing@5"
            ]
        },
        {
            "x": -3,
            "y": -6,
            "z": -2,
            "elements": [
                "contenttweaker:fusion_reactor_inner_casing@0"
            ]
        },
        {
            "x": -1,
            "y": -2,
            "z": 0,
            "elements": [
                "immersiveengineering:storage@8"
            ]
        },
        {
            "x": -4,
            "y": -6,
            "z": -2,
            "elements": [
                "contenttweaker:fusion_reactor_inner_casing@0"
            ]
        },
        {
            "x": -2,
            "y": -2,
            "z": 0,
            "elements": [
                "contenttweaker:high_current_superconductive_coil@0"
            ]
        },
        {
            "x": -5,
            "y": -6,
            "z": -2,
            "elements": [
                "contenttweaker:fusion_reactor_inner_casing@0"
            ]
        },
        {
            "x": -3,
            "y": -2,
            "z": 0,
            "elements": [
                "contenttweaker:fusion_reactor_outer_casing@0"
            ]
        },
        {
            "x": -6,
            "y": -6,
            "z": -2,
            "elements": [
                "contenttweaker:fusion_reactor_outer_casing@0"
            ]
        },
        {
            "x": -4,
            "y": -2,
            "z": 0,
            "elements": [
                "contenttweaker:fusion_reactor_inner_casing@0"
            ]
        },
        {
            "x": -5,
            "y": -2,
            "z": 0,
            "elements": [
                "contenttweaker:fusion_reactor_inner_casing@0"
            ]
        },
        {
            "x": -6,
            "y": -2,
            "z": 0,
            "elements": [
                "contenttweaker:fusion_reactor_outer_casing@0"
            ]
        },
        {
            "x": -8,
            "y": -2,
            "z": 0,
            "elements": [
                "immersiveengineering:storage@8"
            ]
        },
        {
            "x": 8,
            "y": -3,
            "z": 0,
            "elements": [
                "immersiveengineering:storage@8"
            ]
        },
        {
            "x": 7,
            "y": -3,
            "z": 0,
            "elements": [
                "contenttweaker:fusion_reactor_outer_casing@0"
            ]
        },
        {
            "x": 5,
            "y": -7,
            "z": -2,
 
            "elements": [
                "modularmachinery:blockfluidinputhatch@2"
            ]
        },
        {
            "x": 6,
            "y": -3,
            "z": 0,
            "elements": [
                "contenttweaker:fusion_reactor_inner_casing@0"
            ]
        },
        {
            "x": 4,
            "y": -7,
            "z": -2,
            "elements": [
                "contenttweaker:fusion_reactor_outer_casing@0"
            ]
        },
        {
            "x": 3,
            "y": -7,
            "z": -2,
            "elements": [
                "contenttweaker:high_current_superconductive_coil@0"
            ]
        },
        {
            "x": 4,
            "y": -3,
            "z": 0,
            "elements": [
                "contenttweaker:fusion_reactor_inner_casing@0"
            ]
        },
        {
            "x": 2,
            "y": -7,
            "z": -2,
            "elements": [
                "contenttweaker:high_current_superconductive_coil@0"
            ]
        },
        {
            "x": 3,
            "y": -3,
            "z": 0,
            "elements": [
                "contenttweaker:fusion_reactor_outer_casing@0"
            ]
        },
        {
            "x": 1,
            "y": -7,
            "z": -2,
            "elements": [
                "contenttweaker:high_current_superconductive_coil@0"
            ]
        },
        {
            "x": 0,
            "y": -7,
            "z": -2,
            "elements": [
                "contenttweaker:high_current_superconductive_coil@0"
            ]
        },
        {
            "x": 2,
            "y": -3,
            "z": 0,
            "elements": [
                "contenttweaker:high_current_superconductive_coil@0"
            ]
        },
        {
            "x": 1,
            "y": -3,
            "z": 0,
            "elements": [
                "immersiveengineering:storage@8"
            ]
        },
        {
            "x": -1,
            "y": -7,
            "z": -2,
            "elements": [
                "contenttweaker:high_current_superconductive_coil@0"
            ]
        },
        {
            "x": -2,
            "y": -7,
            "z": -2,
            "elements": [
                "contenttweaker:high_current_superconductive_coil@0"
            ]
        },
        {
            "x": 0,
            "y": -3,
            "z": 0,

            "elements": [
                "modularmachinery:blockcasing@5"
            ]
        },
        {
            "x": -3,
            "y": -7,
            "z": -2,
            "elements": [
                "contenttweaker:high_current_superconductive_coil@0"
            ]
        },
        {
            "x": -1,
            "y": -3,
            "z": 0,
            "elements": [
                "immersiveengineering:storage@8"
            ]
        },
        {
            "x": -4,
            "y": -7,
            "z": -2,
            "elements": [
                "contenttweaker:fusion_reactor_outer_casing@0"
            ]
        },
        {
            "x": -2,
            "y": -3,
            "z": 0,
            "elements": [
                "contenttweaker:high_current_superconductive_coil@0"
            ]
        },
        {
            "x": -5,
            "y": -7,
            "z": -2,
 
            "elements": [
                "modularmachinery:blockfluidinputhatch@2"
            ]
        },
        {
            "x": -3,
            "y": -3,
            "z": 0,
            "elements": [
                "contenttweaker:fusion_reactor_outer_casing@0"
            ]
        },
        {
            "x": -4,
            "y": -3,
            "z": 0,
            "elements": [
                "contenttweaker:fusion_reactor_inner_casing@0"
            ]
        },
        {
            "x": -6,
            "y": -3,
            "z": 0,
            "elements": [
                "contenttweaker:fusion_reactor_inner_casing@0"
            ]
        },
        {
            "x": -7,
            "y": -3,
            "z": 0,
            "elements": [
                "contenttweaker:fusion_reactor_outer_casing@0"
            ]
        },
        {
            "x": -8,
            "y": -3,
            "z": 0,
            "elements": [
                "immersiveengineering:storage@8"
            ]
        },
        {
            "x": 8,
            "y": -4,
            "z": 0,
            "elements": [
                "immersiveengineering:storage@8"
            ]
        },
        {
            "x": 7,
            "y": -4,
            "z": 0,
            "elements": [
                "contenttweaker:fusion_reactor_outer_casing@0"
            ]
        },
        {
            "x": 6,
            "y": -4,
            "z": 0,
            "elements": [
                "contenttweaker:fusion_reactor_inner_casing@0"
            ]
        },
        {
            "x": 4,
            "y": -4,
            "z": 0,
            "elements": [
                "contenttweaker:fusion_reactor_inner_casing@0"
            ]
        },
        {
            "x": 2,
            "y": -8,
            "z": -2,
            "elements": [
                "immersiveengineering:storage@8"
            ]
        },
        {
            "x": 3,
            "y": -4,
            "z": 0,
            "elements": [
                "contenttweaker:fusion_reactor_outer_casing@0"
            ]
        },
        {
            "x": 1,
            "y": -8,
            "z": -2,

            "elements": [
                "modularmachinery:blockenergyinputhatch@2"
            ]
        },
        {
            "x": 0,
            "y": -8,
            "z": -2,
            "elements": [
                "immersiveengineering:storage@8"
            ]
        },
        {
            "x": 2,
            "y": -4,
            "z": 0,
            "elements": [
                "contenttweaker:high_current_superconductive_coil@0"
            ]
        },
        {
            "x": 1,
            "y": -4,
            "z": 0,
            "elements": [
                "immersiveengineering:storage@8"
            ]
        },
        {
            "x": -1,
            "y": -8,
            "z": -2,

            "elements": [
                "modularmachinery:blockenergyinputhatch@2"
            ]
        },
        {
            "x": -2,
            "y": -8,
            "z": -2,
            "elements": [
                "immersiveengineering:storage@8"
            ]
        },
        {
            "x": 0,
            "y": -4,
            "z": 0,

            "elements": [
                "modularmachinery:blockcasing@5"
            ]
        },
        {
            "x": -1,
            "y": -4,
            "z": 0,
            "elements": [
                "immersiveengineering:storage@8"
            ]
        },
        {
            "x": -2,
            "y": -4,
            "z": 0,
            "elements": [
                "contenttweaker:high_current_superconductive_coil@0"
            ]
        },
        {
            "x": -3,
            "y": -4,
            "z": 0,
            "elements": [
                "contenttweaker:fusion_reactor_outer_casing@0"
            ]
        },
        {
            "x": -4,
            "y": -4,
            "z": 0,
            "elements": [
                "contenttweaker:fusion_reactor_inner_casing@0"
            ]
        },
        {
            "x": -6,
            "y": -4,
            "z": 0,
            "elements": [
                "contenttweaker:fusion_reactor_inner_casing@0"
            ]
        },
        {
            "x": -7,
            "y": -4,
            "z": 0,
            "elements": [
                "contenttweaker:fusion_reactor_outer_casing@0"
            ]
        },
        {
            "x": -8,
            "y": -4,
            "z": 0,
            "elements": [
                "immersiveengineering:storage@8"
            ]
        },
        {
            "x": 8,
            "y": -5,
            "z": 0,
            "elements": [
                "immersiveengineering:storage@8"
            ]
        },
        {
            "x": 7,
            "y": -5,
            "z": 0,
            "elements": [
                "contenttweaker:fusion_reactor_outer_casing@0"
            ]
        },
        {
            "x": 6,
            "y": -5,
            "z": 0,
            "elements": [
                "contenttweaker:fusion_reactor_inner_casing@0"
            ]
        },
        {
            "x": 4,
            "y": -5,
            "z": 0,
            "elements": [
                "contenttweaker:fusion_reactor_inner_casing@0"
            ]
        },
        {
            "x": 3,
            "y": -5,
            "z": 0,
            "elements": [
                "contenttweaker:fusion_reactor_outer_casing@0"
            ]
        },
        {
            "x": 2,
            "y": -5,
            "z": 0,
            "elements": [
                "contenttweaker:high_current_superconductive_coil@0"
            ]
        },
        {
            "x": 1,
            "y": -5,
            "z": 0,
            "elements": [
                "immersiveengineering:storage@8"
            ]
        },
        {
            "x": 0,
            "y": -5,
            "z": 0,

            "elements": [
                "modularmachinery:blockcasing@5"
            ]
        },
        {
            "x": -1,
            "y": -5,
            "z": 0,
            "elements": [
                "immersiveengineering:storage@8"
            ]
        },
        {
            "x": -2,
            "y": -5,
            "z": 0,
            "elements": [
                "contenttweaker:high_current_superconductive_coil@0"
            ]
        },
        {
            "x": -3,
            "y": -5,
            "z": 0,
            "elements": [
                "contenttweaker:fusion_reactor_outer_casing@0"
            ]
        },
        {
            "x": -4,
            "y": -5,
            "z": 0,
            "elements": [
                "contenttweaker:fusion_reactor_inner_casing@0"
            ]
        },
        {
            "x": -6,
            "y": -5,
            "z": 0,
            "elements": [
                "contenttweaker:fusion_reactor_inner_casing@0"
            ]
        },
        {
            "x": -7,
            "y": -5,
            "z": 0,
            "elements": [
                "contenttweaker:fusion_reactor_outer_casing@0"
            ]
        },
        {
            "x": -8,
            "y": -5,
            "z": 0,
            "elements": [
                "immersiveengineering:storage@8"
            ]
        },
        {
            "x": 8,
            "y": -6,
            "z": 0,
            "elements": [
                "immersiveengineering:storage@8"
            ]
        },
        {
            "x": 6,
            "y": -6,
            "z": 0,
            "elements": [
                "contenttweaker:fusion_reactor_outer_casing@0"
            ]
        },
        {
            "x": 5,
            "y": -6,
            "z": 0,
            "elements": [
                "contenttweaker:fusion_reactor_inner_casing@0"
            ]
        },
        {
            "x": 4,
            "y": -6,
            "z": 0,
            "elements": [
                "contenttweaker:fusion_reactor_inner_casing@0"
            ]
        },
        {
            "x": 3,
            "y": -6,
            "z": 0,
            "elements": [
                "contenttweaker:fusion_reactor_outer_casing@0"
            ]
        },
        {
            "x": 2,
            "y": -6,
            "z": 0,
            "elements": [
                "contenttweaker:high_current_superconductive_coil@0"
            ]
        },
        {
            "x": 1,
            "y": -6,
            "z": 0,
            "elements": [
                "immersiveengineering:storage@8"
            ]
        },
        {
            "x": 0,
            "y": -6,
            "z": 0,

            "elements": [
                "modularmachinery:blockcasing@5"
            ]
        },
        {
            "x": -1,
            "y": -6,
            "z": 0,
            "elements": [
                "immersiveengineering:storage@8"
            ]
        },
        {
            "x": -2,
            "y": -6,
            "z": 0,
            "elements": [
                "contenttweaker:high_current_superconductive_coil@0"
            ]
        },
        {
            "x": -3,
            "y": -6,
            "z": 0,
            "elements": [
                "contenttweaker:fusion_reactor_outer_casing@0"
            ]
        },
        {
            "x": -4,
            "y": -6,
            "z": 0,
            "elements": [
                "contenttweaker:fusion_reactor_inner_casing@0"
            ]
        },
        {
            "x": -5,
            "y": -6,
            "z": 0,
            "elements": [
                "contenttweaker:fusion_reactor_inner_casing@0"
            ]
        },
        {
            "x": -6,
            "y": -6,
            "z": 0,
            "elements": [
                "contenttweaker:fusion_reactor_outer_casing@0"
            ]
        },
        {
            "x": -8,
            "y": -6,
            "z": 0,
            "elements": [
                "immersiveengineering:storage@8"
            ]
        },
        {
            "x": 8,
            "y": -7,
            "z": 0,
            "elements": [
                "immersiveengineering:storage@8"
            ]
        },
        {
            "x": 5,
            "y": -7,
            "z": 0,
            "elements": [
                "contenttweaker:fusion_reactor_outer_casing@0"
            ]
        },
        {
            "x": 4,
            "y": -7,
            "z": 0,
            "elements": [
                "contenttweaker:fusion_reactor_outer_casing@0"
            ]
        },
        {
            "x": 3,
            "y": -7,
            "z": 0,
            "elements": [
                "contenttweaker:fusion_reactor_outer_casing@0"
            ]
        },
        {
            "x": 2,
            "y": -7,
            "z": 0,
            "elements": [
                "contenttweaker:high_current_superconductive_coil@0"
            ]
        },
        {
            "x": 1,
            "y": -7,
            "z": 0,
            "elements": [
                "immersiveengineering:storage@8"
            ]
        },
        {
            "x": 0,
            "y": -7,
            "z": 0,

            "elements": [
                "modularmachinery:blockcasing@5"
            ]
        },
        {
            "x": -1,
            "y": -7,
            "z": 0,
            "elements": [
                "immersiveengineering:storage@8"
            ]
        },
        {
            "x": -2,
            "y": -7,
            "z": 0,
            "elements": [
                "contenttweaker:high_current_superconductive_coil@0"
            ]
        },
        {
            "x": -3,
            "y": -7,
            "z": 0,
            "elements": [
                "contenttweaker:fusion_reactor_outer_casing@0"
            ]
        },
        {
            "x": -4,
            "y": -7,
            "z": 0,
            "elements": [
                "contenttweaker:fusion_reactor_outer_casing@0"
            ]
        },
        {
            "x": -5,
            "y": -7,
            "z": 0,
            "elements": [
                "contenttweaker:fusion_reactor_outer_casing@0"
            ]
        },
        {
            "x": -8,
            "y": -7,
            "z": 0,
            "elements": [
                "immersiveengineering:storage@8"
            ]
        },
        {
            "x": 8,
            "y": -8,
            "z": 0,
            "elements": [
                "immersiveengineering:storage@8"
            ]
        },
        {
            "x": 7,
            "y": -8,
            "z": 0,
            "elements": [
                "immersiveengineering:storage@8"
            ]
        },
        {
            "x": 6,
            "y": -8,
            "z": 0,
            "elements": [
                "immersiveengineering:storage@8"
            ]
        },
        {
            "x": 5,
            "y": -8,
            "z": 0,
            "elements": [
                "immersiveengineering:storage@8"
            ]
        },
        {
            "x": 4,
            "y": -8,
            "z": 0,
            "elements": [
                "immersiveengineering:storage@8"
            ]
        },
        {
            "x": 3,
            "y": -8,
            "z": 0,
            "elements": [
                "immersiveengineering:storage@8"
            ]
        },
        {
            "x": 2,
            "y": -8,
            "z": 0,
            "elements": [
                "immersiveengineering:storage@8"
            ]
        },
        {
            "x": 1,
            "y": -8,
            "z": 0,
            "elements": [
                "immersiveengineering:storage@8"
            ]
        },
        {
            "x": 0,
            "y": -8,
            "z": 0,
            "elements": [
                "modularmachinery:blockcontroller@2"
            ]
        },
        {
            "x": -1,
            "y": -8,
            "z": 0,
            "elements": [
                "immersiveengineering:storage@8"
            ]
        },
        {
            "x": -2,
            "y": -8,
            "z": 0,
            "elements": [
                "immersiveengineering:storage@8"
            ]
        },
        {
            "x": -3,
            "y": -8,
            "z": 0,
            "elements": [
                "immersiveengineering:storage@8"
            ]
        },
        {
            "x": -4,
            "y": -8,
            "z": 0,
            "elements": [
                "immersiveengineering:storage@8"
            ]
        },
        {
            "x": -5,
            "y": -8,
            "z": 0,
            "elements": [
                "immersiveengineering:storage@8"
            ]
        },
        {
            "x": -6,
            "y": -8,
            "z": 0,
            "elements": [
                "immersiveengineering:storage@8"
            ]
        },
        {
            "x": -7,
            "y": -8,
            "z": 0,
            "elements": [
                "immersiveengineering:storage@8"
            ]
        },
        {
            "x": -8,
            "y": -8,
            "z": 0,
            "elements": [
                "immersiveengineering:storage@8"
            ]
        },
        {
            "x": 0,
            "y": -8,
            "z": 7,
            "elements": [
                "immersiveengineering:storage@8"
            ]
        },
        {
            "x": -1,
            "y": -5,
            "z": 7,
            "elements": [
                "contenttweaker:high_current_superconductive_coil@0"
            ]
        },
        {
            "x": 0,
            "y": -5,
            "z": 7,
            "elements": [
                "contenttweaker:fusion_reactor_outer_casing@0"
            ]
        },
        {
            "x": 1,
            "y": -5,
            "z": 7,
            "elements": [
                "contenttweaker:high_current_superconductive_coil@0"
            ]
        },
        {
            "x": -5,
            "y": -8,
            "z": 5,
            "elements": [
                "immersiveengineering:storage@8"
            ]
        },
        {
            "x": -2,
            "y": -4,
            "z": 7,
            "elements": [
                "contenttweaker:fusion_reactor_outer_casing@0"
            ]
        },
        {
            "x": -1,
            "y": -4,
            "z": 7,
            "elements": [
                "contenttweaker:high_current_superconductive_coil@0"
            ]
        },
        {
            "x": 0,
            "y": -4,
            "z": 7,
            "elements": [
                "contenttweaker:fusion_reactor_outer_casing@0"
            ]
        },
        {
            "x": 1,
            "y": -4,
            "z": 7,
            "elements": [
                "contenttweaker:high_current_superconductive_coil@0"
            ]
        },
        {
            "x": 0,
            "y": -8,
            "z": 5,
            "elements": [
                "immersiveengineering:storage@8"
            ]
        },
        {
            "x": 2,
            "y": -4,
            "z": 7,
            "elements": [
                "contenttweaker:fusion_reactor_outer_casing@0"
            ]
        },
        {
            "x": 5,
            "y": -8,
            "z": 5,
            "elements": [
                "immersiveengineering:storage@8"
            ]
        },
        {
            "x": -1,
            "y": -3,
            "z": 7,
            "elements": [
                "contenttweaker:high_current_superconductive_coil@0"
            ]
        },
        {
            "x": -2,
            "y": -7,
            "z": 5,
 
            "elements": [
                "modularmachinery:blockfluidinputhatch@2"
            ]
        },
        {
            "x": 0,
            "y": -3,
            "z": 7,
            "elements": [
                "contenttweaker:fusion_reactor_outer_casing@0"
            ]
        },
        {
            "x": 1,
            "y": -3,
            "z": 7,
            "elements": [
                "contenttweaker:high_current_superconductive_coil@0"
            ]
        },
        {
            "x": -1,
            "y": -7,
            "z": 5,
            "elements": [
                "contenttweaker:high_current_superconductive_coil@0"
            ]
        },
        {
            "x": 0,
            "y": -7,
            "z": 5,
            "elements": [
                "contenttweaker:fusion_reactor_outer_casing@0"
            ]
        },
        {
            "x": 1,
            "y": -7,
            "z": 5,
            "elements": [
                "contenttweaker:high_current_superconductive_coil@0"
            ]
        },
        {
            "x": 2,
            "y": -7,
            "z": 5,
 
            "elements": [
                "modularmachinery:blockfluidinputhatch@2"
            ]
        },
        {
            "x": -5,
            "y": -6,
            "z": 5,
            "elements": [
                "contenttweaker:high_current_superconductive_coil@0"
            ]
        },
        {
            "x": -4,
            "y": -6,
            "z": 5,
            "elements": [
                "contenttweaker:fusion_reactor_outer_casing@0"
            ]
        },
        {
            "x": -3,
            "y": -6,
            "z": 5,
            "elements": [
                "contenttweaker:high_current_superconductive_coil@0"
            ]
        },
        {
            "x": -2,
            "y": -6,
            "z": 5,
            "elements": [
                "contenttweaker:fusion_reactor_inner_casing@0"
            ]
        },
        {
            "x": -1,
            "y": -6,
            "z": 5,
            "elements": [
                "contenttweaker:fusion_reactor_inner_casing@0"
            ]
        },
        {
            "x": 0,
            "y": -6,
            "z": 5,
            "elements": [
                "contenttweaker:fusion_reactor_inner_casing@0"
            ]
        },
        {
            "x": 1,
            "y": -6,
            "z": 5,
            "elements": [
                "contenttweaker:fusion_reactor_inner_casing@0"
            ]
        },
        {
            "x": 2,
            "y": -6,
            "z": 5,
            "elements": [
                "contenttweaker:fusion_reactor_inner_casing@0"
            ]
        },
        {
            "x": 3,
            "y": -6,
            "z": 5,
            "elements": [
                "contenttweaker:high_current_superconductive_coil@0"
            ]
        },
        {
            "x": 4,
            "y": -6,
            "z": 5,
            "elements": [
                "contenttweaker:fusion_reactor_outer_casing@0"
            ]
        },
        {
            "x": 5,
            "y": -6,
            "z": 5,
            "elements": [
                "contenttweaker:high_current_superconductive_coil@0"
            ]
        },
        {
            "x": -5,
            "y": -5,
            "z": 5,
            "elements": [
                "contenttweaker:high_current_superconductive_coil@0"
            ]
        },
        {
            "x": -4,
            "y": -5,
            "z": 5,
            "elements": [
                "contenttweaker:fusion_reactor_inner_casing@0"
            ]
        },
        {
            "x": -3,
            "y": -5,
            "z": 5,
            "elements": [
                "contenttweaker:fusion_reactor_inner_casing@0"
            ]
        },
        {
            "x": 3,
            "y": -5,
            "z": 5,
            "elements": [
                "contenttweaker:fusion_reactor_inner_casing@0"
            ]
        },
        {
            "x": 4,
            "y": -5,
            "z": 5,
            "elements": [
                "contenttweaker:fusion_reactor_inner_casing@0"
            ]
        },
        {
            "x": 5,
            "y": -5,
            "z": 5,
            "elements": [
                "contenttweaker:high_current_superconductive_coil@0"
            ]
        },
        {
            "x": -5,
            "y": -4,
            "z": 5,
            "elements": [
                "contenttweaker:high_current_superconductive_coil@0"
            ]
        },
        {
            "x": -4,
            "y": -4,
            "z": 5,
            "elements": [
                "contenttweaker:fusion_reactor_inner_casing@0"
            ]
        },
        {
            "x": 0,
            "y": 0,
            "z": -7,
            "elements": [
                "immersiveengineering:storage@8"
            ]
        },
        {
            "x": -3,
            "y": -4,
            "z": 5,
            "elements": [
                "contenttweaker:fusion_reactor_inner_casing@0"
            ]
        },
        {
            "x": 0,
            "y": 0,
            "z": 7,
            "elements": [
                "immersiveengineering:storage@8"
            ]
        },
        {
            "x": -3,
            "y": -8,
            "z": 3,
            "elements": [
                "immersiveengineering:storage@8"
            ]
        },
        {
            "x": -1,
            "y": -8,
            "z": 3,

            "elements": [
                "modularmachinery:blockfluidoutputhatch@1"
            ]
        },
        {
            "x": 0,
            "y": -8,
            "z": 3,
            "elements": [
                "immersiveengineering:storage@8"
            ]
        },
        {
            "x": 3,
            "y": -4,
            "z": 5,
            "elements": [
                "contenttweaker:fusion_reactor_inner_casing@0"
            ]
        },
        {
            "x": 1,
            "y": -8,
            "z": 3,

            "elements": [
                "modularmachinery:blockfluidoutputhatch@1"
            ]
        },
        {
            "x": 4,
            "y": -4,
            "z": 5,
            "elements": [
                "contenttweaker:fusion_reactor_inner_casing@0"
            ]
        },
        {
            "x": 5,
            "y": -4,
            "z": 5,
            "elements": [
                "contenttweaker:high_current_superconductive_coil@0"
            ]
        },
        {
            "x": 3,
            "y": -8,
            "z": 3,
            "elements": [
                "immersiveengineering:storage@8"
            ]
        },
        {
            "x": -5,
            "y": -3,
            "z": 5,
            "elements": [
                "contenttweaker:high_current_superconductive_coil@0"
            ]
        },
        {
            "x": -4,
            "y": -3,
            "z": 5,
            "elements": [
                "contenttweaker:fusion_reactor_inner_casing@0"
            ]
        },
        {
            "x": -3,
            "y": -3,
            "z": 5,
            "elements": [
                "contenttweaker:fusion_reactor_inner_casing@0"
            ]
        },
        {
            "x": -4,
            "y": -7,
            "z": 3,
            "elements": [
                "contenttweaker:high_current_superconductive_coil@0"
            ]
        },
        {
            "x": -3,
            "y": -7,
            "z": 3,
            "elements": [
                "contenttweaker:high_current_superconductive_coil@0"
            ]
        },
        {
            "x": -2,
            "y": -7,
            "z": 3,
            "elements": [
                "contenttweaker:high_current_superconductive_coil@0"
            ]
        },
        {
            "x": -1,
            "y": -7,
            "z": 3,
            "elements": [
                "contenttweaker:high_current_superconductive_coil@0"
            ]
        },
        {
            "x": 0,
            "y": -7,
            "z": 3,
            "elements": [
                "contenttweaker:fusion_reactor_outer_casing@0"
            ]
        },
        {
            "x": 3,
            "y": -3,
            "z": 5,
            "elements": [
                "contenttweaker:fusion_reactor_inner_casing@0"
            ]
        },
        {
            "x": 1,
            "y": -7,
            "z": 3,
            "elements": [
                "contenttweaker:high_current_superconductive_coil@0"
            ]
        },
        {
            "x": 4,
            "y": -3,
            "z": 5,
            "elements": [
                "contenttweaker:fusion_reactor_inner_casing@0"
            ]
        },
        {
            "x": 2,
            "y": -7,
            "z": 3,
            "elements": [
                "contenttweaker:high_current_superconductive_coil@0"
            ]
        },
        {
            "x": 5,
            "y": -3,
            "z": 5,
            "elements": [
                "contenttweaker:high_current_superconductive_coil@0"
            ]
        },
        {
            "x": 3,
            "y": -7,
            "z": 3,
            "elements": [
                "contenttweaker:high_current_superconductive_coil@0"
            ]
        },
        {
            "x": 4,
            "y": -7,
            "z": 3,
            "elements": [
                "contenttweaker:high_current_superconductive_coil@0"
            ]
        },
        {
            "x": -5,
            "y": -2,
            "z": 5,
            "elements": [
                "contenttweaker:high_current_superconductive_coil@0"
            ]
        },
        {
            "x": -4,
            "y": -2,
            "z": 5,
            "elements": [
                "contenttweaker:fusion_reactor_outer_casing@0"
            ]
        },
        {
            "x": -5,
            "y": -6,
            "z": 3,
            "elements": [
                "contenttweaker:high_current_superconductive_coil@0"
            ]
        },
        {
            "x": -3,
            "y": -2,
            "z": 5,
            "elements": [
                "contenttweaker:high_current_superconductive_coil@0"
            ]
        },
        {
            "x": -4,
            "y": -6,
            "z": 3,
            "elements": [
                "contenttweaker:fusion_reactor_inner_casing@0"
            ]
        },
        {
            "x": -2,
            "y": -2,
            "z": 5,
            "elements": [
                "contenttweaker:fusion_reactor_inner_casing@0"
            ]
        },
        {
            "x": -3,
            "y": -6,
            "z": 3,
            "elements": [
                "contenttweaker:fusion_reactor_inner_casing@0"
            ]
        },
        {
            "x": -1,
            "y": -2,
            "z": 5,
            "elements": [
                "contenttweaker:fusion_reactor_inner_casing@0"
            ]
        },
        {
            "x": -2,
            "y": -6,
            "z": 3,
            "elements": [
                "contenttweaker:fusion_reactor_inner_casing@0"
            ]
        },
        {
            "x": 0,
            "y": -2,
            "z": 5,
            "elements": [
                "contenttweaker:fusion_reactor_inner_casing@0"
            ]
        },
        {
            "x": 1,
            "y": -2,
            "z": 5,
            "elements": [
                "contenttweaker:fusion_reactor_inner_casing@0"
            ]
        },
        {
            "x": -1,
            "y": -6,
            "z": 3,
            "elements": [
                "contenttweaker:high_current_superconductive_coil@0"
            ]
        },
        {
            "x": 0,
            "y": -6,
            "z": 3,
            "elements": [
                "contenttweaker:fusion_reactor_outer_casing@0"
            ]
        },
        {
            "x": 2,
            "y": -2,
            "z": 5,
            "elements": [
                "contenttweaker:fusion_reactor_inner_casing@0"
            ]
        },
        {
            "x": 3,
            "y": -2,
            "z": 5,
            "elements": [
                "contenttweaker:high_current_superconductive_coil@0"
            ]
        },
        {
            "x": 1,
            "y": -6,
            "z": 3,
            "elements": [
                "contenttweaker:high_current_superconductive_coil@0"
            ]
        },
        {
            "x": 4,
            "y": -2,
            "z": 5,
            "elements": [
                "contenttweaker:fusion_reactor_outer_casing@0"
            ]
        },
        {
            "x": 2,
            "y": -6,
            "z": 3,
            "elements": [
                "contenttweaker:fusion_reactor_inner_casing@0"
            ]
        },
        {
            "x": 5,
            "y": -2,
            "z": 5,
            "elements": [
                "contenttweaker:high_current_superconductive_coil@0"
            ]
        },
        {
            "x": 3,
            "y": -6,
            "z": 3,
            "elements": [
                "contenttweaker:fusion_reactor_inner_casing@0"
            ]
        },
        {
            "x": 4,
            "y": -6,
            "z": 3,
            "elements": [
                "contenttweaker:fusion_reactor_inner_casing@0"
            ]
        },
        {
            "x": 5,
            "y": -6,
            "z": 3,
            "elements": [
                "contenttweaker:high_current_superconductive_coil@0"
            ]
        },
        {
            "x": 1,
            "y": -3,
            "z": -7,
            "elements": [
                "contenttweaker:high_current_superconductive_coil@0"
            ]
        },
        {
            "x": -6,
            "y": -5,
            "z": 3,
            "elements": [
                "contenttweaker:high_current_superconductive_coil@0"
            ]
        },
        {
            "x": 0,
            "y": -3,
            "z": -7,
            "elements": [
                "contenttweaker:fusion_reactor_outer_casing@0"
            ]
        },
        {
            "x": -5,
            "y": -5,
            "z": 3,
            "elements": [
                "contenttweaker:fusion_reactor_inner_casing@0"
            ]
        },
        {
            "x": -1,
            "y": -3,
            "z": -7,
            "elements": [
                "contenttweaker:high_current_superconductive_coil@0"
            ]
        },
        {
            "x": -2,
            "y": -1,
            "z": 5,

            "elements": [
                "modularmachinery:blockfluidoutputhatch@2"
            ]
        },
        {
            "x": -3,
            "y": -5,
            "z": 3,
            "elements": [
                "contenttweaker:fusion_reactor_inner_casing@0"
            ]
        },
        {
            "x": -1,
            "y": -1,
            "z": 5,
            "elements": [
                "contenttweaker:high_current_superconductive_coil@0"
            ]
        },
        {
            "x": -2,
            "y": -5,
            "z": 3,
            "elements": [
                "contenttweaker:fusion_reactor_inner_casing@0"
            ]
        },
        {
            "x": 0,
            "y": -1,
            "z": 5,
            "elements": [
                "contenttweaker:fusion_reactor_outer_casing@0"
            ]
        },
        {
            "x": 1,
            "y": -1,
            "z": 5,
            "elements": [
                "contenttweaker:high_current_superconductive_coil@0"
            ]
        },
        {
            "x": -1,
            "y": -5,
            "z": 3,
            "elements": [
                "contenttweaker:high_current_superconductive_coil@0"
            ]
        },
        {
            "x": 0,
            "y": -5,
            "z": 3,
            "elements": [
                "contenttweaker:fusion_reactor_outer_casing@0"
            ]
        },
        {
            "x": 2,
            "y": -1,
            "z": 5,

            "elements": [
                "modularmachinery:blockfluidoutputhatch@2"
            ]
        },
        {
            "x": 1,
            "y": -5,
            "z": 3,
            "elements": [
                "contenttweaker:high_current_superconductive_coil@0"
            ]
        },
        {
            "x": 2,
            "y": -5,
            "z": 3,
            "elements": [
                "contenttweaker:fusion_reactor_inner_casing@0"
            ]
        },
        {
            "x": 3,
            "y": -5,
            "z": 3,
            "elements": [
                "contenttweaker:fusion_reactor_inner_casing@0"
            ]
        },
        {
            "x": 5,
            "y": -5,
            "z": 3,
            "elements": [
                "contenttweaker:fusion_reactor_inner_casing@0"
            ]
        },
        {
            "x": 6,
            "y": -5,
            "z": 3,
            "elements": [
                "contenttweaker:high_current_superconductive_coil@0"
            ]
        },
        {
            "x": 5,
            "y": 0,
            "z": -5,
            "elements": [
                "immersiveengineering:storage@8"
            ]
        },
        {
            "x": -5,
            "y": 0,
            "z": 5,
            "elements": [
                "immersiveengineering:storage@8"
            ]
        },
        {
            "x": 2,
            "y": -4,
            "z": -7,
            "elements": [
                "contenttweaker:fusion_reactor_outer_casing@0"
            ]
        },
        {
            "x": 1,
            "y": -4,
            "z": -7,
            "elements": [
                "contenttweaker:high_current_superconductive_coil@0"
            ]
        },
        {
            "x": -6,
            "y": -4,
            "z": 3,
            "elements": [
                "contenttweaker:high_current_superconductive_coil@0"
            ]
        },
        {
            "x": 0,
            "y": -4,
            "z": -7,
            "elements": [
                "contenttweaker:fusion_reactor_outer_casing@0"
            ]
        },
        {
            "x": -5,
            "y": -4,
            "z": 3,
            "elements": [
                "contenttweaker:fusion_reactor_inner_casing@0"
            ]
        },
        {
            "x": -1,
            "y": -4,
            "z": -7,
            "elements": [
                "contenttweaker:high_current_superconductive_coil@0"
            ]
        },
        {
            "x": 0,
            "y": 0,
            "z": -5,
            "elements": [
                "immersiveengineering:storage@8"
            ]
        },
        {
            "x": -3,
            "y": -4,
            "z": 3,
            "elements": [
                "contenttweaker:fusion_reactor_inner_casing@0"
            ]
        },
        {
            "x": -2,
            "y": -4,
            "z": -7,
            "elements": [
                "contenttweaker:fusion_reactor_outer_casing@0"
            ]
        },
        {
            "x": -2,
            "y": -4,
            "z": 3,
            "elements": [
                "contenttweaker:fusion_reactor_inner_casing@0"
            ]
        },
        {
            "x": 0,
            "y": 0,
            "z": 5,
            "elements": [
                "immersiveengineering:storage@8"
            ]
        },
        {
            "x": -3,
            "y": -8,
            "z": 1,

            "elements": [
                "modularmachinery:blockfluidoutputhatch@1"
            ]
        },
        {
            "x": -1,
            "y": -4,
            "z": 3,
            "elements": [
                "contenttweaker:high_current_superconductive_coil@0"
            ]
        },
        {
            "x": -2,
            "y": -8,
            "z": 1,

            "elements": [
                "modularmachinery:blockenergyinputhatch@2"
            ]
        },
        {
            "x": 0,
            "y": -4,
            "z": 3,
            "elements": [
                "contenttweaker:fusion_reactor_outer_casing@0"
            ]
        },
        {
            "x": 1,
            "y": -4,
            "z": 3,
            "elements": [
                "contenttweaker:high_current_superconductive_coil@0"
            ]
        },
        {
            "x": -1,
            "y": -8,
            "z": 1,
            "elements": [
                "immersiveengineering:storage@8"
            ]
        },
        {
            "x": 0,
            "y": -8,
            "z": 1,
            "elements": [
                "immersiveengineering:storage@8"
            ]
        },
        {
            "x": -5,
            "y": 0,
            "z": -5,
            "elements": [
                "immersiveengineering:storage@8"
            ]
        },
        {
            "x": 2,
            "y": -4,
            "z": 3,
            "elements": [
                "contenttweaker:fusion_reactor_inner_casing@0"
            ]
        },
        {
            "x": 5,
            "y": 0,
            "z": 5,
            "elements": [
                "immersiveengineering:storage@8"
            ]
        },
        {
            "x": 3,
            "y": -4,
            "z": 3,
            "elements": [
                "contenttweaker:fusion_reactor_inner_casing@0"
            ]
        },
        {
            "x": 1,
            "y": -8,
            "z": 1,
            "elements": [
                "immersiveengineering:storage@8"
            ]
        },
        {
            "x": 2,
            "y": -8,
            "z": 1,

            "elements": [
                "modularmachinery:blockenergyinputhatch@2"
            ]
        },
        {
            "x": 5,
            "y": -4,
            "z": 3,
            "elements": [
                "contenttweaker:fusion_reactor_inner_casing@0"
            ]
        },
        {
            "x": 3,
            "y": -8,
            "z": 1,

            "elements": [
                "modularmachinery:blockfluidoutputhatch@1"
            ]
        },
        {
            "x": 6,
            "y": -4,
            "z": 3,
            "elements": [
                "contenttweaker:high_current_superconductive_coil@0"
            ]
        },
        {
            "x": 1,
            "y": -5,
            "z": -7,
            "elements": [
                "contenttweaker:high_current_superconductive_coil@0"
            ]
        },
        {
            "x": -6,
            "y": -3,
            "z": 3,
            "elements": [
                "contenttweaker:high_current_superconductive_coil@0"
            ]
        },
        {
            "x": 0,
            "y": -5,
            "z": -7,
            "elements": [
                "contenttweaker:fusion_reactor_outer_casing@0"
            ]
        },
        {
            "x": -5,
            "y": -3,
            "z": 3,
            "elements": [
                "contenttweaker:fusion_reactor_inner_casing@0"
            ]
        },
        {
            "x": 2,
            "y": -1,
            "z": -5,

            "elements": [
                "modularmachinery:blockfluidoutputhatch@2"
            ]
        },
        {
            "x": 1,
            "y": -1,
            "z": -5,
            "elements": [
                "contenttweaker:high_current_superconductive_coil@0"
            ]
        },
        {
            "x": -1,
            "y": -5,
            "z": -7,
            "elements": [
                "contenttweaker:high_current_superconductive_coil@0"
            ]
        },
        {
            "x": 0,
            "y": -1,
            "z": -5,
            "elements": [
                "contenttweaker:fusion_reactor_outer_casing@0"
            ]
        },
        {
            "x": -5,
            "y": -7,
            "z": 1,
            "elements": [
                "contenttweaker:high_current_superconductive_coil@0"
            ]
        },
        {
            "x": -3,
            "y": -3,
            "z": 3,
            "elements": [
                "contenttweaker:fusion_reactor_inner_casing@0"
            ]
        },
        {
            "x": -1,
            "y": -1,
            "z": -5,
            "elements": [
                "contenttweaker:high_current_superconductive_coil@0"
            ]
        },
        {
            "x": -4,
            "y": -7,
            "z": 1,
            "elements": [
                "contenttweaker:high_current_superconductive_coil@0"
            ]
        },
        {
            "x": -2,
            "y": -3,
            "z": 3,
            "elements": [
                "contenttweaker:fusion_reactor_inner_casing@0"
            ]
        },
        {
            "x": -3,
            "y": -7,
            "z": 1,
            "elements": [
                "contenttweaker:high_current_superconductive_coil@0"
            ]
        },
        {
            "x": -1,
            "y": -3,
            "z": 3,
            "elements": [
                "contenttweaker:high_current_superconductive_coil@0"
            ]
        },
        {
            "x": -2,
            "y": -1,
            "z": -5,

            "elements": [
                "modularmachinery:blockfluidoutputhatch@2"
            ]
        },
        {
            "x": -2,
            "y": -7,
            "z": 1,
            "elements": [
                "contenttweaker:high_current_superconductive_coil@0"
            ]
        },
        {
            "x": 0,
            "y": -3,
            "z": 3,
            "elements": [
                "contenttweaker:fusion_reactor_outer_casing@0"
            ]
        },
        {
            "x": 1,
            "y": -3,
            "z": 3,
            "elements": [
                "contenttweaker:high_current_superconductive_coil@0"
            ]
        },
        {
            "x": -1,
            "y": -7,
            "z": 1,
            "elements": [
                "immersiveengineering:storage@8"
            ]
        },
        {
            "x": 0,
            "y": -7,
            "z": 1,
            "elements": [
                "immersiveengineering:storage@8"
            ]
        },
        {
            "x": 2,
            "y": -3,
            "z": 3,
            "elements": [
                "contenttweaker:fusion_reactor_inner_casing@0"
            ]
        },
        {
            "x": 3,
            "y": -3,
            "z": 3,
            "elements": [
                "contenttweaker:fusion_reactor_inner_casing@0"
            ]
        },
        {
            "x": 1,
            "y": -7,
            "z": 1,
            "elements": [
                "immersiveengineering:storage@8"
            ]
        },
        {
            "x": 2,
            "y": -7,
            "z": 1,
            "elements": [
                "contenttweaker:high_current_superconductive_coil@0"
            ]
        },
        {
            "x": 5,
            "y": -3,
            "z": 3,
            "elements": [
                "contenttweaker:fusion_reactor_inner_casing@0"
            ]
        },
        {
            "x": 3,
            "y": -7,
            "z": 1,
            "elements": [
                "contenttweaker:high_current_superconductive_coil@0"
            ]
        },
        {
            "x": 6,
            "y": -3,
            "z": 3,
            "elements": [
                "contenttweaker:high_current_superconductive_coil@0"
            ]
        },
        {
            "x": 4,
            "y": -7,
            "z": 1,
            "elements": [
                "contenttweaker:high_current_superconductive_coil@0"
            ]
        },
        {
            "x": 5,
            "y": -7,
            "z": 1,
            "elements": [
                "contenttweaker:high_current_superconductive_coil@0"
            ]
        },
        {
            "x": 5,
            "y": -2,
            "z": -5,
            "elements": [
                "contenttweaker:high_current_superconductive_coil@0"
            ]
        },
        {
            "x": 4,
            "y": -2,
            "z": -5,
            "elements": [
                "contenttweaker:fusion_reactor_outer_casing@0"
            ]
        },
        {
            "x": 3,
            "y": -2,
            "z": -5,
            "elements": [
                "contenttweaker:high_current_superconductive_coil@0"
            ]
        },
        {
            "x": -5,
            "y": -2,
            "z": 3,
            "elements": [
                "contenttweaker:high_current_superconductive_coil@0"
            ]
        },
        {
            "x": 2,
            "y": -2,
            "z": -5,
            "elements": [
                "contenttweaker:fusion_reactor_inner_casing@0"
            ]
        },
        {
            "x": 1,
            "y": -2,
            "z": -5,
            "elements": [
                "contenttweaker:fusion_reactor_inner_casing@0"
            ]
        },
        {
            "x": -6,
            "y": -6,
            "z": 1,
            "elements": [
                "contenttweaker:high_current_superconductive_coil@0"
            ]
        },
        {
            "x": -4,
            "y": -2,
            "z": 3,
            "elements": [
                "contenttweaker:fusion_reactor_inner_casing@0"
            ]
        },
        {
            "x": 0,
            "y": -2,
            "z": -5,
            "elements": [
                "contenttweaker:fusion_reactor_inner_casing@0"
            ]
        },
        {
            "x": -5,
            "y": -6,
            "z": 1,
            "elements": [
                "contenttweaker:fusion_reactor_inner_casing@0"
            ]
        },
        {
            "x": -3,
            "y": -2,
            "z": 3,
            "elements": [
                "contenttweaker:fusion_reactor_inner_casing@0"
            ]
        },
        {
            "x": -1,
            "y": -2,
            "z": -5,
            "elements": [
                "contenttweaker:fusion_reactor_inner_casing@0"
            ]
        },
        {
            "x": -4,
            "y": -6,
            "z": 1,
            "elements": [
                "contenttweaker:fusion_reactor_inner_casing@0"
            ]
        },
        {
            "x": -2,
            "y": -2,
            "z": 3,
            "elements": [
                "contenttweaker:fusion_reactor_inner_casing@0"
            ]
        },
        {
            "x": -3,
            "y": -6,
            "z": 1,
            "elements": [
                "contenttweaker:high_current_superconductive_coil@0"
            ]
        },
        {
            "x": -1,
            "y": -2,
            "z": 3,
            "elements": [
                "contenttweaker:high_current_superconductive_coil@0"
            ]
        },
        {
            "x": -2,
            "y": -2,
            "z": -5,
            "elements": [
                "contenttweaker:fusion_reactor_inner_casing@0"
            ]
        },
        {
            "x": -2,
            "y": -6,
            "z": 1,
            "elements": [
                "contenttweaker:high_current_superconductive_coil@0"
            ]
        },
        {
            "x": 0,
            "y": -2,
            "z": 3,
            "elements": [
                "contenttweaker:fusion_reactor_outer_casing@0"
            ]
        },
        {
            "x": -3,
            "y": -2,
            "z": -5,
            "elements": [
                "contenttweaker:high_current_superconductive_coil@0"
            ]
        },
        {
            "x": 1,
            "y": -2,
            "z": 3,
            "elements": [
                "contenttweaker:high_current_superconductive_coil@0"
            ]
        },
        {
            "x": -1,
            "y": -6,
            "z": 1,
            "elements": [
                "immersiveengineering:storage@8"
            ]
        },
        {
            "x": -4,
            "y": -2,
            "z": -5,
            "elements": [
                "contenttweaker:fusion_reactor_outer_casing@0"
            ]
        },
        {
            "x": 0,
            "y": -6,
            "z": 1,
            "elements": [
                "immersiveengineering:storage@8"
            ]
        },
        {
            "x": -5,
            "y": -2,
            "z": -5,
            "elements": [
                "contenttweaker:high_current_superconductive_coil@0"
            ]
        },
        {
            "x": 2,
            "y": -2,
            "z": 3,
            "elements": [
                "contenttweaker:fusion_reactor_inner_casing@0"
            ]
        },
        {
            "x": 3,
            "y": -2,
            "z": 3,
            "elements": [
                "contenttweaker:fusion_reactor_inner_casing@0"
            ]
        },
        {
            "x": 1,
            "y": -6,
            "z": 1,
            "elements": [
                "immersiveengineering:storage@8"
            ]
        },
        {
            "x": 4,
            "y": -2,
            "z": 3,
            "elements": [
                "contenttweaker:fusion_reactor_inner_casing@0"
            ]
        },
        {
            "x": 2,
            "y": -6,
            "z": 1,
            "elements": [
                "contenttweaker:high_current_superconductive_coil@0"
            ]
        },
        {
            "x": 5,
            "y": -2,
            "z": 3,
            "elements": [
                "contenttweaker:high_current_superconductive_coil@0"
            ]
        },
        {
            "x": 3,
            "y": -6,
            "z": 1,
            "elements": [
                "contenttweaker:high_current_superconductive_coil@0"
            ]
        },
        {
            "x": 4,
            "y": -6,
            "z": 1,
            "elements": [
                "contenttweaker:fusion_reactor_inner_casing@0"
            ]
        },
        {
            "x": 5,
            "y": -6,
            "z": 1,
            "elements": [
                "contenttweaker:fusion_reactor_inner_casing@0"
            ]
        },
        {
            "x": 6,
            "y": -6,
            "z": 1,
            "elements": [
                "contenttweaker:high_current_superconductive_coil@0"
            ]
        },
        {
            "x": 5,
            "y": -3,
            "z": -5,
            "elements": [
                "contenttweaker:high_current_superconductive_coil@0"
            ]
        },
        {
            "x": 4,
            "y": -3,
            "z": -5,
            "elements": [
                "contenttweaker:fusion_reactor_inner_casing@0"
            ]
        },
        {
            "x": 3,
            "y": -3,
            "z": -5,
            "elements": [
                "contenttweaker:fusion_reactor_inner_casing@0"
            ]
        },
        {
            "x": -7,
            "y": -5,
            "z": 1,
            "elements": [
                "contenttweaker:high_current_superconductive_coil@0"
            ]
        },
        {
            "x": -6,
            "y": -5,
            "z": 1,
            "elements": [
                "contenttweaker:fusion_reactor_inner_casing@0"
            ]
        },
        {
            "x": -4,
            "y": -1,
            "z": 3,
            "elements": [
                "contenttweaker:high_current_superconductive_coil@0"
            ]
        },
        {
            "x": -3,
            "y": -1,
            "z": 3,
            "elements": [
                "contenttweaker:high_current_superconductive_coil@0"
            ]
        },
        {
            "x": -4,
            "y": -5,
            "z": 1,
            "elements": [
                "contenttweaker:fusion_reactor_inner_casing@0"
            ]
        },
        {
            "x": -2,
            "y": -1,
            "z": 3,
            "elements": [
                "contenttweaker:high_current_superconductive_coil@0"
            ]
        },
        {
            "x": -3,
            "y": -5,
            "z": 1,
            "elements": [
                "contenttweaker:high_current_superconductive_coil@0"
            ]
        },
        {
            "x": -1,
            "y": -1,
            "z": 3,
            "elements": [
                "contenttweaker:high_current_superconductive_coil@0"
            ]
        },
        {
            "x": -2,
            "y": -5,
            "z": 1,
            "elements": [
                "contenttweaker:high_current_superconductive_coil@0"
            ]
        },
        {
            "x": 0,
            "y": -1,
            "z": 3,
            "elements": [
                "contenttweaker:fusion_reactor_outer_casing@0"
            ]
        },
        {
            "x": -3,
            "y": -3,
            "z": -5,
            "elements": [
                "contenttweaker:fusion_reactor_inner_casing@0"
            ]
        },
        {
            "x": 1,
            "y": -1,
            "z": 3,
            "elements": [
                "contenttweaker:high_current_superconductive_coil@0"
            ]
        },
        {
            "x": -1,
            "y": -5,
            "z": 1,
            "elements": [
                "immersiveengineering:storage@8"
            ]
        },
        {
            "x": -4,
            "y": -3,
            "z": -5,
            "elements": [
                "contenttweaker:fusion_reactor_inner_casing@0"
            ]
        },
        {
            "x": 0,
            "y": -5,
            "z": 1,
            "elements": [
                "immersiveengineering:storage@8"
            ]
        },
        {
            "x": -5,
            "y": -3,
            "z": -5,
            "elements": [
                "contenttweaker:high_current_superconductive_coil@0"
            ]
        },
        {
            "x": 2,
            "y": -1,
            "z": 3,
            "elements": [
                "contenttweaker:high_current_superconductive_coil@0"
            ]
        },
        {
            "x": 3,
            "y": -1,
            "z": 3,
            "elements": [
                "contenttweaker:high_current_superconductive_coil@0"
            ]
        },
        {
            "x": 1,
            "y": -5,
            "z": 1,
            "elements": [
                "immersiveengineering:storage@8"
            ]
        },
        {
            "x": 4,
            "y": -1,
            "z": 3,
            "elements": [
                "contenttweaker:high_current_superconductive_coil@0"
            ]
        },
        {
            "x": 2,
            "y": -5,
            "z": 1,
            "elements": [
                "contenttweaker:high_current_superconductive_coil@0"
            ]
        },
        {
            "x": 3,
            "y": -5,
            "z": 1,
            "elements": [
                "contenttweaker:high_current_superconductive_coil@0"
            ]
        },
        {
            "x": 4,
            "y": -5,
            "z": 1,
            "elements": [
                "contenttweaker:fusion_reactor_inner_casing@0"
            ]
        },
        {
            "x": 6,
            "y": -5,
            "z": 1,
            "elements": [
                "contenttweaker:fusion_reactor_inner_casing@0"
            ]
        },
        {
            "x": 7,
            "y": -5,
            "z": 1,
            "elements": [
                "contenttweaker:high_current_superconductive_coil@0"
            ]
        },
        {
            "x": 5,
            "y": -4,
            "z": -5,
            "elements": [
                "contenttweaker:high_current_superconductive_coil@0"
            ]
        },
        {
            "x": 4,
            "y": -4,
            "z": -5,
            "elements": [
                "contenttweaker:fusion_reactor_inner_casing@0"
            ]
        },
        {
            "x": 3,
            "y": -4,
            "z": -5,
            "elements": [
                "contenttweaker:fusion_reactor_inner_casing@0"
            ]
        },
        {
            "x": 0,
            "y": -8,
            "z": -7,
            "elements": [
                "immersiveengineering:storage@8"
            ]
        },
        {
            "x": -7,
            "y": -4,
            "z": 1,
            "elements": [
                "contenttweaker:high_current_superconductive_coil@0"
            ]
        },
        {
            "x": 3,
            "y": 0,
            "z": -3,
            "elements": [
                "immersiveengineering:storage@8"
            ]
        },
        {
            "x": -6,
            "y": -4,
            "z": 1,
            "elements": [
                "contenttweaker:fusion_reactor_inner_casing@0"
            ]
        },
        {
            "x": -3,
            "y": 0,
            "z": 3,
            "elements": [
                "immersiveengineering:storage@8"
            ]
        },
        {
            "x": 1,
            "y": 0,
            "z": -3,

            "elements": [
                "modularmachinery:blockfluidinputhatch@1"
            ]
        },
        {
            "x": -4,
            "y": -4,
            "z": 1,
            "elements": [
                "contenttweaker:fusion_reactor_inner_casing@0"
            ]
        },
        {
            "x": 0,
            "y": 0,
            "z": -3,
            "elements": [
                "immersiveengineering:storage@8"
            ]
        },
        {
            "x": -3,
            "y": -4,
            "z": 1,
            "elements": [
                "contenttweaker:high_current_superconductive_coil@0"
            ]
        },
        {
            "x": -1,
            "y": 0,
            "z": 3,

            "elements": [
                "modularmachinery:blockfluidinputhatch@1"
            ]
        },
        {
            "x": 0,
            "y": 0,
            "z": 3,
            "elements": [
                "immersiveengineering:storage@8"
            ]
        },
        {
            "x": -3,
            "y": -4,
            "z": -5,
            "elements": [
                "contenttweaker:fusion_reactor_inner_casing@0"
            ]
        },
        {
            "x": -1,
            "y": 0,
            "z": -3,

            "elements": [
                "modularmachinery:blockfluidinputhatch@1"
            ]
        },
        {
            "x": -2,
            "y": -4,
            "z": 1,
            "elements": [
                "contenttweaker:high_current_superconductive_coil@0"
            ]
        },
        {
            "x": 1,
            "y": 0,
            "z": 3,

            "elements": [
                "modularmachinery:blockfluidinputhatch@1"
            ]
        },
        {
            "x": -1,
            "y": -4,
            "z": 1,
            "elements": [
                "immersiveengineering:storage@8"
            ]
        },
        {
            "x": -4,
            "y": -4,
            "z": -5,
            "elements": [
                "contenttweaker:fusion_reactor_inner_casing@0"
            ]
        },
        {
            "x": 0,
            "y": -4,
            "z": 1,
            "elements": [
                "immersiveengineering:storage@8"
            ]
        },
        {
            "x": -5,
            "y": -4,
            "z": -5,
            "elements": [
                "contenttweaker:high_current_superconductive_coil@0"
            ]
        },
        {
            "x": -3,
            "y": 0,
            "z": -3,
            "elements": [
                "immersiveengineering:storage@8"
            ]
        },
        {
            "x": 3,
            "y": 0,
            "z": 3,
            "elements": [
                "immersiveengineering:storage@8"
            ]
        },
        {
            "x": 1,
            "y": -4,
            "z": 1,
            "elements": [
                "immersiveengineering:storage@8"
            ]
        },
        {
            "x": 2,
            "y": -4,
            "z": 1,
            "elements": [
                "contenttweaker:high_current_superconductive_coil@0"
            ]
        },
        {
            "x": 3,
            "y": -4,
            "z": 1,
            "elements": [
                "contenttweaker:high_current_superconductive_coil@0"
            ]
        },
        {
            "x": 4,
            "y": -4,
            "z": 1,
            "elements": [
                "contenttweaker:fusion_reactor_inner_casing@0"
            ]
        },
        {
            "x": 6,
            "y": -4,
            "z": 1,
            "elements": [
                "contenttweaker:fusion_reactor_inner_casing@0"
            ]
        },
        {
            "x": 7,
            "y": -4,
            "z": 1,
            "elements": [
                "contenttweaker:high_current_superconductive_coil@0"
            ]
        },
        {
            "x": 5,
            "y": -5,
            "z": -5,
            "elements": [
                "contenttweaker:high_current_superconductive_coil@0"
            ]
        },
        {
            "x": 4,
            "y": -5,
            "z": -5,
            "elements": [
                "contenttweaker:fusion_reactor_inner_casing@0"
            ]
        },
        {
            "x": 3,
            "y": -5,
            "z": -5,
            "elements": [
                "contenttweaker:fusion_reactor_inner_casing@0"
            ]
        },
        {
            "x": -7,
            "y": -3,
            "z": 1,
            "elements": [
                "contenttweaker:high_current_superconductive_coil@0"
            ]
        },
        {
            "x": 4,
            "y": -1,
            "z": -3,
            "elements": [
                "contenttweaker:high_current_superconductive_coil@0"
            ]
        },
        {
            "x": 3,
            "y": -1,
            "z": -3,
            "elements": [
                "contenttweaker:high_current_superconductive_coil@0"
            ]
        },
        {
            "x": -6,
            "y": -3,
            "z": 1,
            "elements": [
                "contenttweaker:fusion_reactor_inner_casing@0"
            ]
        },
        {
            "x": 2,
            "y": -1,
            "z": -3,
            "elements": [
                "contenttweaker:high_current_superconductive_coil@0"
            ]
        },
        {
            "x": 1,
            "y": -1,
            "z": -3,
            "elements": [
                "contenttweaker:high_current_superconductive_coil@0"
            ]
        },
        {
            "x": -4,
            "y": -3,
            "z": 1,
            "elements": [
                "contenttweaker:fusion_reactor_inner_casing@0"
            ]
        },
        {
            "x": 0,
            "y": -1,
            "z": -3,
            "elements": [
                "contenttweaker:fusion_reactor_outer_casing@0"
            ]
        },
        {
            "x": -3,
            "y": -3,
            "z": 1,
            "elements": [
                "contenttweaker:high_current_superconductive_coil@0"
            ]
        },
        {
            "x": -3,
            "y": -5,
            "z": -5,
            "elements": [
                "contenttweaker:fusion_reactor_inner_casing@0"
            ]
        },
        {
            "x": -1,
            "y": -1,
            "z": -3,
            "elements": [
                "contenttweaker:high_current_superconductive_coil@0"
            ]
        },
        {
            "x": -2,
            "y": -3,
            "z": 1,
            "elements": [
                "contenttweaker:high_current_superconductive_coil@0"
            ]
        },
        {
            "x": -1,
            "y": -3,
            "z": 1,
            "elements": [
                "immersiveengineering:storage@8"
            ]
        },
        {
            "x": -4,
            "y": -5,
            "z": -5,
            "elements": [
                "contenttweaker:fusion_reactor_inner_casing@0"
            ]
        },
        {
            "x": -2,
            "y": -1,
            "z": -3,
            "elements": [
                "contenttweaker:high_current_superconductive_coil@0"
            ]
        },
        {
            "x": 0,
            "y": -3,
            "z": 1,
            "elements": [
                "immersiveengineering:storage@8"
            ]
        },
        {
            "x": -5,
            "y": -5,
            "z": -5,
            "elements": [
                "contenttweaker:high_current_superconductive_coil@0"
            ]
        },
        {
            "x": -3,
            "y": -1,
            "z": -3,
            "elements": [
                "contenttweaker:high_current_superconductive_coil@0"
            ]
        },
        {
            "x": 1,
            "y": -3,
            "z": 1,
            "elements": [
                "immersiveengineering:storage@8"
            ]
        },
        {
            "x": -4,
            "y": -1,
            "z": -3,
            "elements": [
                "contenttweaker:high_current_superconductive_coil@0"
            ]
        },
        {
            "x": 2,
            "y": -3,
            "z": 1,
            "elements": [
                "contenttweaker:high_current_superconductive_coil@0"
            ]
        },
        {
            "x": 3,
            "y": -3,
            "z": 1,
            "elements": [
                "contenttweaker:high_current_superconductive_coil@0"
            ]
        },
        {
            "x": 4,
            "y": -3,
            "z": 1,
            "elements": [
                "contenttweaker:fusion_reactor_inner_casing@0"
            ]
        },
        {
            "x": 6,
            "y": -3,
            "z": 1,
            "elements": [
                "contenttweaker:fusion_reactor_inner_casing@0"
            ]
        },
        {
            "x": 7,
            "y": -3,
            "z": 1,
            "elements": [
                "contenttweaker:high_current_superconductive_coil@0"
            ]
        },
        {
            "x": 5,
            "y": -6,
            "z": -5,
            "elements": [
                "contenttweaker:high_current_superconductive_coil@0"
            ]
        },
        {
            "x": 4,
            "y": -6,
            "z": -5,
            "elements": [
                "contenttweaker:fusion_reactor_outer_casing@0"
            ]
        },
        {
            "x": 5,
            "y": -2,
            "z": -3,
            "elements": [
                "contenttweaker:high_current_superconductive_coil@0"
            ]
        },
        {
            "x": 3,
            "y": -6,
            "z": -5,
            "elements": [
                "contenttweaker:high_current_superconductive_coil@0"
            ]
        },
        {
            "x": 4,
            "y": -2,
            "z": -3,
            "elements": [
                "contenttweaker:fusion_reactor_inner_casing@0"
            ]
        },
        {
            "x": 2,
            "y": -6,
            "z": -5,
            "elements": [
                "contenttweaker:fusion_reactor_inner_casing@0"
            ]
        },
        {
            "x": 3,
            "y": -2,
            "z": -3,
            "elements": [
                "contenttweaker:fusion_reactor_inner_casing@0"
            ]
        },
        {
            "x": 1,
            "y": -6,
            "z": -5,
            "elements": [
                "contenttweaker:fusion_reactor_inner_casing@0"
            ]
        },
        {
            "x": -6,
            "y": -2,
            "z": 1,
            "elements": [
                "contenttweaker:high_current_superconductive_coil@0"
            ]
        },
        {
            "x": 0,
            "y": -6,
            "z": -5,
            "elements": [
                "contenttweaker:fusion_reactor_inner_casing@0"
            ]
        },
        {
            "x": -5,
            "y": -2,
            "z": 1,
            "elements": [
                "contenttweaker:fusion_reactor_inner_casing@0"
            ]
        },
        {
            "x": 2,
            "y": -2,
            "z": -3,
            "elements": [
                "contenttweaker:fusion_reactor_inner_casing@0"
            ]
        },
        {
            "x": 1,
            "y": -2,
            "z": -3,
            "elements": [
                "contenttweaker:high_current_superconductive_coil@0"
            ]
        },
        {
            "x": -1,
            "y": -6,
            "z": -5,
            "elements": [
                "contenttweaker:fusion_reactor_inner_casing@0"
            ]
        },
        {
            "x": -4,
            "y": -2,
            "z": 1,
            "elements": [
                "contenttweaker:fusion_reactor_inner_casing@0"
            ]
        },
        {
            "x": -2,
            "y": -6,
            "z": -5,
            "elements": [
                "contenttweaker:fusion_reactor_inner_casing@0"
            ]
        },
        {
            "x": 0,
            "y": -2,
            "z": -3,
            "elements": [
                "contenttweaker:fusion_reactor_outer_casing@0"
            ]
        },
        {
            "x": -3,
            "y": -2,
            "z": 1,
            "elements": [
                "contenttweaker:high_current_superconductive_coil@0"
            ]
        },
        {
            "x": -3,
            "y": -6,
            "z": -5,
            "elements": [
                "contenttweaker:high_current_superconductive_coil@0"
            ]
        },
        {
            "x": -1,
            "y": -2,
            "z": -3,
            "elements": [
                "contenttweaker:high_current_superconductive_coil@0"
            ]
        },
        {
            "x": -2,
            "y": -2,
            "z": 1,
            "elements": [
                "contenttweaker:high_current_superconductive_coil@0"
            ]
        },
        {
            "x": -1,
            "y": -2,
            "z": 1,
            "elements": [
                "immersiveengineering:storage@8"
            ]
        },
        {
            "x": -4,
            "y": -6,
            "z": -5,
            "elements": [
                "contenttweaker:fusion_reactor_outer_casing@0"
            ]
        },
        {
            "x": -2,
            "y": -2,
            "z": -3,
            "elements": [
                "contenttweaker:fusion_reactor_inner_casing@0"
            ]
        },
        {
            "x": 0,
            "y": -2,
            "z": 1,
            "elements": [
                "immersiveengineering:storage@8"
            ]
        },
        {
            "x": -5,
            "y": -6,
            "z": -5,
            "elements": [
                "contenttweaker:high_current_superconductive_coil@0"
            ]
        },
        {
            "x": -3,
            "y": -2,
            "z": -3,
            "elements": [
                "contenttweaker:fusion_reactor_inner_casing@0"
            ]
        },
        {
            "x": 1,
            "y": -2,
            "z": 1,
            "elements": [
                "immersiveengineering:storage@8"
            ]
        },
        {
            "x": -4,
            "y": -2,
            "z": -3,
            "elements": [
                "contenttweaker:fusion_reactor_inner_casing@0"
            ]
        },
        {
            "x": -5,
            "y": -2,
            "z": -3,
            "elements": [
                "contenttweaker:high_current_superconductive_coil@0"
            ]
        },
        {
            "x": 2,
            "y": -2,
            "z": 1,
            "elements": [
                "contenttweaker:high_current_superconductive_coil@0"
            ]
        },
        {
            "x": 3,
            "y": -2,
            "z": 1,
            "elements": [
                "contenttweaker:high_current_superconductive_coil@0"
            ]
        },
        {
            "x": 4,
            "y": -2,
            "z": 1,
            "elements": [
                "contenttweaker:fusion_reactor_inner_casing@0"
            ]
        },
        {
            "x": 5,
            "y": -2,
            "z": 1,
            "elements": [
                "contenttweaker:fusion_reactor_inner_casing@0"
            ]
        },
        {
            "x": 6,
            "y": -2,
            "z": 1,
            "elements": [
                "contenttweaker:high_current_superconductive_coil@0"
            ]
        },
        {
            "x": 6,
            "y": -3,
            "z": -3,
            "elements": [
                "contenttweaker:high_current_superconductive_coil@0"
            ]
        },
        {
            "x": 5,
            "y": -3,
            "z": -3,
            "elements": [
                "contenttweaker:fusion_reactor_inner_casing@0"
            ]
        },
        {
            "x": 2,
            "y": -7,
            "z": -5,
 
            "elements": [
                "modularmachinery:blockfluidinputhatch@2"
            ]
        },
        {
            "x": 3,
            "y": -3,
            "z": -3,
            "elements": [
                "contenttweaker:fusion_reactor_inner_casing@0"
            ]
        },
        {
            "x": 1,
            "y": -7,
            "z": -5,
            "elements": [
                "contenttweaker:high_current_superconductive_coil@0"
            ]
        },
        {
            "x": 0,
            "y": -7,
            "z": -5,
            "elements": [
                "contenttweaker:fusion_reactor_outer_casing@0"
            ]
        },
        {
            "x": -5,
            "y": -1,
            "z": 1,
            "elements": [
                "contenttweaker:high_current_superconductive_coil@0"
            ]
        },
        {
            "x": 2,
            "y": -3,
            "z": -3,
            "elements": [
                "contenttweaker:fusion_reactor_inner_casing@0"
            ]
        },
        {
            "x": 1,
            "y": -3,
            "z": -3,
            "elements": [
                "contenttweaker:high_current_superconductive_coil@0"
            ]
        },
        {
            "x": -1,
            "y": -7,
            "z": -5,
            "elements": [
                "contenttweaker:high_current_superconductive_coil@0"
            ]
        },
        {
            "x": -4,
            "y": -1,
            "z": 1,
            "elements": [
                "contenttweaker:high_current_superconductive_coil@0"
            ]
        },
        {
            "x": -2,
            "y": -7,
            "z": -5,
 
            "elements": [
                "modularmachinery:blockfluidinputhatch@2"
            ]
        },
        {
            "x": 0,
            "y": -3,
            "z": -3,
            "elements": [
                "contenttweaker:fusion_reactor_outer_casing@0"
            ]
        },
        {
            "x": -3,
            "y": -1,
            "z": 1,
            "elements": [
                "contenttweaker:high_current_superconductive_coil@0"
            ]
        },
        {
            "x": -1,
            "y": -3,
            "z": -3,
            "elements": [
                "contenttweaker:high_current_superconductive_coil@0"
            ]
        },
        {
            "x": -2,
            "y": -1,
            "z": 1,
            "elements": [
                "contenttweaker:high_current_superconductive_coil@0"
            ]
        },
        {
            "x": -1,
            "y": -1,
            "z": 1,
            "elements": [
                "immersiveengineering:storage@8"
            ]
        },
        {
            "x": -2,
            "y": -3,
            "z": -3,
            "elements": [
                "contenttweaker:fusion_reactor_inner_casing@0"
            ]
        },
        {
            "x": 0,
            "y": -1,
            "z": 1,
            "elements": [
                "immersiveengineering:storage@8"
            ]
        },
        {
            "x": -3,
            "y": -3,
            "z": -3,
            "elements": [
                "contenttweaker:fusion_reactor_inner_casing@0"
            ]
        },
        {
            "x": 1,
            "y": -1,
            "z": 1,
            "elements": [
                "immersiveengineering:storage@8"
            ]
        },
        {
            "x": -5,
            "y": -3,
            "z": -3,
            "elements": [
                "contenttweaker:fusion_reactor_inner_casing@0"
            ]
        },
        {
            "x": 2,
            "y": -1,
            "z": 1,
            "elements": [
