{
    "parts": [
        {
            "x": -2,
            "y": -2,
            "z": -1,
            "elements": [
                "contenttweaker:sub_block_holder_1@5"
            ]
        },
        {
            "x": -1,
            "y": 0,
            "z": 0,
            "nbt": {"id":"minecraft:tilefluidinputhatch","casingColor":"10790052","input":"1b","size":"2","tank":{"Empty":"","gasTag":{"Empty":""}}},
            "elements": [
                "modularmachinery:blockfluidinputhatch@2"
            ]
        },
        {
            "x": 1,
            "y": 0,
            "z": 0,
            "nbt": {"id":"minecraft:tilefluidinputhatch","casingColor":"10790052","input":"1b","size":"2","tank":{"Empty":"","gasTag":{"Empty":""}}},
            "elements": [
                "modularmachinery:blockfluidinputhatch@2"
            ]
        },
        {
            "x": -2,
            "y": -6,
            "z": 1,
            "elements": [
                "contenttweaker:sub_block_holder_1@5"
            ]
        },
        {
            "x": -1,
            "y": -4,
            "z": 2,
            "elements": [
                "contenttweaker:sub_block_holder_1@5"
            ]
        },
        {
            "x": -1,
            "y": -6,
            "z": 1,
            "elements": [
                "contenttweaker:sub_block_holder_0@3"
            ]
        },
        {
            "x": 1,
            "y": -4,
            "z": 2,
            "elements": [
                "contenttweaker:sub_block_holder_1@5"
            ]
        },
        {
            "x": 1,
            "y": -6,
            "z": 1,
            "elements": [
                "contenttweaker:sub_block_holder_0@3"
            ]
        },
        {
            "x": 2,
            "y": -6,
            "z": 1,
            "elements": [
                "contenttweaker:sub_block_holder_1@5"
            ]
        },
        {
            "x": 1,
            "y": -7,
            "z": -3,
            "elements": [
                "contenttweaker:sub_block_holder_1@4"
            ]
        },
        {
            "x": 3,
            "y": -1,
            "z": 0,
            "elements": [
                "contenttweaker:sub_block_holder_1@4"
            ]
        },
        {
            "x": 2,
            "y": -3,
            "z": -1,
            "elements": [
                "contenttweaker:sub_block_holder_1@5"
            ]
        },
        {
            "x": 1,
            "y": -5,
            "z": -2,
            "elements": [
                "contenttweaker:sub_block_holder_1@5"
            ]
        },
        {
            "x": 0,
            "y": -7,
            "z": -3,
            "elements": [
                "contenttweaker:sub_block_holder_1@4"
            ]
        },
        {
            "x": 2,
            "y": -1,
            "z": 0,
            "elements": [
                "contenttweaker:sub_block_holder_1@5"
            ]
        },
        {
            "x": 1,
            "y": -3,
            "z": -1,
            "elements": [
                "contenttweaker:sub_block_holder_0@3"
            ]
        },
        {
            "x": -1,
            "y": -7,
            "z": -3,
            "elements": [
                "contenttweaker:sub_block_holder_1@4"
            ]
        },
        {
            "x": -1,
            "y": -5,
            "z": -2,
            "elements": [
                "contenttweaker:sub_block_holder_1@5"
            ]
        },
        {
            "x": 0,
            "y": -3,
            "z": -1,
            "elements": [
                "contenttweaker:sub_block_holder_1@7"
            ]
        },
        {
            "x": 1,
            "y": -1,
            "z": 0,
            "elements": [
                "contenttweaker:sub_block_holder_1@4"
            ]
        },
        {
            "x": -1,
            "y": -3,
            "z": -1,
            "elements": [
                "contenttweaker:sub_block_holder_0@3"
            ]
        },
        {
            "x": 0,
            "y": -1,
            "z": 0,
            "elements": [
                "contenttweaker:sub_block_holder_0@11"
            ]
        },
        {
            "x": -2,
            "y": -3,
            "z": -1,
            "elements": [
                "contenttweaker:sub_block_holder_1@5"
            ]
        },
        {
            "x": -1,
            "y": -1,
            "z": 0,
            "elements": [
                "contenttweaker:sub_block_holder_1@4"
            ]
        },
        {
            "x": -2,
            "y": -1,
            "z": 0,
            "elements": [
                "contenttweaker:sub_block_holder_1@5"
            ]
        },
        {
            "x": -3,
            "y": -1,
            "z": 0,
            "elements": [
                "contenttweaker:sub_block_holder_1@4"
            ]
        },
        {
            "x": -1,
            "y": -1,
            "z": 3,
            "elements": [
                "contenttweaker:sub_block_holder_1@4"
            ]
        },
        {
            "x": -2,
            "y": -5,
            "z": 1,
            "elements": [
                "contenttweaker:sub_block_holder_1@5"
            ]
        },
        {
            "x": -1,
            "y": -3,
            "z": 2,
            "elements": [
                "contenttweaker:sub_block_holder_1@5"
            ]
        },
        {
            "x": 0,
            "y": -1,
            "z": 3,
            "elements": [
                "contenttweaker:sub_block_holder_1@4"
            ]
        },
        {
            "x": -1,
            "y": -5,
            "z": 1,
            "elements": [
                "contenttweaker:sub_block_holder_0@3"
            ]
        },
        {
            "x": 1,
            "y": -1,
            "z": 3,
            "elements": [
                "contenttweaker:sub_block_holder_1@4"
            ]
        },
        {
            "x": 1,
            "y": -3,
            "z": 2,
            "elements": [
                "contenttweaker:sub_block_holder_1@5"
            ]
        },
        {
            "x": 0,
            "y": -5,
            "z": 1,
            "elements": [
                "contenttweaker:sub_block_holder_1@7"
            ]
        },
        {
            "x": 1,
            "y": -5,
            "z": 1,
            "elements": [
                "contenttweaker:sub_block_holder_0@3"
            ]
        },
        {
            "x": 2,
            "y": -5,
            "z": 1,
            "elements": [
                "contenttweaker:sub_block_holder_1@5"
            ]
        },
        {
            "x": 2,
            "y": -4,
            "z": -1,
            "elements": [
                "contenttweaker:sub_block_holder_1@5"
            ]
        },
        {
            "x": 1,
            "y": -6,
            "z": -2,
            "elements": [
                "contenttweaker:sub_block_holder_1@5"
            ]
        },
        {
            "x": 1,
            "y": -4,
            "z": -1,
            "elements": [
                "contenttweaker:sub_block_holder_0@3"
            ]
        },
        {
            "x": -1,
            "y": -6,
            "z": -2,
            "elements": [
                "contenttweaker:sub_block_holder_1@5"
            ]
        },
        {
            "x": -1,
            "y": -4,
            "z": -1,
            "elements": [
                "contenttweaker:sub_block_holder_0@3"
            ]
        },
        {
            "x": 0,
            "y": -2,
            "z": 0,
            "elements": [
                "contenttweaker:sub_block_holder_0@11"
            ]
        },
        {
            "x": -2,
            "y": -4,
            "z": -1,
            "elements": [
                "contenttweaker:sub_block_holder_1@5"
            ]
        },
        {
            "x": -1,
            "y": -2,
            "z": 2,
            "elements": [
                "contenttweaker:sub_block_holder_1@5"
            ]
        },
        {
            "x": -2,
            "y": -4,
            "z": 1,
            "elements": [
                "contenttweaker:sub_block_holder_1@5"
            ]
        },
        {
            "x": -1,
            "y": -4,
            "z": 1,
            "elements": [
                "contenttweaker:sub_block_holder_0@3"
            ]
        },
        {
            "x": 1,
            "y": -2,
            "z": 2,
            "elements": [
                "contenttweaker:sub_block_holder_1@5"
            ]
        },
        {
            "x": 1,
            "y": -4,
            "z": 1,
            "elements": [
                "contenttweaker:sub_block_holder_0@3"
            ]
        },
        {
            "x": 2,
            "y": -4,
            "z": 1,
            "elements": [
                "contenttweaker:sub_block_holder_1@5"
            ]
        },
        {
            "x": 2,
            "y": -7,
            "z": -2,
            "elements": [
                "contenttweaker:sub_block_holder_1@4"
            ]
        },
        {
            "x": 2,
            "y": -5,
            "z": -1,
            "elements": [
                "contenttweaker:sub_block_holder_1@5"
            ]
        },
        {
            "x": 1,
            "y": -7,
            "z": -2,
            "elements": [
                "contenttweaker:sub_block_holder_1@5"
            ]
        },
        {
            "x": 1,
            "y": -5,
            "z": -1,
            "elements": [
                "contenttweaker:sub_block_holder_0@3"
            ]
        },
        {
            "x": 0,
            "y": -7,
            "z": -2,
            "elements": [
                "contenttweaker:sub_block_holder_1@5"
            ]
        },
        {
            "x": 1,
            "y": -3,
            "z": 0,
            "elements": [
                "contenttweaker:sub_block_holder_1@7"
            ]
        },
        {
            "x": -1,
            "y": -7,
            "z": -2,
            "elements": [
                "contenttweaker:sub_block_holder_1@5"
            ]
        },
        {
            "x": 0,
            "y": -5,
            "z": -1,
            "elements": [
                "contenttweaker:sub_block_holder_1@7"
            ]
        },
        {
            "x": -2,
            "y": -7,
            "z": -2,
            "elements": [
                "contenttweaker:sub_block_holder_1@4"
            ]
        },
        {
            "x": -1,
            "y": -5,
            "z": -1,
            "elements": [
                "contenttweaker:sub_block_holder_0@3"
            ]
        },
        {
            "x": 0,
            "y": -3,
            "z": 0,
            "elements": [
                "contenttweaker:sub_block_holder_1@7"
            ]
        },
        {
            "x": -2,
            "y": -5,
            "z": -1,
            "elements": [
                "contenttweaker:sub_block_holder_1@5"
            ]
        },
        {
            "x": -1,
            "y": -3,
            "z": 0,
            "elements": [
                "contenttweaker:sub_block_holder_1@7"
            ]
        },
        {
            "x": 1,
            "y": -1,
            "z": -3,
            "elements": [
                "contenttweaker:sub_block_holder_1@4"
            ]
        },
        {
            "x": 0,
            "y": -1,
            "z": -3,
            "elements": [
                "contenttweaker:sub_block_holder_1@4"
            ]
        },
        {
            "x": -2,
            "y": -1,
            "z": 2,
            "elements": [
                "contenttweaker:sub_block_holder_1@4"
            ]
        },
        {
            "x": -1,
            "y": -1,
            "z": -3,
            "elements": [
                "contenttweaker:sub_block_holder_1@4"
            ]
        },
        {
            "x": -2,
            "y": -3,
            "z": 1,
            "elements": [
                "contenttweaker:sub_block_holder_1@5"
            ]
        },
        {
            "x": -1,
            "y": -1,
            "z": 2,
            "elements": [
                "contenttweaker:sub_block_holder_1@5"
            ]
        },
        {
            "x": -1,
            "y": -3,
            "z": 1,
            "elements": [
                "contenttweaker:sub_block_holder_0@3"
            ]
        },
        {
            "x": 0,
            "y": -1,
            "z": 2,
            "elements": [
                "contenttweaker:sub_block_holder_1@5"
            ]
        },
        {
            "x": 0,
            "y": -3,
            "z": 1,
            "elements": [
                "contenttweaker:sub_block_holder_1@7"
            ]
        },
        {
            "x": 1,
            "y": -1,
            "z": 2,
            "elements": [
                "contenttweaker:sub_block_holder_1@5"
            ]
        },
        {
            "x": 2,
            "y": -1,
            "z": 2,
            "elements": [
                "contenttweaker:sub_block_holder_1@4"
            ]
        },
        {
            "x": 1,
            "y": -3,
            "z": 1,
            "elements": [
                "contenttweaker:sub_block_holder_0@3"
            ]
        },
        {
            "x": 2,
            "y": -3,
            "z": 1,
            "elements": [
                "contenttweaker:sub_block_holder_1@5"
            ]
        },
        {
            "x": -1,
            "y": -7,
            "z": 3,
            "elements": [
                "contenttweaker:sub_block_holder_1@4"
            ]
        },
        {
            "x": 0,
            "y": -7,
            "z": 3,
            "elements": [
                "contenttweaker:sub_block_holder_1@4"
            ]
        },
        {
            "x": 1,
            "y": -7,
            "z": 3,
            "elements": [
                "contenttweaker:sub_block_holder_1@4"
            ]
        },
        {
            "x": 2,
            "y": -6,
            "z": -1,
            "elements": [
                "contenttweaker:sub_block_holder_1@5"
            ]
        },
        {
            "x": 1,
            "y": -6,
            "z": -1,
            "elements": [
                "contenttweaker:sub_block_holder_0@3"
            ]
        },
        {
            "x": -1,
            "y": -6,
            "z": -1,
            "elements": [
                "contenttweaker:sub_block_holder_0@3"
            ]
        },
        {
            "x": 0,
            "y": -4,
            "z": 0,
            "nbt": {"id":"minecraft:tileiteminputbus","casingColor":"10790052","inventory":{"inSlots":,"outSlots":,"miscSlots":,"inventoryArray":[{"holderEmpty":"1b","holderId":"0"},{"holderEmpty":"1b","holderId":"1"},{"holderEmpty":"1b","holderId":"2"},{"holderEmpty":"1b","holderId":"3"}],"sides":},"busSize":"1"},
            "elements": [
                "modularmachinery:blockinputbus@1"
            ]
        },
        {
            "x": -2,
            "y": -6,
            "z": -1,
            "elements": [
                "contenttweaker:sub_block_holder_1@5"
            ]
        },
        {
            "x": -2,
            "y": -2,
            "z": 1,
            "elements": [
                "contenttweaker:sub_block_holder_1@5"
            ]
        },
        {
            "x": -1,
            "y": -2,
            "z": 1,
            "elements": [
                "contenttweaker:sub_block_holder_0@3"
            ]
        },
        {
            "x": 1,
            "y": -2,
            "z": 1,
            "elements": [
                "contenttweaker:sub_block_holder_0@3"
            ]
        },
        {
            "x": 2,
            "y": -2,
            "z": 1,
            "elements": [
                "contenttweaker:sub_block_holder_1@5"
            ]
        },
        {
            "x": 3,
            "y": -7,
            "z": -1,
            "elements": [
                "contenttweaker:sub_block_holder_1@4"
            ]
        },
        {
            "x": 2,
            "y": -7,
            "z": -1,
            "elements": [
                "contenttweaker:sub_block_holder_1@5"
            ]
        },
        {
            "x": 1,
            "y": -7,
            "z": -1,
            "elements": [
                "contenttweaker:sub_block_holder_1@4"
            ]
        },
        {
            "x": 1,
            "y": -5,
            "z": 0,
            "elements": [
                "contenttweaker:sub_block_holder_1@7"
            ]
        },
        {
            "x": 0,
            "y": -7,
            "z": -1,
            "elements": [
                "contenttweaker:sub_block_holder_1@4"
            ]
        },
        {
            "x": -1,
            "y": -7,
            "z": -1,
            "elements": [
                "contenttweaker:sub_block_holder_1@4"
            ]
        },
        {
            "x": 0,
            "y": -5,
            "z": 0,
            "elements": [
                "contenttweaker:sub_block_holder_1@7"
            ]
        },
        {
            "x": -2,
            "y": -7,
            "z": -1,
            "elements": [
                "contenttweaker:sub_block_holder_1@5"
            ]
        },
        {
            "x": -1,
            "y": -5,
            "z": 0,
            "elements": [
                "contenttweaker:sub_block_holder_1@7"
            ]
        },
        {
            "x": -3,
            "y": -7,
            "z": -1,
            "elements": [
                "contenttweaker:sub_block_holder_1@4"
            ]
        },
        {
            "x": 2,
            "y": -1,
            "z": -2,
            "elements": [
                "contenttweaker:sub_block_holder_1@4"
            ]
        },
        {
            "x": -3,
            "y": -1,
            "z": 1,
            "elements": [
                "contenttweaker:sub_block_holder_1@4"
            ]
        },
        {
            "x": 1,
            "y": -1,
            "z": -2,
            "elements": [
                "contenttweaker:sub_block_holder_1@5"
            ]
        },
        {
            "x": 0,
            "y": -1,
            "z": -2,
            "elements": [
                "contenttweaker:sub_block_holder_1@5"
            ]
        },
        {
            "x": -2,
            "y": -1,
            "z": 1,
            "elements": [
                "contenttweaker:sub_block_holder_1@5"
            ]
        },
        {
            "x": -1,
            "y": -1,
            "z": -2,
            "elements": [
                "contenttweaker:sub_block_holder_1@5"
            ]
        },
        {
            "x": -1,
            "y": -1,
            "z": 1,
            "elements": [
                "contenttweaker:sub_block_holder_1@4"
            ]
        },
        {
            "x": 0,
            "y": -1,
            "z": 1,
            "elements": [
                "contenttweaker:sub_block_holder_1@4"
            ]
        },
        {
            "x": -2,
            "y": -1,
            "z": -2,
            "elements": [
                "contenttweaker:sub_block_holder_1@4"
            ]
        },
        {
            "x": 1,
            "y": -1,
            "z": 1,
            "elements": [
                "contenttweaker:sub_block_holder_1@4"
            ]
        },
        {
            "x": 2,
            "y": -1,
            "z": 1,
            "elements": [
                "contenttweaker:sub_block_holder_1@5"
            ]
        },
        {
            "x": 3,
            "y": -1,
            "z": 1,
            "elements": [
                "contenttweaker:sub_block_holder_1@4"
            ]
        },
        {
            "x": -2,
            "y": -7,
            "z": 2,
            "elements": [
                "contenttweaker:sub_block_holder_1@4"
            ]
        },
        {
            "x": -1,
            "y": -7,
            "z": 2,
            "elements": [
                "contenttweaker:sub_block_holder_1@5"
            ]
        },
        {
            "x": 0,
            "y": -7,
            "z": 2,
            "elements": [
                "contenttweaker:sub_block_holder_1@5"
            ]
        },
        {
            "x": 1,
            "y": -7,
            "z": 2,
            "elements": [
                "contenttweaker:sub_block_holder_1@5"
            ]
        },
        {
            "x": 2,
            "y": -7,
            "z": 2,
            "elements": [
                "contenttweaker:sub_block_holder_1@4"
            ]
        },
        {
            "x": 0,
            "y": -8,
            "z": -1,
            "nbt": {"id":"minecraft:tilefluidoutputhatch","casingColor":"10790052","input":"0b","size":"2","tank":{"Empty":"","gasTag":{"Empty":""}}},
            "elements": [
                "modularmachinery:blockfluidoutputhatch@2"
            ]
        },
        {
            "x": 0,
            "y": -6,
            "z": 0,
            "elements": [
                "contenttweaker:sub_block_holder_0@11"
            ]
        },
        {
            "x": 1,
            "y": -2,
            "z": -2,
            "elements": [
                "contenttweaker:sub_block_holder_1@5"
            ]
        },
        {
            "x": 0,
            "y": 0,
            "z": -1,
            "nbt": {"id":"minecraft:tilefluidinputhatch","casingColor":"10790052","input":"1b","size":"2","tank":{"Empty":"","gasTag":{"Empty":""}}},
            "elements": [
                "modularmachinery:blockfluidinputhatch@2"
            ]
        },
        {
            "x": -1,
            "y": -2,
            "z": -2,
            "elements": [
                "contenttweaker:sub_block_holder_1@5"
            ]
        },
        {
            "x": 0,
            "y": 0,
            "z": 1,
            "nbt": {"id":"minecraft:tilefluidinputhatch","casingColor":"10790052","input":"1b","size":"2","tank":{"Empty":"","gasTag":{"Empty":""}}},
            "elements": [
                "modularmachinery:blockfluidinputhatch@2"
            ]
        },
        {
            "x": -1,
            "y": -6,
            "z": 2,
            "elements": [
                "contenttweaker:sub_block_holder_1@5"
            ]
        },
        {
            "x": 1,
            "y": -6,
            "z": 2,
            "elements": [
                "contenttweaker:sub_block_holder_1@5"
            ]
        },
        {
            "x": 0,
            "y": -8,
            "z": 1,
            "nbt": {"id":"minecraft:tilefluidoutputhatch","casingColor":"10790052","input":"0b","size":"2","tank":{"Empty":"","gasTag":{"Empty":""}}},
            "elements": [
                "modularmachinery:blockfluidoutputhatch@2"
            ]
        },
        {
            "x": 3,
            "y": -7,
            "z": 0,
            "elements": [
                "contenttweaker:sub_block_holder_1@4"
            ]
        },
        {
            "x": 2,
            "y": -7,
            "z": 0,
            "elements": [
                "contenttweaker:sub_block_holder_1@5"
            ]
        },
        {
            "x": 1,
            "y": -7,
            "z": 0,
            "elements": [
                "contenttweaker:sub_block_holder_1@4"
            ]
        },
        {
            "x": 0,
            "y": -7,
            "z": 0,
            "elements": [
                "contenttweaker:sub_block_holder_0@11"
            ]
        },
        {
            "x": -1,
            "y": -7,
            "z": 0,
            "elements": [
                "contenttweaker:sub_block_holder_1@4"
            ]
        },
        {
            "x": -2,
            "y": -7,
            "z": 0,
            "elements": [
                "contenttweaker:sub_block_holder_1@5"
            ]
        },
        {
            "x": -3,
            "y": -7,
            "z": 0,
            "elements": [
                "contenttweaker:sub_block_holder_1@4"
            ]
        },
        {
            "x": 3,
            "y": -1,
            "z": -1,
            "elements": [
                "contenttweaker:sub_block_holder_1@4"
            ]
        },
        {
            "x": 2,
            "y": -1,
            "z": -1,
            "elements": [
                "contenttweaker:sub_block_holder_1@5"
            ]
        },
        {
            "x": 1,
            "y": -3,
            "z": -2,
            "elements": [
                "contenttweaker:sub_block_holder_1@5"
            ]
        },
        {
            "x": 1,
            "y": -1,
            "z": -1,
            "elements": [
                "contenttweaker:sub_block_holder_1@4"
            ]
        },
        {
            "x": -1,
            "y": -3,
            "z": -2,
            "elements": [
                "contenttweaker:sub_block_holder_1@5"
            ]
        },
        {
            "x": 0,
            "y": -1,
            "z": -1,
            "elements": [
                "contenttweaker:sub_block_holder_1@4"
            ]
        },
        {
            "x": -1,
            "y": -1,
            "z": -1,
            "elements": [
                "contenttweaker:sub_block_holder_1@4"
            ]
        },
        {
            "x": -2,
            "y": -1,
            "z": -1,
            "elements": [
                "contenttweaker:sub_block_holder_1@5"
            ]
        },
        {
            "x": -3,
            "y": -1,
            "z": -1,
            "elements": [
                "contenttweaker:sub_block_holder_1@4"
            ]
        },
        {
            "x": -3,
            "y": -7,
            "z": 1,
            "elements": [
                "contenttweaker:sub_block_holder_1@4"
            ]
        },
        {
            "x": -2,
            "y": -7,
            "z": 1,
            "elements": [
                "contenttweaker:sub_block_holder_1@5"
            ]
        },
        {
            "x": -1,
            "y": -5,
            "z": 2,
            "elements": [
                "contenttweaker:sub_block_holder_1@5"
            ]
        },
        {
            "x": -1,
            "y": -7,
            "z": 1,
            "elements": [
                "contenttweaker:sub_block_holder_1@4"
            ]
        },
        {
            "x": 1,
            "y": -5,
            "z": 2,
            "elements": [
                "contenttweaker:sub_block_holder_1@5"
            ]
        },
        {
            "x": 0,
            "y": -7,
            "z": 1,
            "elements": [
                "contenttweaker:sub_block_holder_1@4"
            ]
        },
        {
            "x": 1,
            "y": -7,
            "z": 1,
            "elements": [
                "contenttweaker:sub_block_holder_1@4"
            ]
        },
        {
            "x": 2,
            "y": -7,
            "z": 1,
            "elements": [
                "contenttweaker:sub_block_holder_1@5"
            ]
        },
        {
            "x": 3,
            "y": -7,
            "z": 1,
            "elements": [
                "contenttweaker:sub_block_holder_1@4"
            ]
        },
        {
            "x": 1,
            "y": -8,
            "z": 0,
            "nbt": {"id":"minecraft:tilefluidoutputhatch","casingColor":"10790052","input":"0b","size":"2","tank":{"Empty":"","gasTag":{"Empty":""}}},
            "elements": [
                "modularmachinery:blockfluidoutputhatch@2"
            ]
        },
        {
            "x": 0,
            "y": -8,
            "z": 0,
            "nbt": {"id":"minecraft:tileenergyinputhatch","casingColor":"10790052","energy":"0L","hatchSize":"2"},
            "elements": [
                "modularmachinery:blockenergyinputhatch@2"
            ]
        },
        {
            "x": -1,
            "y": -8,
            "z": 0,
            "nbt": {"id":"minecraft:tilefluidoutputhatch","casingColor":"10790052","input":"0b","size":"2","tank":{"Empty":"","gasTag":{"Empty":""}}},
            "elements": [
                "modularmachinery:blockfluidoutputhatch@2"
            ]
        },
        {
            "x": 2,
            "y": -2,
            "z": -1,
            "elements": [
                "contenttweaker:sub_block_holder_1@5"
            ]
        },
        {
            "x": 1,
            "y": -4,
            "z": -2,
            "elements": [
                "contenttweaker:sub_block_holder_1@5"
            ]
        },
        {
            "x": 1,
            "y": -2,
            "z": -1,
            "elements": [
                "contenttweaker:sub_block_holder_0@3"
            ]
        },
        {
            "x": -1,
            "y": -4,
            "z": -2,
            "elements": [
                "contenttweaker:sub_block_holder_1@5"
            ]
        },
        {
            "x": -1,
            "y": -2,
            "z": -1,
            "elements": [
                "contenttweaker:sub_block_holder_0@3"
            ]
        }
    ]}